2024-10-21 16:56:14,436 - INFO - WebSocket Unified V5 (Auth) attempting connection...
2024-10-21 16:56:15,499 - ERROR - error from callback <function _WebSocketManager._connect.<locals>.<lambda> at 0x000001AC6ADEF880>: [SSL: CERTIFICATE_VERIFY_FAILED] certificate verify failed: unable to get local issuer certificate (_ssl.c:1006)
2024-10-21 16:56:15,517 - INFO - tearing down on exception [SSL: CERTIFICATE_VERIFY_FAILED] certificate verify failed: unable to get local issuer certificate (_ssl.c:1006)
2024-10-21 16:56:15,534 - INFO - WebSocket Unified V5 (Auth) attempting connection...
2024-10-21 16:56:16,544 - ERROR - error from callback <function _WebSocketManager._connect.<locals>.<lambda> at 0x000001AC6AE0CB80>: [SSL: CERTIFICATE_VERIFY_FAILED] certificate verify failed: unable to get local issuer certificate (_ssl.c:1006)
2024-10-21 16:56:16,604 - INFO - tearing down on exception [SSL: CERTIFICATE_VERIFY_FAILED] certificate verify failed: unable to get local issuer certificate (_ssl.c:1006)
2024-10-21 16:56:16,615 - INFO - WebSocket Unified V5 (Auth) attempting connection...
2024-10-21 16:56:17,640 - ERROR - error from callback <function _WebSocketManager._connect.<locals>.<lambda> at 0x000001AC6AE0D4E0>: [SSL: CERTIFICATE_VERIFY_FAILED] certificate verify failed: unable to get local issuer certificate (_ssl.c:1006)
2024-10-21 16:56:17,674 - INFO - tearing down on exception [SSL: CERTIFICATE_VERIFY_FAILED] certificate verify failed: unable to get local issuer certificate (_ssl.c:1006)
2024-10-21 16:56:17,709 - INFO - WebSocket Unified V5 (Auth) attempting connection...
2024-10-21 16:56:18,720 - ERROR - error from callback <function _WebSocketManager._connect.<locals>.<lambda> at 0x000001AC6AE0DDA0>: [SSL: CERTIFICATE_VERIFY_FAILED] certificate verify failed: unable to get local issuer certificate (_ssl.c:1006)
2024-10-21 16:56:18,756 - INFO - tearing down on exception [SSL: CERTIFICATE_VERIFY_FAILED] certificate verify failed: unable to get local issuer certificate (_ssl.c:1006)
2024-10-21 16:56:18,789 - INFO - WebSocket Unified V5 (Auth) attempting connection...
2024-10-21 16:56:19,724 - ERROR - error from callback <function _WebSocketManager._connect.<locals>.<lambda> at 0x000001AC6AE0E700>: [SSL: CERTIFICATE_VERIFY_FAILED] certificate verify failed: unable to get local issuer certificate (_ssl.c:1006)
2024-10-21 16:56:19,755 - INFO - tearing down on exception [SSL: CERTIFICATE_VERIFY_FAILED] certificate verify failed: unable to get local issuer certificate (_ssl.c:1006)
2024-10-21 16:56:19,799 - INFO - WebSocket Unified V5 (Auth) attempting connection...
2024-10-21 16:56:20,765 - ERROR - error from callback <function _WebSocketManager._connect.<locals>.<lambda> at 0x000001AC6AE0EFC0>: [SSL: CERTIFICATE_VERIFY_FAILED] certificate verify failed: unable to get local issuer certificate (_ssl.c:1006)
2024-10-21 16:56:20,779 - INFO - tearing down on exception [SSL: CERTIFICATE_VERIFY_FAILED] certificate verify failed: unable to get local issuer certificate (_ssl.c:1006)
2024-10-21 16:56:20,781 - INFO - WebSocket Unified V5 (Auth) attempting connection...
2024-10-21 16:56:21,755 - ERROR - error from callback <function _WebSocketManager._connect.<locals>.<lambda> at 0x000001AC6AE0EB60>: [SSL: CERTIFICATE_VERIFY_FAILED] certificate verify failed: unable to get local issuer certificate (_ssl.c:1006)
2024-10-21 16:56:21,783 - INFO - tearing down on exception [SSL: CERTIFICATE_VERIFY_FAILED] certificate verify failed: unable to get local issuer certificate (_ssl.c:1006)
2024-10-21 16:56:21,816 - INFO - WebSocket Unified V5 (Auth) attempting connection...
2024-10-21 16:56:22,827 - ERROR - error from callback <function _WebSocketManager._connect.<locals>.<lambda> at 0x000001AC6AE0DDA0>: [SSL: CERTIFICATE_VERIFY_FAILED] certificate verify failed: unable to get local issuer certificate (_ssl.c:1006)
2024-10-21 16:56:22,837 - INFO - tearing down on exception [SSL: CERTIFICATE_VERIFY_FAILED] certificate verify failed: unable to get local issuer certificate (_ssl.c:1006)
2024-10-21 16:56:22,868 - INFO - WebSocket Unified V5 (Auth) attempting connection...
2024-10-21 16:56:23,836 - ERROR - error from callback <function _WebSocketManager._connect.<locals>.<lambda> at 0x000001AC6AE0DA80>: [SSL: CERTIFICATE_VERIFY_FAILED] certificate verify failed: unable to get local issuer certificate (_ssl.c:1006)
2024-10-21 16:56:23,851 - INFO - tearing down on exception [SSL: CERTIFICATE_VERIFY_FAILED] certificate verify failed: unable to get local issuer certificate (_ssl.c:1006)
2024-10-21 16:56:23,851 - INFO - WebSocket Unified V5 (Auth) attempting connection...
2024-10-21 16:56:24,882 - ERROR - error from callback <function _WebSocketManager._connect.<locals>.<lambda> at 0x000001AC6AE0D1C0>: [SSL: CERTIFICATE_VERIFY_FAILED] certificate verify failed: unable to get local issuer certificate (_ssl.c:1006)
2024-10-21 16:56:24,923 - INFO - tearing down on exception [SSL: CERTIFICATE_VERIFY_FAILED] certificate verify failed: unable to get local issuer certificate (_ssl.c:1006)
2024-10-21 17:30:54,769 - INFO - WebSocket Unified V5 (Auth) attempting connection...
2024-10-21 17:30:57,029 - DEBUG - --- request header ---
2024-10-21 17:30:57,061 - DEBUG - GET /v5/public/linear HTTP/1.1
Upgrade: websocket
Host: stream-testnet.bybit.com
Origin: https://stream-testnet.bybit.com
Sec-WebSocket-Key: BwJo7V7ONgJaRl2oilw4eA==
Sec-WebSocket-Version: 13
Connection: Upgrade


2024-10-21 17:30:57,105 - DEBUG - -----------------------
2024-10-21 17:30:57,143 - DEBUG - --- response header ---
2024-10-21 17:30:58,324 - DEBUG - HTTP/1.1 101 Switching Protocols
2024-10-21 17:30:58,378 - DEBUG - Connection: upgrade
2024-10-21 17:30:58,427 - DEBUG - Date: Mon, 21 Oct 2024 15:30:58 GMT
2024-10-21 17:30:58,438 - DEBUG - Upgrade: websocket
2024-10-21 17:30:58,453 - DEBUG - Sec-WebSocket-Accept: KXmdlYpGSHQIimEUkg2RUwfjznM=
2024-10-21 17:30:58,474 - DEBUG - X-Cache: Miss from cloudfront
2024-10-21 17:30:58,491 - DEBUG - Via: 1.1 4c71f51c48fb1aec28bdb43b72260ca2.cloudfront.net (CloudFront)
2024-10-21 17:30:58,528 - DEBUG - X-Amz-Cf-Pop: JFK52-P6
2024-10-21 17:30:58,565 - DEBUG - X-Amz-Cf-Id: hy6j8xCXdEgSE1vI3FHFty35PuSv0JexQrnCbb9Ft2LGI9rNkGPsXw==
2024-10-21 17:30:58,582 - DEBUG - -----------------------
2024-10-21 17:30:58,669 - INFO - Websocket connected
2024-10-21 17:30:58,672 - INFO - WebSocket Unified V5 (Auth) connected
2024-10-21 17:31:18,705 - DEBUG - ++Sent raw: b'\x81\x8e\x8c\xca\xe6\x8a\xf7\xe8\x89\xfa\xae\xf0\xc6\xa8\xfc\xa3\x88\xed\xae\xb7'
2024-10-21 17:31:18,705 - DEBUG - ++Sent decoded: fin=1 opcode=1 data=b'{"op": "ping"}'
2024-10-21 17:31:19,154 - DEBUG - ++Rcv raw: b'\x81j{"success":true,"ret_msg":"pong","conn_id":"53a7947b-039c-407f-a228-e06677f3c8a0","req_id":"","op":"ping"}'
2024-10-21 17:31:19,154 - DEBUG - ++Rcv decoded: fin=1 opcode=1 data=b'{"success":true,"ret_msg":"pong","conn_id":"53a7947b-039c-407f-a228-e06677f3c8a0","req_id":"","op":"ping"}'
2024-10-21 17:38:53,346 - INFO - WebSocket Unified V5 (Auth) attempting connection...
2024-10-21 17:38:55,562 - DEBUG - --- request header ---
2024-10-21 17:38:55,593 - DEBUG - GET /v5/public/linear HTTP/1.1
Upgrade: websocket
Host: stream-testnet.bybit.com
Origin: https://stream-testnet.bybit.com
Sec-WebSocket-Key: +t17V9otPvNvKVQLDH+vTQ==
Sec-WebSocket-Version: 13
Connection: Upgrade


2024-10-21 17:38:55,628 - DEBUG - -----------------------
2024-10-21 17:38:55,656 - DEBUG - --- response header ---
2024-10-21 17:38:56,664 - DEBUG - HTTP/1.1 101 Switching Protocols
2024-10-21 17:38:56,664 - DEBUG - Connection: upgrade
2024-10-21 17:38:56,673 - DEBUG - Date: Mon, 21 Oct 2024 15:38:56 GMT
2024-10-21 17:38:56,807 - DEBUG - Upgrade: websocket
2024-10-21 17:38:56,840 - DEBUG - Sec-WebSocket-Accept: uTAJZgpjn57fbco2bs75ho7cy90=
2024-10-21 17:38:56,875 - DEBUG - X-Cache: Miss from cloudfront
2024-10-21 17:38:56,916 - DEBUG - Via: 1.1 b8f0ff2969e7ec30e68b72cac77780e8.cloudfront.net (CloudFront)
2024-10-21 17:38:56,936 - DEBUG - X-Amz-Cf-Pop: JFK52-P6
2024-10-21 17:38:57,024 - DEBUG - X-Amz-Cf-Id: Bjl84an23LRgHN9MT12u_m7CUk7hWffXpCWB69J7S8jvRRa0Mr-I7g==
2024-10-21 17:38:57,044 - DEBUG - -----------------------
2024-10-21 17:38:57,062 - INFO - WebSocket Unified V5 (Auth) connected
2024-10-21 17:38:57,062 - INFO - Websocket connected
2024-10-21 17:39:00,461 - DEBUG - ++Sent raw: b"\x81\xe7B\x92\xe1\xd49\xb0\x8e\xa4`\xa8\xc1\xf61\xe7\x83\xa7!\xe0\x88\xb6'\xb0\xcd\xf4`\xe0\x84\xa5\x1d\xfb\x85\xf6x\xb2\xc3\xe3&\xf7\x82\xb0v\xf0\x80\xf9t\xa6\x83\xeco\xa6\xd7\xe5w\xbf\x83\xec'\xa0\xcc\xe7 \xa4\xd6\xe5u\xa0\xd8\xb1#\xf4\xd3\xf6n\xb2\xc3\xb50\xf5\x92\xf6x\xb2\xba\xf6-\xe0\x85\xb10\xf0\x8e\xbb)\xbc\xd4\xe4l\xd0\xb5\x97\x17\xc1\xa5\x80`\xcf\x9c"
2024-10-21 17:39:00,465 - DEBUG - ++Sent decoded: fin=1 opcode=1 data=b'{"op": "subscribe", "req_id": "7decd4ba-64b8-4615-b8e2-3b671729eaf2", "args": ["orderbook.50.BTCUSDT"]}'
2024-10-21 17:39:00,922 - DEBUG - ++Rcv raw: b'\x81~\x08\xd0{"topic":"orderbook.50.BTCUSDT","type":"snapshot","ts":1729525139873,"data":{"s":"BTCUSDT","b":[["67560.80","200.842"],["67555.00","0.001"],["67553.30","0.001"],["67550.80","0.397"],["67550.00","0.003"],["67544.60","0.089"],["67542.00","0.001"],["67541.20","0.129"],["67540.00","0.550"],["67537.60","0.001"],["67531.40","0.001"],["67516.50","0.001"],["67511.30","0.010"],["67507.80","0.001"],["67500.00","0.019"],["67494.30","0.004"],["67492.00","0.074"],["67489.80","0.918"],["67467.20","0.005"],["67461.30","0.443"],["67456.90","0.002"],["67454.90","0.001"],["67452.60","0.426"],["67450.20","0.686"],["67449.70","0.001"],["67399.70","0.001"],["67384.50","0.001"],["67376.10","0.450"],["67375.00","0.002"],["67368.90","0.001"],["67360.60","0.001"],["67349.70","2.513"],["67343.40","0.001"],["67333.30","0.021"],["67331.70","0.004"],["67322.10","0.001"],["67320.90","0.631"],["67300.00","0.057"],["67293.30","0.017"],["67292.80","0.002"],["67291.50","0.358"],["67290.00","0.552"],["67287.60","0.264"],["67286.80","0.185"],["67283.50","0.001"],["67282.90","0.426"],["67278.30","0.010"],["67277.30","0.089"],["67249.40","0.129"],["67233.30","0.001"]],"a":[["67560.90","0.004"],["67561.00","0.001"],["67574.60","0.001"],["67588.20","0.001"],["67597.00","0.598"],["67777.00","0.015"],["67786.40","0.002"],["67792.00","0.188"],["67801.10","0.402"],["67827.80","0.755"],["67833.30","0.057"],["67833.50","0.598"],["67900.00","0.003"],["67901.50","0.009"],["67931.00","0.035"],["67951.70","0.002"],["67961.70","0.236"],["67970.90","0.443"],["67986.60","0.017"],["67996.70","0.918"],["68000.00","0.005"],["68027.10","0.001"],["68030.00","0.553"],["68056.90","0.264"],["68070.40","0.113"],["68075.00","0.003"],["68077.50","0.459"],["68079.10","0.089"],["68100.00","0.070"],["68108.00","0.001"],["68117.50","0.002"],["68124.60","0.129"],["68131.30","0.426"],["68140.80","0.443"],["68165.70","0.658"],["68188.40","0.001"],["68216.50","0.281"],["68223.50","0.020"],["68250.00","0.003"],["68254.00","0.459"],["68275.00","0.001"],["68283.60","0.002"],["68295.90","0.001"],["68296.10","0.010"],["68297.40","0.010"],["68301.00","0.426"],["68308.40","0.549"],["68310.70","0.443"],["68328.50","0.020"],["68333.30","0.017"]],"u":10129955,"seq":9374133155},"cts":1729525139833}'
2024-10-21 17:39:00,926 - DEBUG - ++Rcv decoded: fin=1 opcode=1 data=b'{"topic":"orderbook.50.BTCUSDT","type":"snapshot","ts":1729525139873,"data":{"s":"BTCUSDT","b":[["67560.80","200.842"],["67555.00","0.001"],["67553.30","0.001"],["67550.80","0.397"],["67550.00","0.003"],["67544.60","0.089"],["67542.00","0.001"],["67541.20","0.129"],["67540.00","0.550"],["67537.60","0.001"],["67531.40","0.001"],["67516.50","0.001"],["67511.30","0.010"],["67507.80","0.001"],["67500.00","0.019"],["67494.30","0.004"],["67492.00","0.074"],["67489.80","0.918"],["67467.20","0.005"],["67461.30","0.443"],["67456.90","0.002"],["67454.90","0.001"],["67452.60","0.426"],["67450.20","0.686"],["67449.70","0.001"],["67399.70","0.001"],["67384.50","0.001"],["67376.10","0.450"],["67375.00","0.002"],["67368.90","0.001"],["67360.60","0.001"],["67349.70","2.513"],["67343.40","0.001"],["67333.30","0.021"],["67331.70","0.004"],["67322.10","0.001"],["67320.90","0.631"],["67300.00","0.057"],["67293.30","0.017"],["67292.80","0.002"],["67291.50","0.358"],["67290.00","0.552"],["67287.60","0.264"],["67286.80","0.185"],["67283.50","0.001"],["67282.90","0.426"],["67278.30","0.010"],["67277.30","0.089"],["67249.40","0.129"],["67233.30","0.001"]],"a":[["67560.90","0.004"],["67561.00","0.001"],["67574.60","0.001"],["67588.20","0.001"],["67597.00","0.598"],["67777.00","0.015"],["67786.40","0.002"],["67792.00","0.188"],["67801.10","0.402"],["67827.80","0.755"],["67833.30","0.057"],["67833.50","0.598"],["67900.00","0.003"],["67901.50","0.009"],["67931.00","0.035"],["67951.70","0.002"],["67961.70","0.236"],["67970.90","0.443"],["67986.60","0.017"],["67996.70","0.918"],["68000.00","0.005"],["68027.10","0.001"],["68030.00","0.553"],["68056.90","0.264"],["68070.40","0.113"],["68075.00","0.003"],["68077.50","0.459"],["68079.10","0.089"],["68100.00","0.070"],["68108.00","0.001"],["68117.50","0.002"],["68124.60","0.129"],["68131.30","0.426"],["68140.80","0.443"],["68165.70","0.658"],["68188.40","0.001"],["68216.50","0.281"],["68223.50","0.020"],["68250.00","0.003"],["68254.00","0.459"],["68275.00","0.001"],["68283.60","0.002"],["68295.90","0.001"],["68296.10","0.010"],["68297.40","0.010"],["68301.00","0.426"],["68308.40","0.549"],["68310.70","0.443"],["68328.50","0.020"],["68333.30","0.017"]],"u":10129955,"seq":9374133155},"cts":1729525139833}'
2024-10-21 17:39:00,944 - ERROR - error from callback <function _WebSocketManager._connect.<locals>.<lambda> at 0x000002417B4DFB00>: BybitWebSocket.handle_orderbook() takes 1 positional argument but 2 were given
2024-10-21 17:39:00,946 - DEBUG - ++Sent raw: b'\x88\x82y=<\x10z\xd5'
2024-10-21 17:39:00,947 - DEBUG - ++Sent decoded: fin=1 opcode=8 data=b'\x03\xe8'
2024-10-21 17:39:01,404 - ERROR - error from callback <function _WebSocketManager._connect.<locals>.<lambda> at 0x000002417B4DFD80>: BybitWebSocket.handle_orderbook() takes 1 positional argument but 2 were given
2024-10-21 17:39:01,404 - INFO - tearing down on exception BybitWebSocket.handle_orderbook() takes 1 positional argument but 2 were given
2024-10-21 17:40:06,507 - INFO - WebSocket Unified V5 (Auth) attempting connection...
2024-10-21 17:40:08,607 - DEBUG - --- request header ---
2024-10-21 17:40:08,620 - DEBUG - GET /v5/public/linear HTTP/1.1
Upgrade: websocket
Host: stream-testnet.bybit.com
Origin: https://stream-testnet.bybit.com
Sec-WebSocket-Key: DLZ03MReWrjc60/safT+lw==
Sec-WebSocket-Version: 13
Connection: Upgrade


2024-10-21 17:40:08,636 - DEBUG - -----------------------
2024-10-21 17:40:08,652 - DEBUG - --- response header ---
2024-10-21 17:40:09,869 - DEBUG - HTTP/1.1 101 Switching Protocols
2024-10-21 17:40:09,965 - DEBUG - Connection: upgrade
2024-10-21 17:40:10,010 - DEBUG - Date: Mon, 21 Oct 2024 15:40:09 GMT
2024-10-21 17:40:10,029 - DEBUG - Upgrade: websocket
2024-10-21 17:40:10,079 - DEBUG - Sec-WebSocket-Accept: LnMe054D/l99dR+O867yBaO8DKo=
2024-10-21 17:40:10,088 - DEBUG - X-Cache: Miss from cloudfront
2024-10-21 17:40:10,139 - DEBUG - Via: 1.1 69b5dbefd76c92e64a93f1d3eb7e22a8.cloudfront.net (CloudFront)
2024-10-21 17:40:10,161 - DEBUG - X-Amz-Cf-Pop: JFK52-P6
2024-10-21 17:40:10,197 - DEBUG - X-Amz-Cf-Id: ZMQk-IJEA7CByv9VpymcxPmWW36Z-xQKFFlLpR6sq9YPtJK3oWoUqQ==
2024-10-21 17:40:10,215 - DEBUG - -----------------------
2024-10-21 17:40:10,225 - INFO - WebSocket Unified V5 (Auth) connected
2024-10-21 17:40:10,225 - INFO - Websocket connected
2024-10-21 17:40:15,764 - DEBUG - ++Sent raw: b"\x81\xe7\xd4\x15\xef\xfc\xaf7\x80\x8c\xf6/\xcf\xde\xa7`\x8d\x8f\xb7g\x86\x9e\xb17\xc3\xdc\xf6g\x8a\x8d\x8b|\x8b\xde\xee5\xcd\xce\xe4'\x8a\xcb\xb7$\x8d\xd1\xe6v\xdc\x9f\xf9!\xdd\xc9\xb58\xd7\xcb\xecs\xc2\xcf\xb2q\xd7\xc8\xe3p\xd6\xcc\xe7v\x8c\xde\xf85\xcd\x9d\xa6r\x9c\xde\xee5\xb4\xde\xbbg\x8b\x99\xa6w\x80\x93\xbf;\xda\xcc\xfaW\xbb\xbf\x81F\xab\xa8\xf6H\x92"
2024-10-21 17:40:15,775 - DEBUG - ++Sent decoded: fin=1 opcode=1 data=b'{"op": "subscribe", "req_id": "202e7c1b-2c3c-425a-878f-3fd847e903cc", "args": ["orderbook.50.BTCUSDT"]}'
2024-10-21 17:40:16,220 - DEBUG - ++Rcv raw: b'\x81~\x08\xd0{"topic":"orderbook.50.BTCUSDT","type":"snapshot","ts":1729525215874,"data":{"s":"BTCUSDT","b":[["67613.60","0.159"],["67560.80","199.397"],["67555.00","0.001"],["67553.30","0.001"],["67550.80","0.397"],["67550.00","0.003"],["67544.60","0.089"],["67542.00","0.001"],["67541.20","0.129"],["67540.00","0.550"],["67537.60","0.001"],["67531.40","0.001"],["67516.50","0.001"],["67511.30","0.010"],["67507.80","0.001"],["67500.00","0.019"],["67494.30","0.004"],["67492.00","0.074"],["67489.80","0.918"],["67467.20","0.005"],["67461.30","0.443"],["67456.90","0.002"],["67454.90","0.001"],["67452.60","0.426"],["67450.20","0.686"],["67449.70","0.001"],["67399.70","0.001"],["67384.50","0.001"],["67376.10","0.450"],["67375.00","0.002"],["67368.90","0.001"],["67360.60","0.001"],["67349.70","2.513"],["67343.40","0.001"],["67333.30","0.021"],["67331.70","0.004"],["67322.10","0.001"],["67320.90","0.631"],["67300.00","0.057"],["67293.30","0.017"],["67292.80","0.002"],["67291.50","0.358"],["67290.00","0.552"],["67287.60","0.264"],["67286.80","0.185"],["67283.50","0.001"],["67282.90","0.426"],["67278.30","0.010"],["67277.30","0.089"],["67249.40","0.129"]],"a":[["67618.80","0.001"],["67632.40","0.001"],["67646.10","0.001"],["67659.60","0.001"],["67782.00","0.001"],["67786.40","0.002"],["67792.00","0.426"],["67801.10","0.224"],["67827.80","0.755"],["67833.30","0.057"],["67833.50","0.598"],["67900.00","0.003"],["67901.50","0.009"],["67931.00","0.035"],["67951.70","0.002"],["67961.70","0.236"],["67970.90","0.443"],["67986.60","0.017"],["67996.70","0.918"],["68000.00","0.005"],["68027.10","0.001"],["68030.00","0.553"],["68056.90","0.264"],["68070.40","0.113"],["68075.00","0.003"],["68077.50","0.459"],["68079.10","0.089"],["68100.00","0.070"],["68108.00","0.001"],["68117.50","0.002"],["68124.60","0.129"],["68131.30","0.426"],["68140.80","0.443"],["68165.70","0.658"],["68188.40","0.001"],["68216.50","0.281"],["68250.00","0.003"],["68254.00","0.459"],["68275.00","0.001"],["68283.00","0.020"],["68283.60","0.002"],["68295.90","0.001"],["68296.10","0.010"],["68297.40","0.010"],["68301.00","0.426"],["68308.40","0.549"],["68310.70","0.443"],["68328.50","0.020"],["68333.30","0.017"],["68334.70","0.606"]],"u":10130029,"seq":9374133541},"cts":1729525215625}'
2024-10-21 17:40:16,233 - DEBUG - ++Rcv decoded: fin=1 opcode=1 data=b'{"topic":"orderbook.50.BTCUSDT","type":"snapshot","ts":1729525215874,"data":{"s":"BTCUSDT","b":[["67613.60","0.159"],["67560.80","199.397"],["67555.00","0.001"],["67553.30","0.001"],["67550.80","0.397"],["67550.00","0.003"],["67544.60","0.089"],["67542.00","0.001"],["67541.20","0.129"],["67540.00","0.550"],["67537.60","0.001"],["67531.40","0.001"],["67516.50","0.001"],["67511.30","0.010"],["67507.80","0.001"],["67500.00","0.019"],["67494.30","0.004"],["67492.00","0.074"],["67489.80","0.918"],["67467.20","0.005"],["67461.30","0.443"],["67456.90","0.002"],["67454.90","0.001"],["67452.60","0.426"],["67450.20","0.686"],["67449.70","0.001"],["67399.70","0.001"],["67384.50","0.001"],["67376.10","0.450"],["67375.00","0.002"],["67368.90","0.001"],["67360.60","0.001"],["67349.70","2.513"],["67343.40","0.001"],["67333.30","0.021"],["67331.70","0.004"],["67322.10","0.001"],["67320.90","0.631"],["67300.00","0.057"],["67293.30","0.017"],["67292.80","0.002"],["67291.50","0.358"],["67290.00","0.552"],["67287.60","0.264"],["67286.80","0.185"],["67283.50","0.001"],["67282.90","0.426"],["67278.30","0.010"],["67277.30","0.089"],["67249.40","0.129"]],"a":[["67618.80","0.001"],["67632.40","0.001"],["67646.10","0.001"],["67659.60","0.001"],["67782.00","0.001"],["67786.40","0.002"],["67792.00","0.426"],["67801.10","0.224"],["67827.80","0.755"],["67833.30","0.057"],["67833.50","0.598"],["67900.00","0.003"],["67901.50","0.009"],["67931.00","0.035"],["67951.70","0.002"],["67961.70","0.236"],["67970.90","0.443"],["67986.60","0.017"],["67996.70","0.918"],["68000.00","0.005"],["68027.10","0.001"],["68030.00","0.553"],["68056.90","0.264"],["68070.40","0.113"],["68075.00","0.003"],["68077.50","0.459"],["68079.10","0.089"],["68100.00","0.070"],["68108.00","0.001"],["68117.50","0.002"],["68124.60","0.129"],["68131.30","0.426"],["68140.80","0.443"],["68165.70","0.658"],["68188.40","0.001"],["68216.50","0.281"],["68250.00","0.003"],["68254.00","0.459"],["68275.00","0.001"],["68283.00","0.020"],["68283.60","0.002"],["68295.90","0.001"],["68296.10","0.010"],["68297.40","0.010"],["68301.00","0.426"],["68308.40","0.549"],["68310.70","0.443"],["68328.50","0.020"],["68333.30","0.017"],["68334.70","0.606"]],"u":10130029,"seq":9374133541},"cts":1729525215625}'
2024-10-21 17:40:16,251 - DEBUG - ++Rcv raw: b'\x81~\x00\x8f{"success":true,"ret_msg":"","conn_id":"b69c54ab-2655-4654-85a5-01a30766f9e9","req_id":"202e7c1b-2c3c-425a-878f-3fd847e903cc","op":"subscribe"}'
2024-10-21 17:40:16,251 - DEBUG - ++Rcv decoded: fin=1 opcode=1 data=b'{"success":true,"ret_msg":"","conn_id":"b69c54ab-2655-4654-85a5-01a30766f9e9","req_id":"202e7c1b-2c3c-425a-878f-3fd847e903cc","op":"subscribe"}'
2024-10-21 17:40:16,589 - DEBUG - ++Rcv raw: b'\x81~\x01\xb7{"topic":"orderbook.50.BTCUSDT","type":"delta","ts":1729525216712,"data":{"s":"BTCUSDT","b":[],"a":[["67618.80","0"],["67632.40","0"],["67646.10","0"],["67659.60","0"],["67782.00","0"],["67786.40","0"],["67792.00","0"],["67801.10","0.193"],["68346.40","0.089"],["68366.60","0.057"],["68400.00","0.566"],["68416.40","0.129"],["68425.00","0.003"],["68426.80","0.002"],["68430.90","0.025"]],"u":10130030,"seq":9374133566},"cts":1729525216709}'
2024-10-21 17:40:16,589 - DEBUG - ++Rcv decoded: fin=1 opcode=1 data=b'{"topic":"orderbook.50.BTCUSDT","type":"delta","ts":1729525216712,"data":{"s":"BTCUSDT","b":[],"a":[["67618.80","0"],["67632.40","0"],["67646.10","0"],["67659.60","0"],["67782.00","0"],["67786.40","0"],["67792.00","0"],["67801.10","0.193"],["68346.40","0.089"],["68366.60","0.057"],["68400.00","0.566"],["68416.40","0.129"],["68425.00","0.003"],["68426.80","0.002"],["68430.90","0.025"]],"u":10130030,"seq":9374133566},"cts":1729525216709}'
2024-10-21 17:40:16,605 - DEBUG - ++Rcv raw: b'\x81~\x00\xe4{"topic":"orderbook.50.BTCUSDT","type":"delta","ts":1729525216732,"data":{"s":"BTCUSDT","b":[["67622.30","0.426"],["67621.50","0.002"],["67277.30","0"],["67249.40","0"]],"a":[],"u":10130031,"seq":9374133568},"cts":1729525216719}'
2024-10-21 17:40:16,609 - DEBUG - ++Rcv decoded: fin=1 opcode=1 data=b'{"topic":"orderbook.50.BTCUSDT","type":"delta","ts":1729525216732,"data":{"s":"BTCUSDT","b":[["67622.30","0.426"],["67621.50","0.002"],["67277.30","0"],["67249.40","0"]],"a":[],"u":10130031,"seq":9374133568},"cts":1729525216719}'
2024-10-21 17:40:16,746 - DEBUG - ++Rcv raw: b'\x81~\x00\xe4{"topic":"orderbook.50.BTCUSDT","type":"delta","ts":1729525216873,"data":{"s":"BTCUSDT","b":[],"a":[["67627.30","0.001"],["67640.90","0.001"],["68426.80","0"],["68430.90","0"]],"u":10130032,"seq":9374133572},"cts":1729525216867}'
2024-10-21 17:40:16,749 - DEBUG - ++Rcv decoded: fin=1 opcode=1 data=b'{"topic":"orderbook.50.BTCUSDT","type":"delta","ts":1729525216873,"data":{"s":"BTCUSDT","b":[],"a":[["67627.30","0.001"],["67640.90","0.001"],["68426.80","0"],["68430.90","0"]],"u":10130032,"seq":9374133572},"cts":1729525216867}'
2024-10-21 17:40:17,737 - DEBUG - ++Rcv raw: b'\x81~\x00\xbe{"topic":"orderbook.50.BTCUSDT","type":"delta","ts":1729525217873,"data":{"s":"BTCUSDT","b":[],"a":[["67654.50","0.001"],["68425.00","0"]],"u":10130033,"seq":9374133575},"cts":1729525217867}'
2024-10-21 17:40:17,740 - DEBUG - ++Rcv decoded: fin=1 opcode=1 data=b'{"topic":"orderbook.50.BTCUSDT","type":"delta","ts":1729525217873,"data":{"s":"BTCUSDT","b":[],"a":[["67654.50","0.001"],["68425.00","0"]],"u":10130033,"seq":9374133575},"cts":1729525217867}'
2024-10-21 17:40:18,717 - DEBUG - ++Rcv raw: b'\x81~\x01D{"topic":"orderbook.50.BTCUSDT","type":"delta","ts":1729525218852,"data":{"s":"BTCUSDT","b":[["67622.30","0"],["67621.50","0"],["67613.60","0.079"],["67277.30","0.089"],["67249.40","0.129"]],"a":[["67786.40","0.002"],["67792.00","0.426"],["68400.00","0"],["68416.40","0"]],"u":10130034,"seq":9374133603},"cts":1729525218843}'
2024-10-21 17:40:18,719 - DEBUG - ++Rcv decoded: fin=1 opcode=1 data=b'{"topic":"orderbook.50.BTCUSDT","type":"delta","ts":1729525218852,"data":{"s":"BTCUSDT","b":[["67622.30","0"],["67621.50","0"],["67613.60","0.079"],["67277.30","0.089"],["67249.40","0.129"]],"a":[["67786.40","0.002"],["67792.00","0.426"],["68400.00","0"],["68416.40","0"]],"u":10130034,"seq":9374133603},"cts":1729525218843}'
2024-10-21 17:40:24,092 - DEBUG - ++Rcv raw: b'\x81~\x00\xbe{"topic":"orderbook.50.BTCUSDT","type":"delta","ts":1729525224193,"data":{"s":"BTCUSDT","b":[["67623.60","0.001"],["67249.40","0"]],"a":[],"u":10130035,"seq":9374133609},"cts":1729525224188}'
2024-10-21 17:40:24,115 - DEBUG - ++Rcv decoded: fin=1 opcode=1 data=b'{"topic":"orderbook.50.BTCUSDT","type":"delta","ts":1729525224193,"data":{"s":"BTCUSDT","b":[["67623.60","0.001"],["67249.40","0"]],"a":[],"u":10130035,"seq":9374133609},"cts":1729525224188}'
2024-10-21 17:40:26,984 - DEBUG - ++Rcv raw: b'\x81~\x01 {"topic":"orderbook.50.BTCUSDT","type":"delta","ts":1729525227073,"data":{"s":"BTCUSDT","b":[["67623.60","0"],["67613.60","0"],["67560.80","199.010"],["67249.40","0.129"],["67233.30","0.001"]],"a":[["67777.00","0.686"],["68366.60","0"]],"u":10130036,"seq":9374133636},"cts":1729525227063}'
2024-10-21 17:40:26,999 - DEBUG - ++Rcv decoded: fin=1 opcode=1 data=b'{"topic":"orderbook.50.BTCUSDT","type":"delta","ts":1729525227073,"data":{"s":"BTCUSDT","b":[["67623.60","0"],["67613.60","0"],["67560.80","199.010"],["67249.40","0.129"],["67233.30","0.001"]],"a":[["67777.00","0.686"],["68366.60","0"]],"u":10130036,"seq":9374133636},"cts":1729525227063}'
2024-10-21 17:40:28,598 - DEBUG - ++Rcv raw: b'\x81~\x00\xbe{"topic":"orderbook.50.BTCUSDT","type":"delta","ts":1729525228673,"data":{"s":"BTCUSDT","b":[],"a":[["67597.00","0.598"],["68346.40","0"]],"u":10130037,"seq":9374133638},"cts":1729525228668}'
2024-10-21 17:40:28,614 - DEBUG - ++Rcv decoded: fin=1 opcode=1 data=b'{"topic":"orderbook.50.BTCUSDT","type":"delta","ts":1729525228673,"data":{"s":"BTCUSDT","b":[],"a":[["67597.00","0.598"],["68346.40","0"]],"u":10130037,"seq":9374133638},"cts":1729525228668}'
2024-10-21 17:40:28,763 - DEBUG - ++Rcv raw: b'\x81~\x01\n{"topic":"orderbook.50.BTCUSDT","type":"delta","ts":1729525228892,"data":{"s":"BTCUSDT","b":[],"a":[["67627.30","0"],["67640.90","0"],["67654.50","0"],["68346.40","0.089"],["68366.60","0.057"],["68400.00","0.566"]],"u":10130038,"seq":9374133641},"cts":1729525228874}'
2024-10-21 17:40:28,769 - DEBUG - ++Rcv decoded: fin=1 opcode=1 data=b'{"topic":"orderbook.50.BTCUSDT","type":"delta","ts":1729525228892,"data":{"s":"BTCUSDT","b":[],"a":[["67627.30","0"],["67640.90","0"],["67654.50","0"],["68346.40","0.089"],["68366.60","0.057"],["68400.00","0.566"]],"u":10130038,"seq":9374133641},"cts":1729525228874}'
2024-10-21 17:40:30,329 - DEBUG - ++Sent raw: b'\x81\x8eu\xbbM\x08\x0e\x99"xW\x81m*\x05\xd2#oW\xc6'
2024-10-21 17:40:30,354 - DEBUG - ++Sent decoded: fin=1 opcode=1 data=b'{"op": "ping"}'
2024-10-21 17:40:30,773 - DEBUG - ++Rcv raw: b'\x81~\x01\n{"topic":"orderbook.50.BTCUSDT","type":"delta","ts":1729525230892,"data":{"s":"BTCUSDT","b":[],"a":[["67560.90","0.001"],["67574.60","0.001"],["67588.10","0.001"],["68346.40","0"],["68366.60","0"],["68400.00","0"]],"u":10130039,"seq":9374133647},"cts":1729525230875}'
2024-10-21 17:40:30,800 - DEBUG - ++Rcv decoded: fin=1 opcode=1 data=b'{"topic":"orderbook.50.BTCUSDT","type":"delta","ts":1729525230892,"data":{"s":"BTCUSDT","b":[],"a":[["67560.90","0.001"],["67574.60","0.001"],["67588.10","0.001"],["68346.40","0"],["68366.60","0"],["68400.00","0"]],"u":10130039,"seq":9374133647},"cts":1729525230875}'
2024-10-21 17:40:30,885 - DEBUG - ++Rcv raw: b'\x81j{"success":true,"ret_msg":"pong","conn_id":"b69c54ab-2655-4654-85a5-01a30766f9e9","req_id":"","op":"ping"}'
2024-10-21 17:40:30,905 - DEBUG - ++Rcv decoded: fin=1 opcode=1 data=b'{"success":true,"ret_msg":"pong","conn_id":"b69c54ab-2655-4654-85a5-01a30766f9e9","req_id":"","op":"ping"}'
2024-10-21 17:40:33,202 - DEBUG - ++Rcv raw: b'\x81~\x00\xbe{"topic":"orderbook.50.BTCUSDT","type":"delta","ts":1729525233293,"data":{"s":"BTCUSDT","b":[],"a":[["67587.00","0.001"],["68334.70","0"]],"u":10130040,"seq":9374133651},"cts":1729525233274}'
2024-10-21 17:40:33,223 - DEBUG - ++Rcv decoded: fin=1 opcode=1 data=b'{"topic":"orderbook.50.BTCUSDT","type":"delta","ts":1729525233293,"data":{"s":"BTCUSDT","b":[],"a":[["67587.00","0.001"],["68334.70","0"]],"u":10130040,"seq":9374133651},"cts":1729525233274}'
2024-10-21 17:40:33,858 - DEBUG - ++Rcv raw: b'\x81~\x00\xbe{"topic":"orderbook.50.BTCUSDT","type":"delta","ts":1729525233972,"data":{"s":"BTCUSDT","b":[],"a":[["67560.90","0"],["68334.70","0.606"]],"u":10130041,"seq":9374133654},"cts":1729525233950}'
2024-10-21 17:40:33,874 - DEBUG - ++Rcv decoded: fin=1 opcode=1 data=b'{"topic":"orderbook.50.BTCUSDT","type":"delta","ts":1729525233972,"data":{"s":"BTCUSDT","b":[],"a":[["67560.90","0"],["68334.70","0.606"]],"u":10130041,"seq":9374133654},"cts":1729525233950}'
2024-10-21 17:40:34,559 - DEBUG - ++Rcv raw: b'\x81~\x00\xaf{"topic":"orderbook.50.BTCUSDT","type":"delta","ts":1729525234652,"data":{"s":"BTCUSDT","b":[["67560.80","199.009"]],"a":[],"u":10130042,"seq":9374133657},"cts":1729525234635}'
2024-10-21 17:40:34,591 - DEBUG - ++Rcv decoded: fin=1 opcode=1 data=b'{"topic":"orderbook.50.BTCUSDT","type":"delta","ts":1729525234652,"data":{"s":"BTCUSDT","b":[["67560.80","199.009"]],"a":[],"u":10130042,"seq":9374133657},"cts":1729525234635}'
2024-10-21 17:40:34,822 - DEBUG - ++Rcv raw: b'\x81~\x00\xbe{"topic":"orderbook.50.BTCUSDT","type":"delta","ts":1729525234893,"data":{"s":"BTCUSDT","b":[],"a":[["67561.00","0.001"],["68334.70","0"]],"u":10130043,"seq":9374133658},"cts":1729525234878}'
2024-10-21 17:40:34,837 - DEBUG - ++Rcv decoded: fin=1 opcode=1 data=b'{"topic":"orderbook.50.BTCUSDT","type":"delta","ts":1729525234893,"data":{"s":"BTCUSDT","b":[],"a":[["67561.00","0.001"],["68334.70","0"]],"u":10130043,"seq":9374133658},"cts":1729525234878}'
2024-10-21 17:40:38,692 - DEBUG - ++Rcv raw: b'\x81~\x00\xbe{"topic":"orderbook.50.BTCUSDT","type":"delta","ts":1729525238812,"data":{"s":"BTCUSDT","b":[],"a":[["67587.00","0"],["68334.70","0.606"]],"u":10130044,"seq":9374133666},"cts":1729525238798}'
2024-10-21 17:40:38,724 - DEBUG - ++Rcv decoded: fin=1 opcode=1 data=b'{"topic":"orderbook.50.BTCUSDT","type":"delta","ts":1729525238812,"data":{"s":"BTCUSDT","b":[],"a":[["67587.00","0"],["68334.70","0.606"]],"u":10130044,"seq":9374133666},"cts":1729525238798}'
2024-10-21 17:40:39,409 - DEBUG - ++Rcv raw: b'\x81~\x00\xbe{"topic":"orderbook.50.BTCUSDT","type":"delta","ts":1729525239513,"data":{"s":"BTCUSDT","b":[],"a":[["67587.00","0.001"],["68334.70","0"]],"u":10130045,"seq":9374133671},"cts":1729525239498}'
2024-10-21 17:40:39,440 - DEBUG - ++Rcv decoded: fin=1 opcode=1 data=b'{"topic":"orderbook.50.BTCUSDT","type":"delta","ts":1729525239513,"data":{"s":"BTCUSDT","b":[],"a":[["67587.00","0.001"],["68334.70","0"]],"u":10130045,"seq":9374133671},"cts":1729525239498}'
2024-10-21 17:41:42,342 - INFO - WebSocket Unified V5 (Auth) attempting connection...
2024-10-21 17:41:45,592 - INFO - Websocket connected
2024-10-21 17:41:45,592 - INFO - WebSocket Unified V5 (Auth) connected
2024-10-21 17:43:44,107 - INFO - WebSocket Unified V5 (Auth) attempting connection...
2024-10-21 17:43:47,187 - INFO - Websocket connected
2024-10-21 17:43:47,187 - INFO - WebSocket Unified V5 (Auth) connected
2024-10-21 17:43:47,648 - ERROR - Couldn't subscribe to topic.Error: error:handler not found,topic:orderbook.10.BTCUSDT.
2024-10-21 17:43:47,648 - ERROR - error from callback <function _WebSocketManager._connect.<locals>.<lambda> at 0x000001A51AA8B880>: '{'
2024-10-21 17:43:48,106 - ERROR - error from callback <function _WebSocketManager._connect.<locals>.<lambda> at 0x000001A51AA8BB00>: '{'
2024-10-21 17:43:48,106 - INFO - tearing down on exception '{'
2024-10-21 17:47:43,829 - INFO - WebSocket Unified V5 (Auth) attempting connection...
2024-10-21 17:47:46,915 - INFO - Websocket connected
2024-10-21 17:47:46,915 - INFO - WebSocket Unified V5 (Auth) connected
2024-10-21 17:47:47,356 - ERROR - Couldn't subscribe to topic.Error: error:handler not found,topic:orderbook.10.BTCUSDT.
2024-10-21 17:47:47,356 - ERROR - error from callback <function _WebSocketManager._connect.<locals>.<lambda> at 0x0000020F65CF85E0>: '{'
2024-10-21 17:47:47,811 - ERROR - error from callback <function _WebSocketManager._connect.<locals>.<lambda> at 0x0000020F65CF87C0>: '{'
2024-10-21 17:47:47,811 - INFO - tearing down on exception '{'
2024-10-21 17:51:11,227 - INFO - WebSocket Unified V5 (Auth) attempting connection...
2024-10-21 17:51:14,331 - INFO - Websocket connected
2024-10-21 17:51:14,331 - INFO - WebSocket Unified V5 (Auth) connected
2024-10-21 17:51:14,767 - ERROR - Couldn't subscribe to topic.Error: error:handler not found,topic:orderbook.10.BTCUSDT.
2024-10-21 17:51:14,767 - ERROR - error from callback <function _WebSocketManager._connect.<locals>.<lambda> at 0x000001F5CE8BC5E0>: '{'
2024-10-21 17:51:15,222 - ERROR - error from callback <function _WebSocketManager._connect.<locals>.<lambda> at 0x000001F5CE8BC7C0>: '{'
2024-10-21 17:51:15,222 - INFO - tearing down on exception '{'
2024-10-21 17:52:04,516 - INFO - WebSocket Unified V5 (Auth) attempting connection...
2024-10-21 17:52:07,458 - INFO - Websocket connected
2024-10-21 17:52:07,460 - INFO - WebSocket Unified V5 (Auth) connected
2024-10-21 17:52:07,908 - ERROR - Couldn't subscribe to topic.Error: error:handler not found,topic:orderbook.10.BTCUSDT.
2024-10-21 17:52:07,908 - ERROR - error from callback <function _WebSocketManager._connect.<locals>.<lambda> at 0x000001BA13BBC5E0>: '{'
2024-10-21 17:52:08,359 - ERROR - error from callback <function _WebSocketManager._connect.<locals>.<lambda> at 0x000001BA13BBC7C0>: '{'
2024-10-21 17:52:08,359 - INFO - tearing down on exception '{'
2024-10-21 17:52:49,447 - INFO - WebSocket Unified V5 (Auth) attempting connection...
2024-10-21 17:52:51,704 - DEBUG - --- request header ---
2024-10-21 17:52:51,720 - DEBUG - GET /v5/public/linear HTTP/1.1
Upgrade: websocket
Host: stream-testnet.bybit.com
Origin: https://stream-testnet.bybit.com
Sec-WebSocket-Key: NCAI5E5tp93ZVvQWcuKGbQ==
Sec-WebSocket-Version: 13
Connection: Upgrade


2024-10-21 17:52:51,738 - DEBUG - -----------------------
2024-10-21 17:52:51,755 - DEBUG - --- response header ---
2024-10-21 17:52:52,896 - DEBUG - HTTP/1.1 101 Switching Protocols
2024-10-21 17:52:52,929 - DEBUG - Connection: upgrade
2024-10-21 17:52:52,960 - DEBUG - Date: Mon, 21 Oct 2024 15:52:52 GMT
2024-10-21 17:52:52,987 - DEBUG - Upgrade: websocket
2024-10-21 17:52:53,018 - DEBUG - Sec-WebSocket-Accept: QHhwlqSySytSIaepMT+8vMtqREk=
2024-10-21 17:52:53,065 - DEBUG - X-Cache: Miss from cloudfront
2024-10-21 17:52:53,080 - DEBUG - Via: 1.1 7f9811832df4c0ab77fe1a54ea6ba566.cloudfront.net (CloudFront)
2024-10-21 17:52:53,108 - DEBUG - X-Amz-Cf-Pop: JFK52-P6
2024-10-21 17:52:53,154 - DEBUG - X-Amz-Cf-Id: fcEm-8j0wzlG-hC_4YA6DzuIeKg7_CciqmEOu-28iIu_rfmWkkyhUw==
2024-10-21 17:52:53,170 - DEBUG - -----------------------
2024-10-21 17:52:53,186 - INFO - WebSocket Unified V5 (Auth) connected
2024-10-21 17:52:53,186 - INFO - Websocket connected
2024-10-21 17:52:53,191 - DEBUG - ++Sent raw: b'\x81\xe7J\xc9U\xfb1\xeb:\x8bh\xf3u\xd99\xbc7\x88)\xbb<\x99/\xeby\xdbh\xbb0\x8a\x15\xa01\xd9p\xe9w\xcb,\xff7\x9e|\xffm\xd6{\xa8e\xccg\xfdm\xcc{\xe44\xc2{\xf9x\x9a+\xa8l\xc9s\xf86\xce/\xa8`\xd9f\xe9w\x9a8\xae&\xd9p\xe9\x0e\xd9%\xbb1\x9e8\xab:\x94!\xe7d\xcbd\x8b\x01\xb8\x1f\x9a\x11\xafh\x94('
2024-10-21 17:52:53,191 - DEBUG - ++Sent decoded: fin=1 opcode=1 data=b'{"op": "subscribe", "req_id": "0f6be668-1a07-4871-a910-aaa9291c5ea5", "args": ["orderbook.10.BTCUSDT"]}'
2024-10-21 17:52:53,639 - DEBUG - ++Rcv raw: b'\x81~\x00\xc2{"success":false,"ret_msg":"error:handler not found,topic:orderbook.10.BTCUSDT","conn_id":"b464c560-e4d0-4f74-9460-ef43ce01df31","req_id":"0f6be668-1a07-4871-a910-aaa9291c5ea5","op":"subscribe"}'
2024-10-21 17:52:53,639 - DEBUG - ++Rcv decoded: fin=1 opcode=1 data=b'{"success":false,"ret_msg":"error:handler not found,topic:orderbook.10.BTCUSDT","conn_id":"b464c560-e4d0-4f74-9460-ef43ce01df31","req_id":"0f6be668-1a07-4871-a910-aaa9291c5ea5","op":"subscribe"}'
2024-10-21 17:52:53,639 - ERROR - Couldn't subscribe to topic.Error: error:handler not found,topic:orderbook.10.BTCUSDT.
2024-10-21 17:52:53,639 - ERROR - error from callback <function _WebSocketManager._connect.<locals>.<lambda> at 0x0000028891DFC5E0>: '{'
2024-10-21 17:52:53,639 - DEBUG - ++Sent raw: b'\x88\x82\x88\xbf\xcc\xaf\x8bW'
2024-10-21 17:52:53,639 - DEBUG - ++Sent decoded: fin=1 opcode=8 data=b'\x03\xe8'
2024-10-21 17:52:54,091 - ERROR - error from callback <function _WebSocketManager._connect.<locals>.<lambda> at 0x0000028891DFC7C0>: '{'
2024-10-21 17:52:54,091 - INFO - tearing down on exception '{'
2024-10-21 18:38:51,719 - INFO - WebSocket Unified V5 (Auth) attempting connection...
2024-10-21 18:38:52,626 - DEBUG - --- request header ---
2024-10-21 18:38:52,641 - DEBUG - GET /v5/public/linear HTTP/1.1
Upgrade: websocket
Host: stream-testnet.bybit.com
Origin: https://stream-testnet.bybit.com
Sec-WebSocket-Key: MtauhC08ayBxSOExWSof4A==
Sec-WebSocket-Version: 13
Connection: Upgrade


2024-10-21 18:38:52,662 - DEBUG - -----------------------
2024-10-21 18:38:52,673 - DEBUG - --- response header ---
2024-10-21 18:38:53,553 - DEBUG - HTTP/1.1 101 Switching Protocols
2024-10-21 18:38:53,569 - DEBUG - Connection: upgrade
2024-10-21 18:38:53,576 - DEBUG - Date: Mon, 21 Oct 2024 16:38:54 GMT
2024-10-21 18:38:53,591 - DEBUG - Upgrade: websocket
2024-10-21 18:38:53,598 - DEBUG - Sec-WebSocket-Accept: VqiPbAiy79x3kKd/9lOqlUcyaTQ=
2024-10-21 18:38:53,611 - DEBUG - X-Cache: Miss from cloudfront
2024-10-21 18:38:53,638 - DEBUG - Via: 1.1 6738971dae8059801185cfa70ff9aeea.cloudfront.net (CloudFront)
2024-10-21 18:38:53,703 - DEBUG - X-Amz-Cf-Pop: SOF50-P1
2024-10-21 18:38:53,715 - DEBUG - X-Amz-Cf-Id: m4KoYlG5lNpt76NsVUhrIK8dR7__yFJX35RX1Pw7OnMteqrdSqUIkQ==
2024-10-21 18:38:53,729 - DEBUG - -----------------------
2024-10-21 18:38:53,745 - INFO - WebSocket Unified V5 (Auth) connected
2024-10-21 18:38:53,745 - INFO - Websocket connected
2024-10-21 18:38:53,745 - INFO - WebSocket Unified V5 (Auth) attempting connection...
2024-10-21 18:38:54,314 - DEBUG - --- request header ---
2024-10-21 18:38:54,347 - DEBUG - GET /v5/private HTTP/1.1
Upgrade: websocket
Host: stream-testnet.bybit.com
Origin: https://stream-testnet.bybit.com
Sec-WebSocket-Key: e37SoMr2+pFpj9VliviQUw==
Sec-WebSocket-Version: 13
Connection: Upgrade


2024-10-21 18:38:54,371 - DEBUG - -----------------------
2024-10-21 18:38:54,376 - DEBUG - --- response header ---
2024-10-21 18:38:55,222 - DEBUG - HTTP/1.1 101 Switching Protocols
2024-10-21 18:38:55,254 - DEBUG - Connection: upgrade
2024-10-21 18:38:55,286 - DEBUG - Date: Mon, 21 Oct 2024 16:38:55 GMT
2024-10-21 18:38:55,313 - DEBUG - Server: fasthttp
2024-10-21 18:38:55,320 - DEBUG - Upgrade: websocket
2024-10-21 18:38:55,341 - DEBUG - Sec-Websocket-Accept: +i4UvRH1nySJvLpNiOU8UaG7ets=
2024-10-21 18:38:55,348 - DEBUG - X-Cache: Miss from cloudfront
2024-10-21 18:38:55,489 - DEBUG - Via: 1.1 6738971dae8059801185cfa70ff9aeea.cloudfront.net (CloudFront)
2024-10-21 18:38:55,504 - DEBUG - X-Amz-Cf-Pop: SOF50-P1
2024-10-21 18:38:55,515 - DEBUG - X-Amz-Cf-Id: UHnbU35p_edo0Y2A0LyCkbJRR24IKZ-ce-TWrVs3vot0Da5TkbPsCw==
2024-10-21 18:38:55,541 - DEBUG - -----------------------
2024-10-21 18:38:55,577 - INFO - WebSocket Unified V5 (Auth) connected
2024-10-21 18:38:55,577 - INFO - Websocket connected
2024-10-21 18:38:55,577 - DEBUG - ++Sent raw: b'\x81\xfe\x00\x81{\x7f\xe5\x11\x00]\x8aaYE\xc53\x1a\n\x91yYS\xc53\x1a\r\x82bYE\xc5JY\x18\xa0i\x08\r\x88S\x1d\x1a\xa2)\x167\x90sKL\xb63W_\xd4&IF\xd0#CH\xd6\'NH\xd2=[]\xd6)\x1a\x1b\x81sB\x19\xd4 \x1fK\x87$O\x19\xd3%LH\xd2p\x1a\x1a\xd7!\x1fJ\x84!H\x1b\x87%\x19M\xd0(C\x19\xd6)\x18K\x83sLH\xd5%\x1a\x1e\xd6sJI\xd7"BG\xd2%I\x19\xc7L\x06'
2024-10-21 18:38:55,578 - DEBUG - ++Sent decoded: fin=1 opcode=1 data=b'{"op": "auth", "args": ["gExsrmBfeG8mHub03S", 1729528736577, "38addb9f11d4b54f64777aae20d5a03db4b2598f38c4fb7704aa3b162398742f"]}'
2024-10-21 18:38:55,578 - DEBUG - ++Sent raw: b'\x81\xdb\xb6\xc0\xa1\x8e\xcd\xe2\xce\xfe\x94\xfa\x81\xac\xc5\xb5\xc3\xfd\xd5\xb2\xc8\xec\xd3\xe2\x8d\xae\x94\xb2\xc4\xff\xe9\xa9\xc5\xac\x8c\xe0\x83\xb8\xd5\xf0\x99\xbc\x8e\xa5\x94\xa3\x8e\xf8\xc5\xb8\x9b\xf4\x94\xbd\x86\xed\xc3\xbb\xd2\xa1\x8c\xeb\xd5\xf6\x96\xba\xd3\xf5\x93\xbf\xd7\xf7\x92\xac\x9a\xe0\x83\xef\xc4\xa7\xd2\xac\x8c\xe0\xfa\xac\xc6\xaf\xd2\xe7\xc2\xa9\xce\xe0\x94\x9d\xdc'
2024-10-21 18:38:55,579 - DEBUG - ++Sent decoded: fin=1 opcode=1 data=b'{"op": "subscribe", "req_id": "6c0828e5-88d6-4530-b5da-ec674e521a73", "args": ["position"]}'
2024-10-21 18:38:55,579 - DEBUG - ++Sent raw: b'\x81\xe7\xc9\xf1\xbd\xcd\xb2\xd3\xd2\xbd\xeb\xcb\x9d\xef\xba\x84\xdf\xbe\xaa\x83\xd4\xaf\xac\xd3\x91\xed\xeb\x83\xd8\xbc\x96\x98\xd9\xef\xf3\xd1\x9f\xfa\xfa\xc8\x8f\xfc\xff\xc4\xd9\xe0\xa8\xc9\x84\xff\xe4\xc5\xdb\xfc\xff\xdc\x85\xfd\xab\xc1\x90\xab\xab\x90\x88\xfd\xfb\xc9\x85\xfe\xac\x93\x85\xef\xe5\xd1\x9f\xac\xbb\x96\xce\xef\xf3\xd1\xe6\xef\xa6\x83\xd9\xa8\xbb\x93\xd2\xa2\xa2\xdf\x88\xfd\xe7\xb3\xe9\x8e\x9c\xa2\xf9\x99\xeb\xac\xc0'
2024-10-21 18:38:55,579 - DEBUG - ++Sent decoded: fin=1 opcode=1 data=b'{"op": "subscribe", "req_id": "7392165d-a892-4f16-80b0-fba502883eb8", "args": ["orderbook.50.BTCUSDT"]}'
2024-10-21 18:38:55,982 - DEBUG - ++Rcv raw: b'\x81O{"success":true,"ret_msg":"","op":"auth","conn_id":"cs88215daugsh3k2lv8g-di92"}'
2024-10-21 18:38:55,982 - DEBUG - ++Rcv raw: b'\x81~\x08\xd0{"topic":"orderbook.50.BTCUSDT","type":"snapshot","ts":1729528735873,"data":{"s":"BTCUSDT","b":[["67560.80","109.205"],["67560.50","0.002"],["67559.80","0.002"],["67555.00","0.001"],["67553.30","0.001"],["67550.80","0.397"],["67550.00","0.003"],["67544.60","0.089"],["67542.00","0.001"],["67541.20","0.129"],["67540.00","0.550"],["67537.60","0.001"],["67531.40","0.001"],["67516.50","0.001"],["67511.30","0.010"],["67507.80","0.001"],["67500.00","0.019"],["67494.30","0.004"],["67492.00","0.074"],["67489.80","0.918"],["67467.20","0.005"],["67461.30","0.443"],["67456.90","0.002"],["67454.90","0.001"],["67452.60","0.426"],["67450.20","0.686"],["67449.70","0.001"],["67399.70","0.001"],["67384.50","0.001"],["67376.10","0.450"],["67375.00","0.002"],["67368.90","0.001"],["67360.60","0.001"],["67349.70","2.513"],["67343.40","0.001"],["67333.30","0.021"],["67331.70","0.004"],["67322.10","0.001"],["67320.90","0.631"],["67300.00","0.057"],["67293.30","0.017"],["67292.80","0.002"],["67291.50","0.358"],["67290.00","0.552"],["67287.60","0.264"],["67286.80","0.185"],["67283.50","0.001"],["67282.90","0.426"],["67278.30","0.010"],["67277.30","0.089"]],"a":[["67560.90","0.073"],["67561.00","0.001"],["67571.00","0.002"],["67574.60","0.001"],["67587.00","0.001"],["67588.10","0.001"],["67597.00","0.597"],["67777.00","0.684"],["67786.40","0.003"],["67792.00","0.426"],["67801.10","0.319"],["67827.80","0.512"],["67833.30","0.057"],["67833.50","0.380"],["67900.00","0.003"],["67901.50","0.009"],["67931.00","0.035"],["67951.70","0.002"],["67961.70","0.236"],["67970.90","0.443"],["67986.60","0.017"],["67996.70","0.918"],["68000.00","0.005"],["68027.10","0.001"],["68030.00","0.553"],["68056.90","0.264"],["68070.40","0.113"],["68075.00","0.003"],["68077.50","0.459"],["68079.10","0.089"],["68100.00","0.070"],["68108.00","0.001"],["68117.50","0.002"],["68124.60","0.129"],["68131.30","0.426"],["68140.80","0.443"],["68165.70","0.658"],["68188.40","0.001"],["68216.50","0.281"],["68250.00","0.003"],["68254.00","0.459"],["68275.00","0.001"],["68283.60","0.002"],["68295.90","0.001"],["68296.10","0.010"],["68297.40","0.010"],["68301.00","0.426"],["68308.40","0.549"],["68310.70","0.443"],["68311.70","0.020"]],"u":10135882,"seq":9374154504},"cts":1729528735352}'
2024-10-21 18:38:55,982 - DEBUG - ++Rcv decoded: fin=1 opcode=1 data=b'{"success":true,"ret_msg":"","op":"auth","conn_id":"cs88215daugsh3k2lv8g-di92"}'
2024-10-21 18:38:55,998 - DEBUG - ++Rcv decoded: fin=1 opcode=1 data=b'{"topic":"orderbook.50.BTCUSDT","type":"snapshot","ts":1729528735873,"data":{"s":"BTCUSDT","b":[["67560.80","109.205"],["67560.50","0.002"],["67559.80","0.002"],["67555.00","0.001"],["67553.30","0.001"],["67550.80","0.397"],["67550.00","0.003"],["67544.60","0.089"],["67542.00","0.001"],["67541.20","0.129"],["67540.00","0.550"],["67537.60","0.001"],["67531.40","0.001"],["67516.50","0.001"],["67511.30","0.010"],["67507.80","0.001"],["67500.00","0.019"],["67494.30","0.004"],["67492.00","0.074"],["67489.80","0.918"],["67467.20","0.005"],["67461.30","0.443"],["67456.90","0.002"],["67454.90","0.001"],["67452.60","0.426"],["67450.20","0.686"],["67449.70","0.001"],["67399.70","0.001"],["67384.50","0.001"],["67376.10","0.450"],["67375.00","0.002"],["67368.90","0.001"],["67360.60","0.001"],["67349.70","2.513"],["67343.40","0.001"],["67333.30","0.021"],["67331.70","0.004"],["67322.10","0.001"],["67320.90","0.631"],["67300.00","0.057"],["67293.30","0.017"],["67292.80","0.002"],["67291.50","0.358"],["67290.00","0.552"],["67287.60","0.264"],["67286.80","0.185"],["67283.50","0.001"],["67282.90","0.426"],["67278.30","0.010"],["67277.30","0.089"]],"a":[["67560.90","0.073"],["67561.00","0.001"],["67571.00","0.002"],["67574.60","0.001"],["67587.00","0.001"],["67588.10","0.001"],["67597.00","0.597"],["67777.00","0.684"],["67786.40","0.003"],["67792.00","0.426"],["67801.10","0.319"],["67827.80","0.512"],["67833.30","0.057"],["67833.50","0.380"],["67900.00","0.003"],["67901.50","0.009"],["67931.00","0.035"],["67951.70","0.002"],["67961.70","0.236"],["67970.90","0.443"],["67986.60","0.017"],["67996.70","0.918"],["68000.00","0.005"],["68027.10","0.001"],["68030.00","0.553"],["68056.90","0.264"],["68070.40","0.113"],["68075.00","0.003"],["68077.50","0.459"],["68079.10","0.089"],["68100.00","0.070"],["68108.00","0.001"],["68117.50","0.002"],["68124.60","0.129"],["68131.30","0.426"],["68140.80","0.443"],["68165.70","0.658"],["68188.40","0.001"],["68216.50","0.281"],["68250.00","0.003"],["68254.00","0.459"],["68275.00","0.001"],["68283.60","0.002"],["68295.90","0.001"],["68296.10","0.010"],["68297.40","0.010"],["68301.00","0.426"],["68308.40","0.549"],["68310.70","0.443"],["68311.70","0.020"]],"u":10135882,"seq":9374154504},"cts":1729528735352}'
2024-10-21 18:38:55,998 - DEBUG - ++Rcv raw: b'\x81~\x00\x84{"req_id":"6c0828e5-88d6-4530-b5da-ec674e521a73","success":true,"ret_msg":"","op":"subscribe","conn_id":"cs88215daugsh3k2lv8g-di92"}'
2024-10-21 18:38:56,007 - DEBUG - ++Rcv decoded: fin=1 opcode=1 data=b'{"req_id":"6c0828e5-88d6-4530-b5da-ec674e521a73","success":true,"ret_msg":"","op":"subscribe","conn_id":"cs88215daugsh3k2lv8g-di92"}'
2024-10-21 18:38:56,020 - DEBUG - ++Rcv raw: b'\x81~\x00\xaf{"topic":"orderbook.50.BTCUSDT","type":"delta","ts":1729528736133,"data":{"s":"BTCUSDT","b":[["67560.80","109.208"]],"a":[],"u":10135883,"seq":9374154505},"cts":1729528736122}'
2024-10-21 18:38:56,021 - DEBUG - ++Rcv decoded: fin=1 opcode=1 data=b'{"topic":"orderbook.50.BTCUSDT","type":"delta","ts":1729528736133,"data":{"s":"BTCUSDT","b":[["67560.80","109.208"]],"a":[],"u":10135883,"seq":9374154505},"cts":1729528736122}'
2024-10-21 18:38:56,028 - DEBUG - ++Rcv raw: b'\x81~\x00\x8f{"success":true,"ret_msg":"","conn_id":"9eb07089-9978-4766-8176-c04268c640fa","req_id":"7392165d-a892-4f16-80b0-fba502883eb8","op":"subscribe"}'
2024-10-21 18:38:56,028 - DEBUG - ++Rcv decoded: fin=1 opcode=1 data=b'{"success":true,"ret_msg":"","conn_id":"9eb07089-9978-4766-8176-c04268c640fa","req_id":"7392165d-a892-4f16-80b0-fba502883eb8","op":"subscribe"}'
2024-10-21 18:38:56,354 - DEBUG - ++Rcv raw: b'\x81~\x00\xad{"topic":"orderbook.50.BTCUSDT","type":"delta","ts":1729528736853,"data":{"s":"BTCUSDT","b":[],"a":[["67560.90","0.077"]],"u":10135884,"seq":9374154508},"cts":1729528736844}'
2024-10-21 18:38:56,370 - DEBUG - ++Rcv decoded: fin=1 opcode=1 data=b'{"topic":"orderbook.50.BTCUSDT","type":"delta","ts":1729528736853,"data":{"s":"BTCUSDT","b":[],"a":[["67560.90","0.077"]],"u":10135884,"seq":9374154508},"cts":1729528736844}'
2024-10-21 18:38:56,842 - DEBUG - ++Rcv raw: b'\x81~\x00\xaf{"topic":"orderbook.50.BTCUSDT","type":"delta","ts":1729528737332,"data":{"s":"BTCUSDT","b":[["67560.80","109.207"]],"a":[],"u":10135885,"seq":9374154509},"cts":1729528737313}'
2024-10-21 18:38:56,842 - DEBUG - ++Rcv decoded: fin=1 opcode=1 data=b'{"topic":"orderbook.50.BTCUSDT","type":"delta","ts":1729528737332,"data":{"s":"BTCUSDT","b":[["67560.80","109.207"]],"a":[],"u":10135885,"seq":9374154509},"cts":1729528737313}'
2024-10-21 18:38:56,909 - DEBUG - ++Rcv raw: b'\x81~\x00\xaf{"topic":"orderbook.50.BTCUSDT","type":"delta","ts":1729528737392,"data":{"s":"BTCUSDT","b":[["67560.80","109.208"]],"a":[],"u":10135886,"seq":9374154510},"cts":1729528737378}'
2024-10-21 18:38:56,909 - DEBUG - ++Rcv decoded: fin=1 opcode=1 data=b'{"topic":"orderbook.50.BTCUSDT","type":"delta","ts":1729528737392,"data":{"s":"BTCUSDT","b":[["67560.80","109.208"]],"a":[],"u":10135886,"seq":9374154510},"cts":1729528737378}'
2024-10-21 18:38:57,222 - DEBUG - ++Rcv raw: b'\x81~\x00\xad{"topic":"orderbook.50.BTCUSDT","type":"delta","ts":1729528737713,"data":{"s":"BTCUSDT","b":[],"a":[["67560.90","0.075"]],"u":10135887,"seq":9374154511},"cts":1729528737700}'
2024-10-21 18:38:57,222 - DEBUG - ++Rcv decoded: fin=1 opcode=1 data=b'{"topic":"orderbook.50.BTCUSDT","type":"delta","ts":1729528737713,"data":{"s":"BTCUSDT","b":[],"a":[["67560.90","0.075"]],"u":10135887,"seq":9374154511},"cts":1729528737700}'
2024-10-21 18:38:58,117 - DEBUG - ++Rcv raw: b'\x81~\x00\xad{"topic":"orderbook.50.BTCUSDT","type":"delta","ts":1729528738612,"data":{"s":"BTCUSDT","b":[],"a":[["67560.90","0.076"]],"u":10135888,"seq":9374154513},"cts":1729528738603}'
2024-10-21 18:38:58,117 - DEBUG - ++Rcv decoded: fin=1 opcode=1 data=b'{"topic":"orderbook.50.BTCUSDT","type":"delta","ts":1729528738612,"data":{"s":"BTCUSDT","b":[],"a":[["67560.90","0.076"]],"u":10135888,"seq":9374154513},"cts":1729528738603}'
2024-10-21 18:38:58,746 - DEBUG - ++Rcv raw: b'\x81~\x00\xbe{"topic":"orderbook.50.BTCUSDT","type":"delta","ts":1729528739233,"data":{"s":"BTCUSDT","b":[],"a":[["67587.00","0"],["68333.30","0.017"]],"u":10135889,"seq":9374154514},"cts":1729528739214}'
2024-10-21 18:38:58,746 - DEBUG - ++Rcv decoded: fin=1 opcode=1 data=b'{"topic":"orderbook.50.BTCUSDT","type":"delta","ts":1729528739233,"data":{"s":"BTCUSDT","b":[],"a":[["67587.00","0"],["68333.30","0.017"]],"u":10135889,"seq":9374154514},"cts":1729528739214}'
2024-10-21 18:38:59,308 - DEBUG - ++Rcv raw: b'\x81~\x00\xbe{"topic":"orderbook.50.BTCUSDT","type":"delta","ts":1729528739793,"data":{"s":"BTCUSDT","b":[],"a":[["67587.00","0.001"],["68333.30","0"]],"u":10135890,"seq":9374154515},"cts":1729528739778}'
2024-10-21 18:38:59,308 - DEBUG - ++Rcv decoded: fin=1 opcode=1 data=b'{"topic":"orderbook.50.BTCUSDT","type":"delta","ts":1729528739793,"data":{"s":"BTCUSDT","b":[],"a":[["67587.00","0.001"],["68333.30","0"]],"u":10135890,"seq":9374154515},"cts":1729528739778}'
2024-10-21 18:39:00,226 - DEBUG - ++Rcv raw: b'\x81~\x00\xad{"topic":"orderbook.50.BTCUSDT","type":"delta","ts":1729528740713,"data":{"s":"BTCUSDT","b":[],"a":[["67560.90","0.047"]],"u":10135891,"seq":9374154517},"cts":1729528740708}'
2024-10-21 18:39:00,226 - DEBUG - ++Rcv decoded: fin=1 opcode=1 data=b'{"topic":"orderbook.50.BTCUSDT","type":"delta","ts":1729528740713,"data":{"s":"BTCUSDT","b":[],"a":[["67560.90","0.047"]],"u":10135891,"seq":9374154517},"cts":1729528740708}'
2024-10-21 18:39:00,776 - DEBUG - ++Rcv raw: b'\x81~\x00\xaf{"topic":"orderbook.50.BTCUSDT","type":"delta","ts":1729528741272,"data":{"s":"BTCUSDT","b":[["67560.80","109.205"]],"a":[],"u":10135892,"seq":9374154519},"cts":1729528741252}'
2024-10-21 18:39:00,792 - DEBUG - ++Rcv decoded: fin=1 opcode=1 data=b'{"topic":"orderbook.50.BTCUSDT","type":"delta","ts":1729528741272,"data":{"s":"BTCUSDT","b":[["67560.80","109.205"]],"a":[],"u":10135892,"seq":9374154519},"cts":1729528741252}'
2024-10-21 18:39:00,807 - DEBUG - ++Rcv raw: b'\x81~\x00\xe4{"topic":"orderbook.50.BTCUSDT","type":"delta","ts":1729528741293,"data":{"s":"BTCUSDT","b":[["67560.50","0"],["67559.80","0"],["67249.40","0.129"],["67233.30","0.001"]],"a":[],"u":10135893,"seq":9374154523},"cts":1729528741276}'
2024-10-21 18:39:00,808 - DEBUG - ++Rcv decoded: fin=1 opcode=1 data=b'{"topic":"orderbook.50.BTCUSDT","type":"delta","ts":1729528741293,"data":{"s":"BTCUSDT","b":[["67560.50","0"],["67559.80","0"],["67249.40","0.129"],["67233.30","0.001"]],"a":[],"u":10135893,"seq":9374154523},"cts":1729528741276}'
2024-10-21 18:39:00,861 - DEBUG - ++Rcv raw: b'\x81~\x00\xc3{"topic":"orderbook.50.BTCUSDT","type":"delta","ts":1729528741352,"data":{"s":"BTCUSDT","b":[["67560.80","109.203"]],"a":[["67560.90","0.044"]],"u":10135894,"seq":9374154525},"cts":1729528741347}'
2024-10-21 18:39:00,861 - DEBUG - ++Rcv decoded: fin=1 opcode=1 data=b'{"topic":"orderbook.50.BTCUSDT","type":"delta","ts":1729528741352,"data":{"s":"BTCUSDT","b":[["67560.80","109.203"]],"a":[["67560.90","0.044"]],"u":10135894,"seq":9374154525},"cts":1729528741347}'
2024-10-21 18:39:00,908 - DEBUG - ++Rcv raw: b'\x81~\x00\xad{"topic":"orderbook.50.BTCUSDT","type":"delta","ts":1729528741392,"data":{"s":"BTCUSDT","b":[],"a":[["67560.90","0.042"]],"u":10135895,"seq":9374154526},"cts":1729528741369}'
2024-10-21 18:39:00,909 - DEBUG - ++Rcv decoded: fin=1 opcode=1 data=b'{"topic":"orderbook.50.BTCUSDT","type":"delta","ts":1729528741392,"data":{"s":"BTCUSDT","b":[],"a":[["67560.90","0.042"]],"u":10135895,"seq":9374154526},"cts":1729528741369}'
2024-10-21 18:39:00,953 - DEBUG - ++Rcv raw: b'\x81~\x00\xad{"topic":"orderbook.50.BTCUSDT","type":"delta","ts":1729528741432,"data":{"s":"BTCUSDT","b":[],"a":[["67560.90","0.040"]],"u":10135896,"seq":9374154527},"cts":1729528741428}'
2024-10-21 18:39:00,953 - DEBUG - ++Rcv decoded: fin=1 opcode=1 data=b'{"topic":"orderbook.50.BTCUSDT","type":"delta","ts":1729528741432,"data":{"s":"BTCUSDT","b":[],"a":[["67560.90","0.040"]],"u":10135896,"seq":9374154527},"cts":1729528741428}'
2024-10-21 18:39:01,117 - DEBUG - ++Rcv raw: b'\x81~\x00\xad{"topic":"orderbook.50.BTCUSDT","type":"delta","ts":1729528741612,"data":{"s":"BTCUSDT","b":[],"a":[["67560.90","0.038"]],"u":10135897,"seq":9374154528},"cts":1729528741590}'
2024-10-21 18:39:01,117 - DEBUG - ++Rcv decoded: fin=1 opcode=1 data=b'{"topic":"orderbook.50.BTCUSDT","type":"delta","ts":1729528741612,"data":{"s":"BTCUSDT","b":[],"a":[["67560.90","0.038"]],"u":10135897,"seq":9374154528},"cts":1729528741590}'
2024-10-21 18:39:03,221 - DEBUG - ++Rcv raw: b'\x81~\x00\xad{"topic":"orderbook.50.BTCUSDT","type":"delta","ts":1729528743712,"data":{"s":"BTCUSDT","b":[],"a":[["67560.90","0.036"]],"u":10135898,"seq":9374154531},"cts":1729528743709}'
2024-10-21 18:39:03,221 - DEBUG - ++Rcv decoded: fin=1 opcode=1 data=b'{"topic":"orderbook.50.BTCUSDT","type":"delta","ts":1729528743712,"data":{"s":"BTCUSDT","b":[],"a":[["67560.90","0.036"]],"u":10135898,"seq":9374154531},"cts":1729528743709}'
2024-10-21 18:39:03,247 - DEBUG - ++Rcv raw: b'\x81~\x00\xad{"topic":"orderbook.50.BTCUSDT","type":"delta","ts":1729528743732,"data":{"s":"BTCUSDT","b":[],"a":[["67560.90","0.034"]],"u":10135899,"seq":9374154535},"cts":1729528743726}'
2024-10-21 18:39:03,247 - DEBUG - ++Rcv decoded: fin=1 opcode=1 data=b'{"topic":"orderbook.50.BTCUSDT","type":"delta","ts":1729528743732,"data":{"s":"BTCUSDT","b":[],"a":[["67560.90","0.034"]],"u":10135899,"seq":9374154535},"cts":1729528743726}'
2024-10-21 18:39:04,819 - DEBUG - ++Rcv raw: b'\x81~\x00\xbe{"topic":"orderbook.50.BTCUSDT","type":"delta","ts":1729528745313,"data":{"s":"BTCUSDT","b":[],"a":[["67587.00","0"],["68333.30","0.017"]],"u":10135900,"seq":9374154536},"cts":1729528745298}'
2024-10-21 18:39:04,819 - DEBUG - ++Rcv decoded: fin=1 opcode=1 data=b'{"topic":"orderbook.50.BTCUSDT","type":"delta","ts":1729528745313,"data":{"s":"BTCUSDT","b":[],"a":[["67587.00","0"],["68333.30","0.017"]],"u":10135900,"seq":9374154536},"cts":1729528745298}'
2024-10-21 18:39:05,520 - DEBUG - ++Rcv raw: b'\x81~\x00\xbe{"topic":"orderbook.50.BTCUSDT","type":"delta","ts":1729528746012,"data":{"s":"BTCUSDT","b":[],"a":[["67587.00","0.001"],["68333.30","0"]],"u":10135901,"seq":9374154537},"cts":1729528745999}'
2024-10-21 18:39:05,520 - DEBUG - ++Rcv decoded: fin=1 opcode=1 data=b'{"topic":"orderbook.50.BTCUSDT","type":"delta","ts":1729528746012,"data":{"s":"BTCUSDT","b":[],"a":[["67587.00","0.001"],["68333.30","0"]],"u":10135901,"seq":9374154537},"cts":1729528745999}'
2024-10-21 18:39:07,288 - DEBUG - ++Rcv raw: b'\x81~\x00\xad{"topic":"orderbook.50.BTCUSDT","type":"delta","ts":1729528747773,"data":{"s":"BTCUSDT","b":[],"a":[["67560.90","0.033"]],"u":10135902,"seq":9374154540},"cts":1729528747750}'
2024-10-21 18:39:07,289 - DEBUG - ++Rcv decoded: fin=1 opcode=1 data=b'{"topic":"orderbook.50.BTCUSDT","type":"delta","ts":1729528747773,"data":{"s":"BTCUSDT","b":[],"a":[["67560.90","0.033"]],"u":10135902,"seq":9374154540},"cts":1729528747750}'
2024-10-21 18:39:10,518 - DEBUG - ++Rcv raw: b'\x81~\x00\xad{"topic":"orderbook.50.BTCUSDT","type":"delta","ts":1729528751012,"data":{"s":"BTCUSDT","b":[],"a":[["67560.90","0.051"]],"u":10135903,"seq":9374154542},"cts":1729528751000}'
2024-10-21 18:39:10,518 - DEBUG - ++Rcv decoded: fin=1 opcode=1 data=b'{"topic":"orderbook.50.BTCUSDT","type":"delta","ts":1729528751012,"data":{"s":"BTCUSDT","b":[],"a":[["67560.90","0.051"]],"u":10135903,"seq":9374154542},"cts":1729528751000}'
2024-10-21 18:39:11,046 - DEBUG - ++Rcv raw: b'\x81~\x00\xbe{"topic":"orderbook.50.BTCUSDT","type":"delta","ts":1729528751532,"data":{"s":"BTCUSDT","b":[],"a":[["67587.00","0"],["68333.30","0.017"]],"u":10135904,"seq":9374154545},"cts":1729528751525}'
2024-10-21 18:39:11,046 - DEBUG - ++Rcv decoded: fin=1 opcode=1 data=b'{"topic":"orderbook.50.BTCUSDT","type":"delta","ts":1729528751532,"data":{"s":"BTCUSDT","b":[],"a":[["67587.00","0"],["68333.30","0.017"]],"u":10135904,"seq":9374154545},"cts":1729528751525}'
2024-10-21 18:39:11,083 - DEBUG - ++Rcv raw: b'\x81~\x00\xaf{"topic":"orderbook.50.BTCUSDT","type":"delta","ts":1729528751572,"data":{"s":"BTCUSDT","b":[["67560.80","109.202"]],"a":[],"u":10135905,"seq":9374154546},"cts":1729528751564}'
2024-10-21 18:39:11,083 - DEBUG - ++Rcv decoded: fin=1 opcode=1 data=b'{"topic":"orderbook.50.BTCUSDT","type":"delta","ts":1729528751572,"data":{"s":"BTCUSDT","b":[["67560.80","109.202"]],"a":[],"u":10135905,"seq":9374154546},"cts":1729528751564}'
2024-10-21 18:39:11,484 - DEBUG - ++Rcv raw: b'\x81~\x00\xbe{"topic":"orderbook.50.BTCUSDT","type":"delta","ts":1729528751973,"data":{"s":"BTCUSDT","b":[],"a":[["67587.00","0.001"],["68333.30","0"]],"u":10135906,"seq":9374154547},"cts":1729528751957}'
2024-10-21 18:39:11,484 - DEBUG - ++Rcv decoded: fin=1 opcode=1 data=b'{"topic":"orderbook.50.BTCUSDT","type":"delta","ts":1729528751973,"data":{"s":"BTCUSDT","b":[],"a":[["67587.00","0.001"],["68333.30","0"]],"u":10135906,"seq":9374154547},"cts":1729528751957}'
2024-10-21 18:39:11,759 - DEBUG - ++Rcv raw: b'\x81~\x00\xaf{"topic":"orderbook.50.BTCUSDT","type":"delta","ts":1729528752252,"data":{"s":"BTCUSDT","b":[["67560.80","109.200"]],"a":[],"u":10135907,"seq":9374154549},"cts":1729528752244}'
2024-10-21 18:39:11,759 - DEBUG - ++Rcv decoded: fin=1 opcode=1 data=b'{"topic":"orderbook.50.BTCUSDT","type":"delta","ts":1729528752252,"data":{"s":"BTCUSDT","b":[["67560.80","109.200"]],"a":[],"u":10135907,"seq":9374154549},"cts":1729528752244}'
2024-10-21 18:39:13,755 - DEBUG - ++Sent raw: b'\x81\x8e\xfe\x82\xbf\x10\x85\xa0\xd0`\xdc\xb8\x9f2\x8e\xeb\xd1w\xdc\xff'
2024-10-21 18:39:13,755 - DEBUG - ++Sent decoded: fin=1 opcode=1 data=b'{"op": "ping"}'
2024-10-21 18:39:14,155 - DEBUG - ++Rcv raw: b'\x81j{"success":true,"ret_msg":"pong","conn_id":"9eb07089-9978-4766-8176-c04268c640fa","req_id":"","op":"ping"}'
2024-10-21 18:39:14,155 - DEBUG - ++Rcv decoded: fin=1 opcode=1 data=b'{"success":true,"ret_msg":"pong","conn_id":"9eb07089-9978-4766-8176-c04268c640fa","req_id":"","op":"ping"}'
2024-10-21 18:39:15,588 - DEBUG - ++Sent raw: b'\x81\x8e\x95A_9\xeec0I\xb7{\x7f\x1b\xe5(1^\xb7<'
2024-10-21 18:39:15,588 - DEBUG - ++Sent decoded: fin=1 opcode=1 data=b'{"op": "ping"}'
2024-10-21 18:39:15,731 - DEBUG - ++Sent raw: b'\x88\x82\xc7\xe1Le\xc4\t'
2024-10-21 18:39:15,731 - DEBUG - ++Sent decoded: fin=1 opcode=8 data=b'\x03\xe8'
2024-10-21 18:39:15,986 - DEBUG - ++Rcv raw: b'\x81L{"op":"pong","args":["1729528756486"],"conn_id":"cs88215daugsh3k2lv8g-di92"}'
2024-10-21 18:39:15,986 - DEBUG - ++Rcv decoded: fin=1 opcode=1 data=b'{"op":"pong","args":["1729528756486"],"conn_id":"cs88215daugsh3k2lv8g-di92"}'
2024-10-21 18:39:55,458 - INFO - WebSocket Unified V5 (Auth) attempting connection...
2024-10-21 18:39:56,513 - DEBUG - --- request header ---
2024-10-21 18:39:56,555 - DEBUG - GET /v5/public/linear HTTP/1.1
Upgrade: websocket
Host: stream-testnet.bybit.com
Origin: https://stream-testnet.bybit.com
Sec-WebSocket-Key: pMAjbKCBEcKAXcREIYgS1Q==
Sec-WebSocket-Version: 13
Connection: Upgrade


2024-10-21 18:39:56,579 - DEBUG - -----------------------
2024-10-21 18:39:56,620 - DEBUG - --- response header ---
2024-10-21 18:39:57,312 - DEBUG - HTTP/1.1 101 Switching Protocols
2024-10-21 18:39:57,328 - DEBUG - Connection: upgrade
2024-10-21 18:39:57,347 - DEBUG - Date: Mon, 21 Oct 2024 16:39:57 GMT
2024-10-21 18:39:57,370 - DEBUG - Upgrade: websocket
2024-10-21 18:39:57,447 - DEBUG - Sec-WebSocket-Accept: 8ufys9z2KIEa7mW72XOotUYXQhA=
2024-10-21 18:39:57,479 - DEBUG - X-Cache: Miss from cloudfront
2024-10-21 18:39:57,500 - DEBUG - Via: 1.1 c337a55bb25a3540411fbbf6c8ad1b46.cloudfront.net (CloudFront)
2024-10-21 18:39:57,527 - DEBUG - X-Amz-Cf-Pop: AMS1-P1
2024-10-21 18:39:57,552 - DEBUG - X-Amz-Cf-Id: UmhFSBfsss-GLsVbPR3QTQNgcwAVBtHSlwZnRYolClZuAJKFbCqzUA==
2024-10-21 18:39:57,579 - DEBUG - -----------------------
2024-10-21 18:39:57,620 - INFO - WebSocket Unified V5 (Auth) connected
2024-10-21 18:39:57,620 - INFO - Websocket connected
2024-10-21 18:39:57,620 - INFO - WebSocket Unified V5 (Auth) attempting connection...
2024-10-21 18:39:58,590 - DEBUG - --- request header ---
2024-10-21 18:39:58,612 - DEBUG - GET /v5/private HTTP/1.1
Upgrade: websocket
Host: stream-testnet.bybit.com
Origin: https://stream-testnet.bybit.com
Sec-WebSocket-Key: jHOPoVwCK/143ORjYnEjzQ==
Sec-WebSocket-Version: 13
Connection: Upgrade


2024-10-21 18:39:58,648 - DEBUG - -----------------------
2024-10-21 18:39:58,661 - DEBUG - --- response header ---
2024-10-21 18:39:59,392 - DEBUG - HTTP/1.1 101 Switching Protocols
2024-10-21 18:39:59,408 - DEBUG - Connection: upgrade
2024-10-21 18:39:59,438 - DEBUG - Date: Mon, 21 Oct 2024 16:39:59 GMT
2024-10-21 18:39:59,451 - DEBUG - Server: fasthttp
2024-10-21 18:39:59,465 - DEBUG - Upgrade: websocket
2024-10-21 18:39:59,481 - DEBUG - Sec-Websocket-Accept: Fgqd+eMOOPEaaqELy+kbxHULerE=
2024-10-21 18:39:59,495 - DEBUG - X-Cache: Miss from cloudfront
2024-10-21 18:39:59,551 - DEBUG - Via: 1.1 5e1e1cde81deec56515dcc5317501fe8.cloudfront.net (CloudFront)
2024-10-21 18:39:59,703 - DEBUG - X-Amz-Cf-Pop: AMS1-P1
2024-10-21 18:39:59,766 - DEBUG - X-Amz-Cf-Id: HrgNWWX2HiTBpUz3mXfM33uNqSmhaLpUSF3pCnYovNdxkqDYHGQbsg==
2024-10-21 18:39:59,781 - DEBUG - -----------------------
2024-10-21 18:39:59,798 - INFO - WebSocket Unified V5 (Auth) connected
2024-10-21 18:39:59,798 - INFO - Websocket connected
2024-10-21 18:39:59,798 - DEBUG - ++Sent raw: b"\x81\xfe\x00\x81\xcbo\xc5\x0c\xb0M\xaa|\xe9U\xe5.\xaa\x1a\xb1d\xe9C\xe5.\xaa\x1d\xa2\x7f\xe9U\xe5W\xe9\x08\x80t\xb8\x1d\xa8N\xad\n\x824\xa6'\xb0n\xfb\\\x96.\xe7O\xf4;\xf9V\xf0>\xf3W\xf5<\xfcV\xfd \xebM\xa0?\xf9\t\xf3:\xae\n\xf0h\xfb\x0b\xf0i\xaa\x0b\xf78\xa9X\xf7m\xfc\r\xf1=\xadX\xf1j\xff\n\xf0i\xae\r\xf1?\xfc\r\xa0;\xf3[\xa3o\xf9V\xf6o\xfa\x0e\xfc?\xfcY\xa49\xaf\x0c\xa05\xa9V\xe7Q\xb6"
2024-10-21 18:39:59,798 - DEBUG - ++Sent decoded: fin=1 opcode=1 data=b'{"op": "auth", "args": ["gExsrmBfeG8mHub03S", 1729528800798, "e32f66ee5d0d5ead24b72a7b41f74f4e5eeb437be784fc293c1a9376a5dce9b9"]}'
2024-10-21 18:39:59,799 - DEBUG - ++Sent raw: b'\x81\xdb\x01\xf6\xd5\xb2z\xd4\xba\xc2#\xcc\xf5\x90r\x83\xb7\xc1b\x84\xbc\xd0d\xd4\xf9\x92#\x84\xb0\xc3^\x9f\xb1\x90;\xd6\xf7\x86b\xcf\xb0\xd60\xce\xb4\x9fe\xcf\xb1\x8a,\xc2\xe7\xd02\xdb\xb7\xd38\xcf\xf8\x856\xc2\xe7\x832\x93\xed\x8a3\xc7\xb7\x90-\xd6\xf7\xd3s\x91\xa6\x90;\xd6\x8e\x90q\x99\xa6\xdbu\x9f\xba\xdc#\xab\xa8'
2024-10-21 18:39:59,799 - DEBUG - ++Sent decoded: fin=1 opcode=1 data=b'{"op": "subscribe", "req_id": "4c9ed18a-d9d8-42b3-ba99-774213e8821b", "args": ["position"]}'
2024-10-21 18:40:00,258 - DEBUG - ++Rcv raw: b'\x81P{"success":true,"ret_msg":"","op":"auth","conn_id":"crjtta1qo29j6gv0ald0-3mz5s"}'
2024-10-21 18:40:00,258 - DEBUG - ++Rcv decoded: fin=1 opcode=1 data=b'{"success":true,"ret_msg":"","op":"auth","conn_id":"crjtta1qo29j6gv0ald0-3mz5s"}'
2024-10-21 18:40:00,258 - DEBUG - ++Rcv raw: b'\x81~\x00\x85{"req_id":"4c9ed18a-d9d8-42b3-ba99-774213e8821b","success":true,"ret_msg":"","op":"subscribe","conn_id":"crjtta1qo29j6gv0ald0-3mz5s"}'
2024-10-21 18:40:00,258 - DEBUG - ++Rcv decoded: fin=1 opcode=1 data=b'{"req_id":"4c9ed18a-d9d8-42b3-ba99-774213e8821b","success":true,"ret_msg":"","op":"subscribe","conn_id":"crjtta1qo29j6gv0ald0-3mz5s"}'
2024-10-21 18:40:17,635 - DEBUG - ++Sent raw: b'\x81\x8e5\xd7\xcd\xfaN\xf5\xa2\x8a\x17\xed\xed\xd8E\xbe\xa3\x9d\x17\xaa'
2024-10-21 18:40:17,635 - DEBUG - ++Sent decoded: fin=1 opcode=1 data=b'{"op": "ping"}'
2024-10-21 18:40:18,092 - DEBUG - ++Rcv raw: b'\x81j{"success":true,"ret_msg":"pong","conn_id":"9b99a6a6-a7ee-45c1-9d0a-d92ff7a57886","req_id":"","op":"ping"}'
2024-10-21 18:40:18,092 - DEBUG - ++Rcv decoded: fin=1 opcode=1 data=b'{"success":true,"ret_msg":"pong","conn_id":"9b99a6a6-a7ee-45c1-9d0a-d92ff7a57886","req_id":"","op":"ping"}'
2024-10-21 18:40:19,809 - DEBUG - ++Sent raw: b"\x81\x8e\x05OI\xa9~m&\xd9'ui\x8bu&'\xce'2"
2024-10-21 18:40:19,809 - DEBUG - ++Sent decoded: fin=1 opcode=1 data=b'{"op": "ping"}'
2024-10-21 18:40:19,968 - DEBUG - ++Sent raw: b'\x88\x82S\x04$9P\xec'
2024-10-21 18:40:19,968 - DEBUG - ++Sent decoded: fin=1 opcode=8 data=b'\x03\xe8'
2024-10-21 18:40:20,250 - DEBUG - ++Rcv raw: b'\x81M{"op":"pong","args":["1729528820707"],"conn_id":"crjtta1qo29j6gv0ald0-3mz5s"}'
2024-10-21 18:40:20,250 - DEBUG - ++Rcv decoded: fin=1 opcode=1 data=b'{"op":"pong","args":["1729528820707"],"conn_id":"crjtta1qo29j6gv0ald0-3mz5s"}'
2024-10-22 08:14:33,051 - INFO - WebSocket Unified V5 (Auth) attempting connection...
2024-10-22 08:14:33,960 - DEBUG - --- request header ---
2024-10-22 08:14:33,991 - DEBUG - GET /v5/public/linear HTTP/1.1
Upgrade: websocket
Host: stream-testnet.bybit.com
Origin: https://stream-testnet.bybit.com
Sec-WebSocket-Key: D8rCyLJca9DmsTo6zjyVKA==
Sec-WebSocket-Version: 13
Connection: Upgrade


2024-10-22 08:14:34,022 - DEBUG - -----------------------
2024-10-22 08:14:34,037 - DEBUG - --- response header ---
2024-10-22 08:14:34,899 - DEBUG - HTTP/1.1 101 Switching Protocols
2024-10-22 08:14:34,914 - DEBUG - Connection: upgrade
2024-10-22 08:14:34,976 - DEBUG - Date: Tue, 22 Oct 2024 06:14:34 GMT
2024-10-22 08:14:34,991 - DEBUG - Upgrade: websocket
2024-10-22 08:14:35,114 - DEBUG - Sec-WebSocket-Accept: dJjuyYdxNO27wEE36oJfmpcP1QQ=
2024-10-22 08:14:35,160 - DEBUG - X-Cache: Miss from cloudfront
2024-10-22 08:14:35,222 - DEBUG - Via: 1.1 fa6ccc8f7e7d948277c6904aeb2ae7a2.cloudfront.net (CloudFront)
2024-10-22 08:14:35,251 - DEBUG - X-Amz-Cf-Pop: FRA60-P7
2024-10-22 08:14:35,267 - DEBUG - X-Amz-Cf-Id: iKI3pHMHNTCxQH9PusxhqIHoWnsVQCTZll-BTJGCYh-3QM17z2zBxQ==
2024-10-22 08:14:35,283 - DEBUG - -----------------------
2024-10-22 08:14:35,298 - INFO - WebSocket Unified V5 (Auth) connected
2024-10-22 08:14:35,298 - INFO - Websocket connected
2024-10-22 08:14:35,299 - INFO - WebSocket Unified V5 (Auth) attempting connection...
2024-10-22 08:14:35,960 - DEBUG - --- request header ---
2024-10-22 08:14:35,975 - DEBUG - GET /v5/private HTTP/1.1
Upgrade: websocket
Host: stream-testnet.bybit.com
Origin: https://stream-testnet.bybit.com
Sec-WebSocket-Key: oyzxYZHwBeA3JzytnK/WxQ==
Sec-WebSocket-Version: 13
Connection: Upgrade


2024-10-22 08:14:36,006 - DEBUG - -----------------------
2024-10-22 08:14:36,037 - DEBUG - --- response header ---
2024-10-22 08:14:36,886 - DEBUG - HTTP/1.1 101 Switching Protocols
2024-10-22 08:14:36,962 - DEBUG - Connection: upgrade
2024-10-22 08:14:36,993 - DEBUG - Date: Tue, 22 Oct 2024 06:14:36 GMT
2024-10-22 08:14:37,024 - DEBUG - Server: fasthttp
2024-10-22 08:14:37,039 - DEBUG - Upgrade: websocket
2024-10-22 08:14:37,086 - DEBUG - Sec-Websocket-Accept: UiQGHgMa1DbdqsZr8Y/34RKvQyg=
2024-10-22 08:14:37,116 - DEBUG - X-Cache: Miss from cloudfront
2024-10-22 08:14:37,147 - DEBUG - Via: 1.1 256cd380c9790a2b71d68709829caa18.cloudfront.net (CloudFront)
2024-10-22 08:14:37,162 - DEBUG - X-Amz-Cf-Pop: FRA60-P7
2024-10-22 08:14:37,208 - DEBUG - X-Amz-Cf-Id: pNlS07vyUDbWfxujW8GFpr5NiWpxkPZyYP_ZVMqclWjFRZvNRiti1A==
2024-10-22 08:14:37,240 - DEBUG - -----------------------
2024-10-22 08:14:37,269 - INFO - WebSocket Unified V5 (Auth) connected
2024-10-22 08:14:37,269 - INFO - Websocket connected
2024-10-22 08:14:37,271 - DEBUG - ++Sent raw: b'\x81\xfe\x00\x81-\x0f\xf3\xcdV-\x9c\xbd\x0f5\xd3\xefLz\x87\xa5\x0f#\xd3\xefL}\x94\xbe\x0f5\xd3\x96\x0fh\xb6\xb5^}\x9e\x8fKj\xb4\xf5@G\x86\xaf\x1d<\xa0\xef\x01/\xc2\xfa\x1f6\xc6\xfa\x1a9\xc4\xf5\x1f9\xca\xe1\r-\xc5\xfc\x1c9\xc4\xfbL9\xc1\xfc\x1e>\x95\xa9\x1ci\xca\xaf\x1d:\xcb\xf9\x1c?\xc2\xa8H>\xcb\xa9\x18:\x96\xabN>\xc1\xae\x14;\xc2\xa9\x14k\x92\xfeH9\xc7\xaf\x14l\x96\xacOm\x92\xac\x1c?\x96\xfd\x159\xd1\x90P'
2024-10-22 08:14:37,271 - DEBUG - ++Sent decoded: fin=1 opcode=1 data=b'{"op": "auth", "args": ["gExsrmBfeG8mHub03S", 1729577678269, "611676a62131fd1f9b0584101ee18d55efc12c941d9da3e64b9ceabbaa10e086"]}'
2024-10-22 08:14:37,272 - DEBUG - ++Sent raw: b'\x81\xdb\xfd\x92f\xe3\x86\xb0\t\x93\xdf\xa8F\xc1\x8e\xe7\x04\x90\x9e\xe0\x0f\x81\x98\xb0J\xc3\xdf\xe0\x03\x92\xa2\xfb\x02\xc1\xc7\xb2D\x82\xc9\xf6\x03\x80\x99\xa4\x07\xce\xce\xf0P\xd6\xd0\xa6\x03\xd1\xcd\xbf^\x85\x99\xa6K\x80\xcc\xf7P\xd1\xca\xa5^\xd6\xc4\xf3U\xc1\xd1\xb2D\x82\x8f\xf5\x15\xc1\xc7\xb2=\xc1\x8d\xfd\x15\x8a\x89\xfb\t\x8d\xdf\xcf\x1b'
2024-10-22 08:14:37,272 - DEBUG - ++Sent decoded: fin=1 opcode=1 data=b'{"op": "subscribe", "req_id": "a4decd6a-3b65-4e20-8fd4-c1e6277859a3", "args": ["position"]}'
2024-10-22 08:14:37,727 - DEBUG - ++Rcv raw: b'\x81O{"success":true,"ret_msg":"","op":"auth","conn_id":"cs88215daugsh3k2lv8g-f0if"}'
2024-10-22 08:14:37,727 - DEBUG - ++Rcv decoded: fin=1 opcode=1 data=b'{"success":true,"ret_msg":"","op":"auth","conn_id":"cs88215daugsh3k2lv8g-f0if"}'
2024-10-22 08:14:37,745 - DEBUG - ++Rcv raw: b'\x81~\x00\x84{"req_id":"a4decd6a-3b65-4e20-8fd4-c1e6277859a3","success":true,"ret_msg":"","op":"subscribe","conn_id":"cs88215daugsh3k2lv8g-f0if"}'
2024-10-22 08:14:37,745 - DEBUG - ++Rcv decoded: fin=1 opcode=1 data=b'{"req_id":"a4decd6a-3b65-4e20-8fd4-c1e6277859a3","success":true,"ret_msg":"","op":"subscribe","conn_id":"cs88215daugsh3k2lv8g-f0if"}'
2024-10-22 08:14:55,308 - DEBUG - ++Sent raw: b'\x81\x8e\xbb\x02\xe5M\xc0 \x8a=\x998\xc5o\xcbk\x8b*\x99\x7f'
2024-10-22 08:14:55,309 - DEBUG - ++Sent decoded: fin=1 opcode=1 data=b'{"op": "ping"}'
2024-10-22 08:14:55,704 - DEBUG - ++Rcv raw: b'\x81j{"success":true,"ret_msg":"pong","conn_id":"2c0a0d0b-8baf-427c-8ca7-e51a2f261466","req_id":"","op":"ping"}'
2024-10-22 08:14:55,705 - DEBUG - ++Rcv decoded: fin=1 opcode=1 data=b'{"success":true,"ret_msg":"pong","conn_id":"2c0a0d0b-8baf-427c-8ca7-e51a2f261466","req_id":"","op":"ping"}'
2024-10-22 08:14:57,286 - DEBUG - ++Sent raw: b'\x81\x8e\xc8\x00\x81\x1a\xb3"\xeej\xea:\xa18\xb8i\xef}\xea}'
2024-10-22 08:14:57,287 - DEBUG - ++Sent decoded: fin=1 opcode=1 data=b'{"op": "ping"}'
2024-10-22 08:14:57,379 - DEBUG - ++Sent raw: b'\x88\x82<\x98gx?p'
2024-10-22 08:14:57,379 - DEBUG - ++Sent decoded: fin=1 opcode=8 data=b'\x03\xe8'
2024-10-22 08:14:57,681 - DEBUG - ++Rcv raw: b'\x81L{"op":"pong","args":["1729577697146"],"conn_id":"cs88215daugsh3k2lv8g-f0if"}'
2024-10-22 08:14:57,681 - DEBUG - ++Rcv decoded: fin=1 opcode=1 data=b'{"op":"pong","args":["1729577697146"],"conn_id":"cs88215daugsh3k2lv8g-f0if"}'
2024-10-22 08:57:45,223 - INFO - WebSocket Unified V5 (Auth) attempting connection...
2024-10-22 08:57:46,294 - DEBUG - --- request header ---
2024-10-22 08:57:46,309 - DEBUG - GET /v5/public/linear HTTP/1.1
Upgrade: websocket
Host: stream-testnet.bybit.com
Origin: https://stream-testnet.bybit.com
Sec-WebSocket-Key: GkbjPrk0z8FMWilYzFl4tA==
Sec-WebSocket-Version: 13
Connection: Upgrade


2024-10-22 08:57:46,340 - DEBUG - -----------------------
2024-10-22 08:57:46,386 - DEBUG - --- response header ---
2024-10-22 08:57:47,202 - DEBUG - HTTP/1.1 101 Switching Protocols
2024-10-22 08:57:47,233 - DEBUG - Connection: upgrade
2024-10-22 08:57:47,264 - DEBUG - Date: Tue, 22 Oct 2024 06:57:46 GMT
2024-10-22 08:57:47,280 - DEBUG - Upgrade: websocket
2024-10-22 08:57:47,295 - DEBUG - Sec-WebSocket-Accept: kVmk9Dz933Cf4bsBslqebwIi3Ic=
2024-10-22 08:57:47,357 - DEBUG - X-Cache: Miss from cloudfront
2024-10-22 08:57:47,419 - DEBUG - Via: 1.1 d619c47997370e0eec10214d0a828f18.cloudfront.net (CloudFront)
2024-10-22 08:57:47,435 - DEBUG - X-Amz-Cf-Pop: VIE50-P3
2024-10-22 08:57:47,450 - DEBUG - X-Amz-Cf-Id: Cq0uer0bYNsSzJ3BugEczV0cKhHdWRXrIx87xQ0T8Wk4_kJDRXCbBA==
2024-10-22 08:57:47,511 - DEBUG - -----------------------
2024-10-22 08:57:47,526 - INFO - WebSocket Unified V5 (Auth) connected
2024-10-22 08:57:47,526 - INFO - Websocket connected
2024-10-22 08:57:47,528 - INFO - WebSocket Unified V5 (Auth) attempting connection...
2024-10-22 08:57:48,161 - DEBUG - --- request header ---
2024-10-22 08:57:48,192 - DEBUG - GET /v5/private HTTP/1.1
Upgrade: websocket
Host: stream-testnet.bybit.com
Origin: https://stream-testnet.bybit.com
Sec-WebSocket-Key: CgguB7lu8RswLNwGQ+VKmg==
Sec-WebSocket-Version: 13
Connection: Upgrade


2024-10-22 08:57:48,207 - DEBUG - -----------------------
2024-10-22 08:57:48,222 - DEBUG - --- response header ---
2024-10-22 08:57:49,042 - DEBUG - HTTP/1.1 101 Switching Protocols
2024-10-22 08:57:49,057 - DEBUG - Connection: upgrade
2024-10-22 08:57:49,103 - DEBUG - Date: Tue, 22 Oct 2024 06:57:48 GMT
2024-10-22 08:57:49,119 - DEBUG - Server: fasthttp
2024-10-22 08:57:49,149 - DEBUG - Upgrade: websocket
2024-10-22 08:57:49,180 - DEBUG - Sec-Websocket-Accept: ggsr6ImhSFyQqtKyQO528awpD4A=
2024-10-22 08:57:49,257 - DEBUG - X-Cache: Miss from cloudfront
2024-10-22 08:57:49,272 - DEBUG - Via: 1.1 737fed785d02e253c0470db1605b490e.cloudfront.net (CloudFront)
2024-10-22 08:57:49,288 - DEBUG - X-Amz-Cf-Pop: VIE50-P3
2024-10-22 08:57:49,319 - DEBUG - X-Amz-Cf-Id: BQEXgcrMa8rPZzUiE3W-74RglNQP5NIpFRyjoUgZw1RHt7-3C9mlyg==
2024-10-22 08:57:49,334 - DEBUG - -----------------------
2024-10-22 08:57:49,350 - INFO - WebSocket Unified V5 (Auth) connected
2024-10-22 08:57:49,350 - INFO - Websocket connected
2024-10-22 08:57:49,350 - DEBUG - ++Sent raw: b'\x81\xfe\x00\x81<2\xe0\x91G\x10\x8f\xe1\x1e\x08\xc0\xb3]G\x94\xf9\x1e\x1e\xc0\xb3]@\x87\xe2\x1e\x08\xc0\xca\x1eU\xa5\xe9O@\x8d\xd3ZW\xa7\xa9Qz\x95\xf3\x0c\x01\xb3\xb3\x10\x12\xd1\xa6\x0e\x0b\xd5\xa9\x0c\x00\xd7\xa1\x0f\x07\xd0\xbd\x1c\x10\xd3\xa2\x05V\xd5\xa4^\x0b\x86\xf4\x0f\x03\x81\xa7\x0f\x07\x83\xf5\x05\n\x84\xf4XQ\x85\xf2Y\x00\x82\xf0\x05S\x83\xf5\x0c\x02\x86\xa2\t\x01\xd3\xa4\t\x07\xd6\xf5YS\xd0\xa3_\x02\xd0\xa1\r\n\xd2\xa0\x0fQ\xd4\xa3\r\x05\xc2\xccA'
2024-10-22 08:57:49,351 - DEBUG - ++Sent decoded: fin=1 opcode=1 data=b'{"op": "auth", "args": ["gExsrmBfeG8mHub03S", 1729580270350, "339d55b9fe31a635cd98dedcece2ba9acd00f35335556dea02c00018213c4217"]}'
2024-10-22 08:57:49,354 - DEBUG - ++Sent raw: b'\x81\xe7S\xb7\xbd\xf1(\x95\xd2\x81q\x8d\x9d\xd3 \xc2\xdf\x820\xc5\xd4\x936\x95\x91\xd1q\xc5\xd8\x80\x0c\xde\xd9\xd3i\x97\x9f\x95e\x80\x8a\xc1f\xd4\xde\xdc7\xd3\x84\xc6~\x83\x89\x90g\x9a\x85\xc2k\xd3\x90\xc3c\x86\xdb\xc7f\x81\x88\x97a\x86\x8a\xd3\x7f\x97\x9f\x90!\xd0\xce\xd3i\x97\xe6\xd3<\xc5\xd9\x94!\xd5\xd2\x9e8\x99\x88\xc1}\xf5\xe9\xb2\x06\xe4\xf9\xa5q\xea\xc0'
2024-10-22 08:57:49,355 - DEBUG - ++Sent decoded: fin=1 opcode=1 data=b'{"op": "subscribe", "req_id": "d67705cc-dd97-44a4-838d-201f6565f217", "args": ["orderbook.50.BTCUSDT"]}'
2024-10-22 08:57:49,753 - DEBUG - ++Rcv raw: b'\x81P{"success":true,"ret_msg":"","op":"auth","conn_id":"crjtta1qo29j6gv0ald0-3ojqz"}'
2024-10-22 08:57:49,754 - DEBUG - ++Rcv decoded: fin=1 opcode=1 data=b'{"success":true,"ret_msg":"","op":"auth","conn_id":"crjtta1qo29j6gv0ald0-3ojqz"}'
2024-10-22 08:57:49,755 - DEBUG - ++Rcv raw: b'\x81~\x08\xce{"topic":"orderbook.50.BTCUSDT","type":"snapshot","ts":1729580267874,"data":{"s":"BTCUSDT","b":[["67622.20","0.001"],["67621.50","0.002"],["67613.60","0.031"],["67601.10","0.514"],["67550.80","0.420"],["67550.00","0.003"],["67531.40","0.001"],["67500.00","0.013"],["67494.30","0.004"],["67489.80","0.918"],["67461.30","0.443"],["67456.90","0.002"],["67452.60","0.186"],["67450.20","0.212"],["67449.70","0.001"],["67432.20","0.523"],["67376.10","0.459"],["67375.00","0.003"],["67368.90","0.001"],["67343.40","0.001"],["67331.70","0.004"],["67322.10","0.001"],["67320.90","0.912"],["67300.00","0.057"],["67293.30","0.017"],["67292.80","0.002"],["67291.50","0.044"],["67290.00","0.057"],["67287.60","0.264"],["67286.80","0.670"],["67283.50","0.001"],["67282.90","0.426"],["67277.30","0.089"],["67263.30","0.547"],["67250.00","0.020"],["67249.40","0.129"],["67233.30","0.001"],["67223.60","0.002"],["67214.10","0.005"],["67201.90","0.153"],["67200.00","0.003"],["67169.10","0.004"],["67151.90","0.918"],["67129.00","0.002"],["67123.40","0.625"],["67122.90","0.001"],["67121.60","0.120"],["67113.20","0.424"],["67094.40","0.545"],["67035.70","0.001"]],"a":[["67622.30","0.001"],["67622.40","0.001"],["67636.10","0.001"],["67649.60","0.001"],["67792.00","0.426"],["67801.10","0.188"],["67803.00","0.112"],["67811.90","0.089"],["67827.80","0.523"],["67832.90","0.129"],["67833.30","0.057"],["67900.00","0.003"],["67901.50","0.459"],["67939.00","0.547"],["67951.70","0.002"],["67961.70","0.131"],["67970.90","0.443"],["67984.00","0.074"],["67986.60","0.017"],["67996.70","0.487"],["68000.00","0.050"],["68001.00","0.010"],["68008.80","0.005"],["68011.20","0.018"],["68027.10","0.001"],["68030.00","0.553"],["68039.80","0.593"],["68056.90","0.264"],["68068.10","0.001"],["68069.00","0.001"],["68075.00","0.003"],["68077.50","0.026"],["68079.10","0.089"],["68100.00","0.070"],["68107.90","0.547"],["68108.00","0.001"],["68115.60","0.005"],["68117.50","0.024"],["68124.60","0.129"],["68131.30","0.296"],["68140.80","0.443"],["68142.80","0.020"],["68165.70","0.918"],["68166.90","0.035"],["68188.40","0.001"],["68192.10","0.012"],["68202.30","0.020"],["68211.60","0.002"],["68216.50","0.281"],["68229.90","0.001"]],"u":10182281,"seq":9374365934},"cts":1729580267154}'
2024-10-22 08:57:49,758 - DEBUG - ++Rcv decoded: fin=1 opcode=1 data=b'{"topic":"orderbook.50.BTCUSDT","type":"snapshot","ts":1729580267874,"data":{"s":"BTCUSDT","b":[["67622.20","0.001"],["67621.50","0.002"],["67613.60","0.031"],["67601.10","0.514"],["67550.80","0.420"],["67550.00","0.003"],["67531.40","0.001"],["67500.00","0.013"],["67494.30","0.004"],["67489.80","0.918"],["67461.30","0.443"],["67456.90","0.002"],["67452.60","0.186"],["67450.20","0.212"],["67449.70","0.001"],["67432.20","0.523"],["67376.10","0.459"],["67375.00","0.003"],["67368.90","0.001"],["67343.40","0.001"],["67331.70","0.004"],["67322.10","0.001"],["67320.90","0.912"],["67300.00","0.057"],["67293.30","0.017"],["67292.80","0.002"],["67291.50","0.044"],["67290.00","0.057"],["67287.60","0.264"],["67286.80","0.670"],["67283.50","0.001"],["67282.90","0.426"],["67277.30","0.089"],["67263.30","0.547"],["67250.00","0.020"],["67249.40","0.129"],["67233.30","0.001"],["67223.60","0.002"],["67214.10","0.005"],["67201.90","0.153"],["67200.00","0.003"],["67169.10","0.004"],["67151.90","0.918"],["67129.00","0.002"],["67123.40","0.625"],["67122.90","0.001"],["67121.60","0.120"],["67113.20","0.424"],["67094.40","0.545"],["67035.70","0.001"]],"a":[["67622.30","0.001"],["67622.40","0.001"],["67636.10","0.001"],["67649.60","0.001"],["67792.00","0.426"],["67801.10","0.188"],["67803.00","0.112"],["67811.90","0.089"],["67827.80","0.523"],["67832.90","0.129"],["67833.30","0.057"],["67900.00","0.003"],["67901.50","0.459"],["67939.00","0.547"],["67951.70","0.002"],["67961.70","0.131"],["67970.90","0.443"],["67984.00","0.074"],["67986.60","0.017"],["67996.70","0.487"],["68000.00","0.050"],["68001.00","0.010"],["68008.80","0.005"],["68011.20","0.018"],["68027.10","0.001"],["68030.00","0.553"],["68039.80","0.593"],["68056.90","0.264"],["68068.10","0.001"],["68069.00","0.001"],["68075.00","0.003"],["68077.50","0.026"],["68079.10","0.089"],["68100.00","0.070"],["68107.90","0.547"],["68108.00","0.001"],["68115.60","0.005"],["68117.50","0.024"],["68124.60","0.129"],["68131.30","0.296"],["68140.80","0.443"],["68142.80","0.020"],["68165.70","0.918"],["68166.90","0.035"],["68188.40","0.001"],["68192.10","0.012"],["68202.30","0.020"],["68211.60","0.002"],["68216.50","0.281"],["68229.90","0.001"]],"u":10182281,"seq":9374365934},"cts":1729580267154}'
2024-10-22 08:57:56,863 - DEBUG - ++Rcv raw: b'\x81~\x00\x8f{"success":true,"ret_msg":"","conn_id":"56cc0902-ae1f-4617-851f-ff16ab61eb8e","req_id":"d67705cc-dd97-44a4-838d-201f6565f217","op":"subscribe"}'
2024-10-22 08:57:56,863 - DEBUG - ++Rcv decoded: fin=1 opcode=1 data=b'{"success":true,"ret_msg":"","conn_id":"56cc0902-ae1f-4617-851f-ff16ab61eb8e","req_id":"d67705cc-dd97-44a4-838d-201f6565f217","op":"subscribe"}'
2024-10-22 08:57:56,864 - DEBUG - ++Rcv raw: b'\x81~\x00\xe3{"topic":"orderbook.50.BTCUSDT","type":"delta","ts":1729580274272,"data":{"s":"BTCUSDT","b":[["67622.20","0"],["67033.30","0.057"]],"a":[["67622.30","0"],["68250.00","0.003"]],"u":10182282,"seq":9374365939},"cts":1729580274253}'
2024-10-22 08:57:56,865 - DEBUG - ++Rcv decoded: fin=1 opcode=1 data=b'{"topic":"orderbook.50.BTCUSDT","type":"delta","ts":1729580274272,"data":{"s":"BTCUSDT","b":[["67622.20","0"],["67033.30","0.057"]],"a":[["67622.30","0"],["68250.00","0.003"]],"u":10182282,"seq":9374365939},"cts":1729580274253}'
2024-10-22 08:57:59,222 - DEBUG - ++Rcv raw: b'\x81~\x00\xbe{"topic":"orderbook.50.BTCUSDT","type":"delta","ts":1729580276272,"data":{"s":"BTCUSDT","b":[],"a":[["67622.30","0.001"],["68250.00","0"]],"u":10182283,"seq":9374365943},"cts":1729580276251}'
2024-10-22 08:57:59,222 - DEBUG - ++Rcv decoded: fin=1 opcode=1 data=b'{"topic":"orderbook.50.BTCUSDT","type":"delta","ts":1729580276272,"data":{"s":"BTCUSDT","b":[],"a":[["67622.30","0.001"],["68250.00","0"]],"u":10182283,"seq":9374365943},"cts":1729580276251}'
2024-10-22 08:58:02,354 - DEBUG - ++Rcv raw: b'\x81~\x00\xbe{"topic":"orderbook.50.BTCUSDT","type":"delta","ts":1729580276492,"data":{"s":"BTCUSDT","b":[],"a":[["67622.20","0.001"],["67622.30","0"]],"u":10182284,"seq":9374365945},"cts":1729580276473}'
2024-10-22 08:58:02,354 - DEBUG - ++Rcv decoded: fin=1 opcode=1 data=b'{"topic":"orderbook.50.BTCUSDT","type":"delta","ts":1729580276492,"data":{"s":"BTCUSDT","b":[],"a":[["67622.20","0.001"],["67622.30","0"]],"u":10182284,"seq":9374365945},"cts":1729580276473}'
2024-10-22 08:58:04,872 - DEBUG - ++Rcv raw: b'\x81~\x00\xbe{"topic":"orderbook.50.BTCUSDT","type":"delta","ts":1729580276712,"data":{"s":"BTCUSDT","b":[],"a":[["67622.10","0.001"],["67622.20","0"]],"u":10182285,"seq":9374365946},"cts":1729580276694}'
2024-10-22 08:58:04,873 - DEBUG - ++Rcv decoded: fin=1 opcode=1 data=b'{"topic":"orderbook.50.BTCUSDT","type":"delta","ts":1729580276712,"data":{"s":"BTCUSDT","b":[],"a":[["67622.10","0.001"],["67622.20","0"]],"u":10182285,"seq":9374365946},"cts":1729580276694}'
2024-10-22 08:58:06,757 - DEBUG - ++Rcv raw: b'\x81~\x00\xbe{"topic":"orderbook.50.BTCUSDT","type":"delta","ts":1729580276933,"data":{"s":"BTCUSDT","b":[],"a":[["67622.00","0.001"],["67622.10","0"]],"u":10182286,"seq":9374365948},"cts":1729580276914}'
2024-10-22 08:58:06,757 - DEBUG - ++Rcv decoded: fin=1 opcode=1 data=b'{"topic":"orderbook.50.BTCUSDT","type":"delta","ts":1729580276933,"data":{"s":"BTCUSDT","b":[],"a":[["67622.00","0.001"],["67622.10","0"]],"u":10182286,"seq":9374365948},"cts":1729580276914}'
2024-10-22 08:58:07,529 - DEBUG - ++Sent raw: b'\x81\x8e\xf8\xaa\xa9\x17\x83\x88\xc6g\xda\x90\x895\x88\xc3\xc7p\xda\xd7'
2024-10-22 08:58:07,529 - DEBUG - ++Sent decoded: fin=1 opcode=1 data=b'{"op": "ping"}'
2024-10-22 08:58:08,703 - DEBUG - ++Rcv raw: b'\x81~\x00\xbe{"topic":"orderbook.50.BTCUSDT","type":"delta","ts":1729580277152,"data":{"s":"BTCUSDT","b":[],"a":[["67621.90","0.001"],["67622.00","0"]],"u":10182287,"seq":9374365951},"cts":1729580277136}'
2024-10-22 08:58:08,704 - DEBUG - ++Rcv decoded: fin=1 opcode=1 data=b'{"topic":"orderbook.50.BTCUSDT","type":"delta","ts":1729580277152,"data":{"s":"BTCUSDT","b":[],"a":[["67621.90","0.001"],["67622.00","0"]],"u":10182287,"seq":9374365951},"cts":1729580277136}'
2024-10-22 08:58:09,365 - DEBUG - ++Sent raw: b'\x81\x8e\xd1\x10\xd6\x08\xaa2\xb9x\xf3*\xf6*\xa1y\xb8o\xf3m'
2024-10-22 08:58:09,366 - DEBUG - ++Sent decoded: fin=1 opcode=1 data=b'{"op": "ping"}'
2024-10-22 08:58:09,537 - DEBUG - ++Rcv raw: b'\x81~\x00\xbe{"topic":"orderbook.50.BTCUSDT","type":"delta","ts":1729580277373,"data":{"s":"BTCUSDT","b":[],"a":[["67621.80","0.001"],["67621.90","0"]],"u":10182288,"seq":9374365952},"cts":1729580277353}'
2024-10-22 08:58:09,538 - DEBUG - ++Rcv decoded: fin=1 opcode=1 data=b'{"topic":"orderbook.50.BTCUSDT","type":"delta","ts":1729580277373,"data":{"s":"BTCUSDT","b":[],"a":[["67621.80","0.001"],["67621.90","0"]],"u":10182288,"seq":9374365952},"cts":1729580277353}'
2024-10-22 08:58:09,764 - DEBUG - ++Rcv raw: b'\x81M{"op":"pong","args":["1729580289262"],"conn_id":"crjtta1qo29j6gv0ald0-3ojqz"}'
2024-10-22 08:58:09,765 - DEBUG - ++Rcv decoded: fin=1 opcode=1 data=b'{"op":"pong","args":["1729580289262"],"conn_id":"crjtta1qo29j6gv0ald0-3ojqz"}'
2024-10-22 08:58:10,397 - DEBUG - ++Rcv raw: b'\x81~\x01k{"topic":"orderbook.50.BTCUSDT","type":"delta","ts":1729580277532,"data":{"s":"BTCUSDT","b":[],"a":[["67621.80","0"],["67622.40","0"],["67636.10","0"],["67649.60","0"],["67792.00","0"],["67801.10","0.169"],["68250.00","0.003"],["68254.00","0.459"],["68271.10","0.001"],["68275.00","0.001"],["68275.20","0.001"]],"u":10182289,"seq":9374365976},"cts":1729580277520}'
2024-10-22 08:58:10,398 - DEBUG - ++Rcv decoded: fin=1 opcode=1 data=b'{"topic":"orderbook.50.BTCUSDT","type":"delta","ts":1729580277532,"data":{"s":"BTCUSDT","b":[],"a":[["67621.80","0"],["67622.40","0"],["67636.10","0"],["67649.60","0"],["67792.00","0"],["67801.10","0.169"],["68250.00","0.003"],["68254.00","0.459"],["68271.10","0.001"],["68275.00","0.001"],["68275.20","0.001"]],"u":10182289,"seq":9374365976},"cts":1729580277520}'
2024-10-22 08:58:10,400 - DEBUG - ++Rcv raw: b'\x81~\x00\xbe{"topic":"orderbook.50.BTCUSDT","type":"delta","ts":1729580277552,"data":{"s":"BTCUSDT","b":[["67622.30","0.426"],["67033.30","0"]],"a":[],"u":10182290,"seq":9374365977},"cts":1729580277530}'
2024-10-22 08:58:10,401 - DEBUG - ++Rcv decoded: fin=1 opcode=1 data=b'{"topic":"orderbook.50.BTCUSDT","type":"delta","ts":1729580277552,"data":{"s":"BTCUSDT","b":[["67622.30","0.426"],["67033.30","0"]],"a":[],"u":10182290,"seq":9374365977},"cts":1729580277530}'
2024-10-22 08:58:10,403 - DEBUG - ++Rcv raw: b'\x81~\x01\n{"topic":"orderbook.50.BTCUSDT","type":"delta","ts":1729580278813,"data":{"s":"BTCUSDT","b":[],"a":[["67622.40","0.001"],["67636.10","0.001"],["67649.60","0.001"],["68271.10","0"],["68275.00","0"],["68275.20","0"]],"u":10182291,"seq":9374365980},"cts":1729580278806}'
2024-10-22 08:58:10,403 - DEBUG - ++Rcv decoded: fin=1 opcode=1 data=b'{"topic":"orderbook.50.BTCUSDT","type":"delta","ts":1729580278813,"data":{"s":"BTCUSDT","b":[],"a":[["67622.40","0.001"],["67636.10","0.001"],["67649.60","0.001"],["68271.10","0"],["68275.00","0"],["68275.20","0"]],"u":10182291,"seq":9374365980},"cts":1729580278806}'
2024-10-22 08:58:10,406 - DEBUG - ++Rcv raw: b'\x81~\x01E{"topic":"orderbook.50.BTCUSDT","type":"delta","ts":1729580280312,"data":{"s":"BTCUSDT","b":[],"a":[["67622.40","0"],["67636.10","0"],["67649.60","0"],["67801.10","0"],["67803.00","0.037"],["68271.10","0.001"],["68275.00","0.001"],["68275.20","0.001"],["68276.30","0.593"]],"u":10182292,"seq":9374365996},"cts":1729580280309}'
2024-10-22 08:58:10,406 - DEBUG - ++Rcv decoded: fin=1 opcode=1 data=b'{"topic":"orderbook.50.BTCUSDT","type":"delta","ts":1729580280312,"data":{"s":"BTCUSDT","b":[],"a":[["67622.40","0"],["67636.10","0"],["67649.60","0"],["67801.10","0"],["67803.00","0.037"],["68271.10","0.001"],["68275.00","0.001"],["68275.20","0.001"],["68276.30","0.593"]],"u":10182292,"seq":9374365996},"cts":1729580280309}'
2024-10-22 08:58:10,409 - DEBUG - ++Rcv raw: b'\x81~\x01j{"topic":"orderbook.50.BTCUSDT","type":"delta","ts":1729580280333,"data":{"s":"BTCUSDT","b":[["67658.80","0.459"],["67631.20","0.443"],["67544.60","0.089"],["67113.20","0"],["67094.40","0"],["67035.70","0"]],"a":[["67803.00","0"],["67811.90","0"],["67827.80","0.419"],["68276.80","0.547"],["68283.60","0.002"]],"u":10182293,"seq":9374366008},"cts":1729580280325}'
2024-10-22 08:58:10,409 - DEBUG - ++Rcv decoded: fin=1 opcode=1 data=b'{"topic":"orderbook.50.BTCUSDT","type":"delta","ts":1729580280333,"data":{"s":"BTCUSDT","b":[["67658.80","0.459"],["67631.20","0.443"],["67544.60","0.089"],["67113.20","0"],["67094.40","0"],["67035.70","0"]],"a":[["67803.00","0"],["67811.90","0"],["67827.80","0.419"],["68276.80","0.547"],["68283.60","0.002"]],"u":10182293,"seq":9374366008},"cts":1729580280325}'
2024-10-22 08:58:10,413 - DEBUG - ++Rcv raw: b'\x81~\x00\xbe{"topic":"orderbook.50.BTCUSDT","type":"delta","ts":1729580280473,"data":{"s":"BTCUSDT","b":[["67622.20","0.002"],["67121.60","0"]],"a":[],"u":10182294,"seq":9374366011},"cts":1729580280456}'
2024-10-22 08:58:10,413 - DEBUG - ++Rcv decoded: fin=1 opcode=1 data=b'{"topic":"orderbook.50.BTCUSDT","type":"delta","ts":1729580280473,"data":{"s":"BTCUSDT","b":[["67622.20","0.002"],["67121.60","0"]],"a":[],"u":10182294,"seq":9374366011},"cts":1729580280456}'
2024-10-22 08:58:10,416 - DEBUG - ++Rcv raw: b'\x81~\x01\n{"topic":"orderbook.50.BTCUSDT","type":"delta","ts":1729580281813,"data":{"s":"BTCUSDT","b":[],"a":[["67658.90","0.001"],["67672.60","0.001"],["67686.10","0.001"],["68276.30","0"],["68276.80","0"],["68283.60","0"]],"u":10182295,"seq":9374366014},"cts":1729580281807}'
2024-10-22 08:58:10,417 - DEBUG - ++Rcv decoded: fin=1 opcode=1 data=b'{"topic":"orderbook.50.BTCUSDT","type":"delta","ts":1729580281813,"data":{"s":"BTCUSDT","b":[],"a":[["67658.90","0.001"],["67672.60","0.001"],["67686.10","0.001"],["68276.30","0"],["68276.80","0"],["68283.60","0"]],"u":10182295,"seq":9374366014},"cts":1729580281807}'
2024-10-22 08:58:10,418 - DEBUG - ++Rcv raw: b'\x81~\x00\xbe{"topic":"orderbook.50.BTCUSDT","type":"delta","ts":1729580281912,"data":{"s":"BTCUSDT","b":[],"a":[["67802.90","0.591"],["68275.20","0"]],"u":10182296,"seq":9374366018},"cts":1729580281909}'
2024-10-22 08:58:10,418 - DEBUG - ++Rcv decoded: fin=1 opcode=1 data=b'{"topic":"orderbook.50.BTCUSDT","type":"delta","ts":1729580281912,"data":{"s":"BTCUSDT","b":[],"a":[["67802.90","0.591"],["68275.20","0"]],"u":10182296,"seq":9374366018},"cts":1729580281909}'
2024-10-22 08:58:10,420 - DEBUG - ++Rcv raw: b'\x81~\x00\xad{"topic":"orderbook.50.BTCUSDT","type":"delta","ts":1729580282972,"data":{"s":"BTCUSDT","b":[["67658.80","0.457"]],"a":[],"u":10182297,"seq":9374366019},"cts":1729580282967}'
2024-10-22 08:58:10,421 - DEBUG - ++Rcv decoded: fin=1 opcode=1 data=b'{"topic":"orderbook.50.BTCUSDT","type":"delta","ts":1729580282972,"data":{"s":"BTCUSDT","b":[["67658.80","0.457"]],"a":[],"u":10182297,"seq":9374366019},"cts":1729580282967}'
2024-10-22 08:58:10,423 - DEBUG - ++Rcv raw: b'\x81~\x00\xe3{"topic":"orderbook.50.BTCUSDT","type":"delta","ts":1729580282993,"data":{"s":"BTCUSDT","b":[["67655.00","0.001"],["67122.90","0"]],"a":[["67670.00","0.001"],["68275.00","0"]],"u":10182298,"seq":9374366021},"cts":1729580282985}'
2024-10-22 08:58:10,424 - DEBUG - ++Rcv decoded: fin=1 opcode=1 data=b'{"topic":"orderbook.50.BTCUSDT","type":"delta","ts":1729580282993,"data":{"s":"BTCUSDT","b":[["67655.00","0.001"],["67122.90","0"]],"a":[["67670.00","0.001"],["68275.00","0"]],"u":10182298,"seq":9374366021},"cts":1729580282985}'
2024-10-22 08:58:10,426 - DEBUG - ++Rcv raw: b'\x81~\x01/{"topic":"orderbook.50.BTCUSDT","type":"delta","ts":1729580283012,"data":{"s":"BTCUSDT","b":[["67650.00","0.001"],["67645.00","0.001"],["67129.00","0"],["67123.40","0"]],"a":[["67660.00","0.001"],["67665.00","0.001"],["68254.00","0"],["68271.10","0"]],"u":10182299,"seq":9374366025},"cts":1729580283002}'
2024-10-22 08:58:10,426 - DEBUG - ++Rcv decoded: fin=1 opcode=1 data=b'{"topic":"orderbook.50.BTCUSDT","type":"delta","ts":1729580283012,"data":{"s":"BTCUSDT","b":[["67650.00","0.001"],["67645.00","0.001"],["67129.00","0"],["67123.40","0"]],"a":[["67660.00","0.001"],["67665.00","0.001"],["68254.00","0"],["68271.10","0"]],"u":10182299,"seq":9374366025},"cts":1729580283002}'
2024-10-22 08:58:10,429 - DEBUG - ++Rcv raw: b'\x81j{"success":true,"ret_msg":"pong","conn_id":"56cc0902-ae1f-4617-851f-ff16ab61eb8e","req_id":"","op":"ping"}'
2024-10-22 08:58:10,429 - DEBUG - ++Rcv decoded: fin=1 opcode=1 data=b'{"success":true,"ret_msg":"pong","conn_id":"56cc0902-ae1f-4617-851f-ff16ab61eb8e","req_id":"","op":"ping"}'
2024-10-22 08:58:10,429 - DEBUG - ++Rcv raw: b'\x81~\x01E{"topic":"orderbook.50.BTCUSDT","type":"delta","ts":1729580289332,"data":{"s":"BTCUSDT","b":[["67658.80","0"],["67655.00","0"],["67650.00","0"],["67645.00","0"],["67631.20","0.431"],["67129.00","0.002"],["67123.40","0.625"],["67122.90","0.001"],["67121.60","0.120"]],"a":[],"u":10182300,"seq":9374366051},"cts":1729580289318}'
2024-10-22 08:58:10,430 - DEBUG - ++Rcv decoded: fin=1 opcode=1 data=b'{"topic":"orderbook.50.BTCUSDT","type":"delta","ts":1729580289332,"data":{"s":"BTCUSDT","b":[["67658.80","0"],["67655.00","0"],["67650.00","0"],["67645.00","0"],["67631.20","0.431"],["67129.00","0.002"],["67123.40","0.625"],["67122.90","0.001"],["67121.60","0.120"]],"a":[],"u":10182300,"seq":9374366051},"cts":1729580289318}'
2024-10-22 08:58:10,432 - DEBUG - ++Rcv raw: b'\x81~\x00\xad{"topic":"orderbook.50.BTCUSDT","type":"delta","ts":1729580289353,"data":{"s":"BTCUSDT","b":[],"a":[["67827.80","0.878"]],"u":10182301,"seq":9374366052},"cts":1729580289330}'
2024-10-22 08:58:10,433 - DEBUG - ++Rcv decoded: fin=1 opcode=1 data=b'{"topic":"orderbook.50.BTCUSDT","type":"delta","ts":1729580289353,"data":{"s":"BTCUSDT","b":[],"a":[["67827.80","0.878"]],"u":10182301,"seq":9374366052},"cts":1729580289330}'
2024-10-22 08:58:10,435 - DEBUG - ++Rcv raw: b'\x81~\x01U{"topic":"orderbook.50.BTCUSDT","type":"delta","ts":1729580289893,"data":{"s":"BTCUSDT","b":[["67655.00","0.001"],["67650.00","0.001"],["67645.00","0.001"],["67123.40","0"],["67122.90","0"],["67121.60","0"]],"a":[["67665.00","0"],["67670.00","0"],["68254.00","0.459"],["68271.10","0.001"]],"u":10182302,"seq":9374366057},"cts":1729580289885}'
2024-10-22 08:58:10,435 - DEBUG - ++Rcv decoded: fin=1 opcode=1 data=b'{"topic":"orderbook.50.BTCUSDT","type":"delta","ts":1729580289893,"data":{"s":"BTCUSDT","b":[["67655.00","0.001"],["67650.00","0.001"],["67645.00","0.001"],["67123.40","0"],["67122.90","0"],["67121.60","0"]],"a":[["67665.00","0"],["67670.00","0"],["68254.00","0.459"],["68271.10","0.001"]],"u":10182302,"seq":9374366057},"cts":1729580289885}'
2024-10-22 08:58:10,504 - DEBUG - ++Sent raw: b'\x88\x82w\x842\xfatl'
2024-10-22 08:58:10,505 - DEBUG - ++Sent decoded: fin=1 opcode=8 data=b'\x03\xe8'
2024-10-22 09:13:51,400 - INFO - WebSocket Unified V5 (Auth) attempting connection...
2024-10-22 09:13:52,370 - DEBUG - --- request header ---
2024-10-22 09:13:52,386 - DEBUG - GET /v5/public/linear HTTP/1.1
Upgrade: websocket
Host: stream-testnet.bybit.com
Origin: https://stream-testnet.bybit.com
Sec-WebSocket-Key: PPm/3EHpb0Bp23aKkH0bjw==
Sec-WebSocket-Version: 13
Connection: Upgrade


2024-10-22 09:13:52,416 - DEBUG - -----------------------
2024-10-22 09:13:52,432 - DEBUG - --- response header ---
2024-10-22 09:13:53,249 - DEBUG - HTTP/1.1 101 Switching Protocols
2024-10-22 09:13:53,326 - DEBUG - Connection: upgrade
2024-10-22 09:13:53,388 - DEBUG - Date: Tue, 22 Oct 2024 07:13:52 GMT
2024-10-22 09:13:53,403 - DEBUG - Upgrade: websocket
2024-10-22 09:13:53,434 - DEBUG - Sec-WebSocket-Accept: bBB5eOTJ2TuUZIhMgp4kXbsJsus=
2024-10-22 09:13:53,481 - DEBUG - X-Cache: Miss from cloudfront
2024-10-22 09:13:53,497 - DEBUG - Via: 1.1 737fed785d02e253c0470db1605b490e.cloudfront.net (CloudFront)
2024-10-22 09:13:53,559 - DEBUG - X-Amz-Cf-Pop: VIE50-P3
2024-10-22 09:13:53,574 - DEBUG - X-Amz-Cf-Id: Ax2jKZ46bi0cG9jvF7jmDcYKcsGcp4xCrlJbmtiY8XAejGa9iSdYeg==
2024-10-22 09:13:53,605 - DEBUG - -----------------------
2024-10-22 09:13:53,635 - INFO - WebSocket Unified V5 (Auth) connected
2024-10-22 09:13:53,635 - INFO - Websocket connected
2024-10-22 09:13:53,636 - INFO - WebSocket Unified V5 (Auth) attempting connection...
2024-10-22 09:13:54,282 - DEBUG - --- request header ---
2024-10-22 09:13:54,297 - DEBUG - GET /v5/private HTTP/1.1
Upgrade: websocket
Host: stream-testnet.bybit.com
Origin: https://stream-testnet.bybit.com
Sec-WebSocket-Key: 3R5DYG7zjYkp8ASDL4spCA==
Sec-WebSocket-Version: 13
Connection: Upgrade


2024-10-22 09:13:54,327 - DEBUG - -----------------------
2024-10-22 09:13:54,358 - DEBUG - --- response header ---
2024-10-22 09:13:55,204 - DEBUG - HTTP/1.1 101 Switching Protocols
2024-10-22 09:13:55,235 - DEBUG - Connection: upgrade
2024-10-22 09:13:55,266 - DEBUG - Date: Tue, 22 Oct 2024 07:13:54 GMT
2024-10-22 09:13:55,312 - DEBUG - Server: fasthttp
2024-10-22 09:13:55,358 - DEBUG - Upgrade: websocket
2024-10-22 09:13:55,420 - DEBUG - Sec-Websocket-Accept: nlab7OeuicquklYl30QUgRFZsvM=
2024-10-22 09:13:55,451 - DEBUG - X-Cache: Miss from cloudfront
2024-10-22 09:13:55,466 - DEBUG - Via: 1.1 fb5c24475d6ce2683fe1262475a1c24c.cloudfront.net (CloudFront)
2024-10-22 09:13:55,496 - DEBUG - X-Amz-Cf-Pop: VIE50-P3
2024-10-22 09:13:55,512 - DEBUG - X-Amz-Cf-Id: z8sOkwSR1Fi2epISwUN3DhCgndf8S0HKg94HuaK-2XkcFyMUOLgmvA==
2024-10-22 09:13:55,543 - DEBUG - -----------------------
2024-10-22 09:13:55,574 - INFO - WebSocket Unified V5 (Auth) connected
2024-10-22 09:13:55,574 - INFO - Websocket connected
2024-10-22 09:13:55,574 - DEBUG - ++Sent raw: b'\x81\xfe\x00\x81\xcfx\xa2\xdc\xb4Z\xcd\xac\xedB\x82\xfe\xae\r\xd6\xb4\xedT\x82\xfe\xae\n\xc5\xaf\xedB\x82\x87\xed\x1f\xe7\xa4\xbc\n\xcf\x9e\xa9\x1d\xe5\xe4\xa20\xd7\xbe\xffK\xf1\xfe\xe3X\x93\xeb\xfdA\x97\xe4\xfeJ\x91\xea\xfaO\x96\xf0\xefZ\xc7\xed\xae\x1e\xc6\xba\xab\x19\x94\xb8\xfd\x1a\x96\xef\xfd\x1e\x90\xb9\xfbJ\x93\xbd\xf7@\x97\xe9\xffN\x92\xbe\xacK\x93\xbf\xf6N\x90\xe8\xfd\x1e\x97\xeb\xfc\x1a\x94\xb8\xab\x1a\x90\xee\xaeA\x9a\xbf\xacJ\x92\xeb\xa9\x1d\xc7\xe4\xa9@\x80\x81\xb2'
2024-10-22 09:13:55,575 - DEBUG - ++Sent decoded: fin=1 opcode=1 data=b'{"op": "auth", "args": ["gExsrmBfeG8mHub03S", 1729581236574, "e1afdfda6d2b432f2e421a8855060bc31c96242f573b6ddb22a98cc207fee8f8"]}'
2024-10-22 09:13:55,576 - DEBUG - ++Sent raw: b'\x81\xe71\xe5\xcb\x83J\xc7\xa4\xf3\x13\xdf\xeb\xa1B\x90\xa9\xf0R\x97\xa2\xe1T\xc7\xe7\xa3\x13\x97\xae\xf2n\x8c\xaf\xa1\x0b\xc5\xe9\xb1\x01\xd7\xf2\xe0\x03\xd6\xfa\xaeP\xd2\xaf\xe0\x1c\xd1\xad\xb6T\xc8\xaa\xb2\x04\xd4\xe6\xba\x06\xd0\xf9\xe7T\xd4\xff\xe2\x05\xdd\xae\xa1\x1d\xc5\xe9\xe2C\x82\xb8\xa1\x0b\xc5\x90\xa1^\x97\xaf\xe6C\x87\xa4\xecZ\xcb\xfe\xb3\x1f\xa7\x9f\xc0d\xb6\x8f\xd7\x13\xb8\xb6'
2024-10-22 09:13:55,576 - DEBUG - ++Sent decoded: fin=1 opcode=1 data=b'{"op": "subscribe", "req_id": "2029c231-a7dc-4f5e-a151-9752de14a48e", "args": ["orderbook.50.BTCUSDT"]}'
2024-10-22 09:13:56,014 - DEBUG - ++Rcv raw: b'\x81P{"success":true,"ret_msg":"","op":"auth","conn_id":"crjtta1qo29j6gv0ald0-3okp4"}'
2024-10-22 09:13:56,015 - DEBUG - ++Rcv decoded: fin=1 opcode=1 data=b'{"success":true,"ret_msg":"","op":"auth","conn_id":"crjtta1qo29j6gv0ald0-3okp4"}'
2024-10-22 09:13:56,019 - DEBUG - ++Rcv raw: b'\x81~\x08\xce{"topic":"orderbook.50.BTCUSDT","type":"snapshot","ts":1729581231873,"data":{"s":"BTCUSDT","b":[["67496.80","0.001"],["67486.80","0.002"],["67461.30","0.259"],["67456.90","0.002"],["67452.60","0.426"],["67450.20","0.247"],["67432.20","0.547"],["67376.10","0.027"],["67375.00","0.003"],["67331.70","0.004"],["67322.10","0.001"],["67320.90","0.835"],["67300.00","0.057"],["67293.30","0.017"],["67292.80","0.002"],["67291.50","0.044"],["67290.00","0.057"],["67287.60","0.264"],["67286.80","0.670"],["67283.50","0.001"],["67282.90","0.426"],["67277.30","0.089"],["67263.30","0.547"],["67249.40","0.129"],["67233.30","0.001"],["67225.20","0.020"],["67223.60","0.002"],["67214.10","0.005"],["67201.90","0.153"],["67200.00","0.003"],["67169.10","0.004"],["67151.90","0.918"],["67129.00","0.002"],["67123.40","0.625"],["67122.90","0.001"],["67121.60","0.120"],["67113.20","0.424"],["67094.40","0.545"],["67035.70","0.001"],["67033.30","0.057"],["67028.10","0.459"],["67025.00","0.003"],["67010.00","0.089"],["67006.50","0.004"],["67006.10","0.001"],["67000.00","0.074"],["66992.80","0.281"],["66982.90","0.918"],["66965.70","0.002"],["66960.00","0.013"]],"a":[["67561.10","0.001"],["67566.40","0.502"],["67574.70","0.001"],["67656.90","0.004"],["67658.80","0.697"],["67725.00","0.003"],["67725.90","0.187"],["67770.10","0.547"],["67777.00","0.317"],["67779.30","0.001"],["67786.40","0.002"],["67792.00","0.426"],["67800.00","0.013"],["67801.10","0.443"],["67802.90","0.551"],["67811.90","0.089"],["67827.80","0.878"],["67832.90","0.129"],["67833.30","0.057"],["67833.40","0.001"],["67893.00","0.001"],["67900.00","0.003"],["67901.50","0.459"],["67928.30","0.001"],["67939.00","0.547"],["67951.70","0.002"],["67961.70","0.131"],["67970.90","0.443"],["67984.00","0.074"],["67985.20","0.001"],["67986.60","0.017"],["67996.70","0.487"],["68000.00","0.050"],["68001.00","0.010"],["68008.80","0.005"],["68011.20","0.018"],["68027.10","0.001"],["68030.00","0.553"],["68039.80","0.593"],["68056.90","0.264"],["68068.10","0.001"],["68069.00","0.001"],["68075.00","0.003"],["68077.50","0.026"],["68079.10","0.089"],["68100.00","0.070"],["68107.90","0.547"],["68108.00","0.001"],["68115.60","0.005"],["68117.50","0.024"]],"u":10184965,"seq":9374372749},"cts":1729581231792}'
2024-10-22 09:13:56,022 - DEBUG - ++Rcv decoded: fin=1 opcode=1 data=b'{"topic":"orderbook.50.BTCUSDT","type":"snapshot","ts":1729581231873,"data":{"s":"BTCUSDT","b":[["67496.80","0.001"],["67486.80","0.002"],["67461.30","0.259"],["67456.90","0.002"],["67452.60","0.426"],["67450.20","0.247"],["67432.20","0.547"],["67376.10","0.027"],["67375.00","0.003"],["67331.70","0.004"],["67322.10","0.001"],["67320.90","0.835"],["67300.00","0.057"],["67293.30","0.017"],["67292.80","0.002"],["67291.50","0.044"],["67290.00","0.057"],["67287.60","0.264"],["67286.80","0.670"],["67283.50","0.001"],["67282.90","0.426"],["67277.30","0.089"],["67263.30","0.547"],["67249.40","0.129"],["67233.30","0.001"],["67225.20","0.020"],["67223.60","0.002"],["67214.10","0.005"],["67201.90","0.153"],["67200.00","0.003"],["67169.10","0.004"],["67151.90","0.918"],["67129.00","0.002"],["67123.40","0.625"],["67122.90","0.001"],["67121.60","0.120"],["67113.20","0.424"],["67094.40","0.545"],["67035.70","0.001"],["67033.30","0.057"],["67028.10","0.459"],["67025.00","0.003"],["67010.00","0.089"],["67006.50","0.004"],["67006.10","0.001"],["67000.00","0.074"],["66992.80","0.281"],["66982.90","0.918"],["66965.70","0.002"],["66960.00","0.013"]],"a":[["67561.10","0.001"],["67566.40","0.502"],["67574.70","0.001"],["67656.90","0.004"],["67658.80","0.697"],["67725.00","0.003"],["67725.90","0.187"],["67770.10","0.547"],["67777.00","0.317"],["67779.30","0.001"],["67786.40","0.002"],["67792.00","0.426"],["67800.00","0.013"],["67801.10","0.443"],["67802.90","0.551"],["67811.90","0.089"],["67827.80","0.878"],["67832.90","0.129"],["67833.30","0.057"],["67833.40","0.001"],["67893.00","0.001"],["67900.00","0.003"],["67901.50","0.459"],["67928.30","0.001"],["67939.00","0.547"],["67951.70","0.002"],["67961.70","0.131"],["67970.90","0.443"],["67984.00","0.074"],["67985.20","0.001"],["67986.60","0.017"],["67996.70","0.487"],["68000.00","0.050"],["68001.00","0.010"],["68008.80","0.005"],["68011.20","0.018"],["68027.10","0.001"],["68030.00","0.553"],["68039.80","0.593"],["68056.90","0.264"],["68068.10","0.001"],["68069.00","0.001"],["68075.00","0.003"],["68077.50","0.026"],["68079.10","0.089"],["68100.00","0.070"],["68107.90","0.547"],["68108.00","0.001"],["68115.60","0.005"],["68117.50","0.024"]],"u":10184965,"seq":9374372749},"cts":1729581231792}'
2024-10-22 09:13:56,026 - DEBUG - ++Rcv raw: b'\x81~\x00\xd3{"topic":"orderbook.50.BTCUSDT","type":"delta","ts":1729581232573,"data":{"s":"BTCUSDT","b":[["67496.80","0"],["67486.80","0.001"],["66957.70","0.129"]],"a":[],"u":10184966,"seq":9374372750},"cts":1729581232557}'
2024-10-22 09:13:56,026 - DEBUG - ++Rcv decoded: fin=1 opcode=1 data=b'{"topic":"orderbook.50.BTCUSDT","type":"delta","ts":1729581232573,"data":{"s":"BTCUSDT","b":[["67496.80","0"],["67486.80","0.001"],["66957.70","0.129"]],"a":[],"u":10184966,"seq":9374372750},"cts":1729581232557}'
2024-10-22 09:13:56,027 - DEBUG - ++Rcv raw: b'\x81~\x00\xd3{"topic":"orderbook.50.BTCUSDT","type":"delta","ts":1729581233533,"data":{"s":"BTCUSDT","b":[["67486.80","0"],["67461.30","0.230"],["66957.60","0.010"]],"a":[],"u":10184967,"seq":9374372751},"cts":1729581233522}'
2024-10-22 09:13:56,028 - DEBUG - ++Rcv decoded: fin=1 opcode=1 data=b'{"topic":"orderbook.50.BTCUSDT","type":"delta","ts":1729581233533,"data":{"s":"BTCUSDT","b":[["67486.80","0"],["67461.30","0.230"],["66957.60","0.010"]],"a":[],"u":10184967,"seq":9374372751},"cts":1729581233522}'
2024-10-22 09:13:56,029 - DEBUG - ++Rcv raw: b'\x81~\x00\xbe{"topic":"orderbook.50.BTCUSDT","type":"delta","ts":1729581233732,"data":{"s":"BTCUSDT","b":[],"a":[["67561.00","0.001"],["68117.50","0"]],"u":10184968,"seq":9374372752},"cts":1729581233722}'
2024-10-22 09:13:56,029 - DEBUG - ++Rcv decoded: fin=1 opcode=1 data=b'{"topic":"orderbook.50.BTCUSDT","type":"delta","ts":1729581233732,"data":{"s":"BTCUSDT","b":[],"a":[["67561.00","0.001"],["68117.50","0"]],"u":10184968,"seq":9374372752},"cts":1729581233722}'
2024-10-22 09:13:56,030 - DEBUG - ++Rcv raw: b'\x81~\x00\xad{"topic":"orderbook.50.BTCUSDT","type":"delta","ts":1729581233753,"data":{"s":"BTCUSDT","b":[],"a":[["67561.00","0.002"]],"u":10184969,"seq":9374372753},"cts":1729581233742}'
2024-10-22 09:13:56,031 - DEBUG - ++Rcv decoded: fin=1 opcode=1 data=b'{"topic":"orderbook.50.BTCUSDT","type":"delta","ts":1729581233753,"data":{"s":"BTCUSDT","b":[],"a":[["67561.00","0.002"]],"u":10184969,"seq":9374372753},"cts":1729581233742}'
2024-10-22 09:13:56,032 - DEBUG - ++Rcv raw: b'\x81~\x00\xf9{"topic":"orderbook.50.BTCUSDT","type":"delta","ts":1729581235172,"data":{"s":"BTCUSDT","b":[],"a":[["67561.00","0"],["67561.10","0"],["67566.40","0.008"],["68117.50","0.024"],["68124.60","0.129"]],"u":10184970,"seq":9374372777},"cts":1729581235157}'
2024-10-22 09:13:56,032 - DEBUG - ++Rcv decoded: fin=1 opcode=1 data=b'{"topic":"orderbook.50.BTCUSDT","type":"delta","ts":1729581235172,"data":{"s":"BTCUSDT","b":[],"a":[["67561.00","0"],["67561.10","0"],["67566.40","0.008"],["68117.50","0.024"],["68124.60","0.129"]],"u":10184970,"seq":9374372777},"cts":1729581235157}'
2024-10-22 09:13:56,033 - DEBUG - ++Rcv raw: b'\x81~\x00\xbe{"topic":"orderbook.50.BTCUSDT","type":"delta","ts":1729581235392,"data":{"s":"BTCUSDT","b":[["67461.40","0.002"],["66957.60","0"]],"a":[],"u":10184971,"seq":9374372778},"cts":1729581235373}'
2024-10-22 09:13:56,033 - DEBUG - ++Rcv decoded: fin=1 opcode=1 data=b'{"topic":"orderbook.50.BTCUSDT","type":"delta","ts":1729581235392,"data":{"s":"BTCUSDT","b":[["67461.40","0.002"],["66957.60","0"]],"a":[],"u":10184971,"seq":9374372778},"cts":1729581235373}'
2024-10-22 09:13:56,035 - DEBUG - ++Rcv raw: b'\x81~\x00\x8f{"success":true,"ret_msg":"","conn_id":"16b2ad43-542f-480c-8860-a44e4f544e1c","req_id":"2029c231-a7dc-4f5e-a151-9752de14a48e","op":"subscribe"}'
2024-10-22 09:13:56,035 - DEBUG - ++Rcv decoded: fin=1 opcode=1 data=b'{"success":true,"ret_msg":"","conn_id":"16b2ad43-542f-480c-8860-a44e4f544e1c","req_id":"2029c231-a7dc-4f5e-a151-9752de14a48e","op":"subscribe"}'
2024-10-22 09:13:56,102 - DEBUG - ++Rcv raw: b'\x81~\x00\xbe{"topic":"orderbook.50.BTCUSDT","type":"delta","ts":1729581235613,"data":{"s":"BTCUSDT","b":[["67461.50","0.002"],["67461.40","0"]],"a":[],"u":10184972,"seq":9374372779},"cts":1729581235597}'
2024-10-22 09:13:56,103 - DEBUG - ++Rcv decoded: fin=1 opcode=1 data=b'{"topic":"orderbook.50.BTCUSDT","type":"delta","ts":1729581235613,"data":{"s":"BTCUSDT","b":[["67461.50","0.002"],["67461.40","0"]],"a":[],"u":10184972,"seq":9374372779},"cts":1729581235597}'
2024-10-22 09:13:56,322 - DEBUG - ++Rcv raw: b'\x81~\x00\xbe{"topic":"orderbook.50.BTCUSDT","type":"delta","ts":1729581235833,"data":{"s":"BTCUSDT","b":[["67461.60","0.002"],["67461.50","0"]],"a":[],"u":10184973,"seq":9374372780},"cts":1729581235814}'
2024-10-22 09:13:56,323 - DEBUG - ++Rcv decoded: fin=1 opcode=1 data=b'{"topic":"orderbook.50.BTCUSDT","type":"delta","ts":1729581235833,"data":{"s":"BTCUSDT","b":[["67461.60","0.002"],["67461.50","0"]],"a":[],"u":10184973,"seq":9374372780},"cts":1729581235814}'
2024-10-22 09:13:56,539 - DEBUG - ++Rcv raw: b'\x81~\x00\xbe{"topic":"orderbook.50.BTCUSDT","type":"delta","ts":1729581236053,"data":{"s":"BTCUSDT","b":[["67461.70","0.002"],["67461.60","0"]],"a":[],"u":10184974,"seq":9374372783},"cts":1729581236034}'
2024-10-22 09:13:56,540 - DEBUG - ++Rcv decoded: fin=1 opcode=1 data=b'{"topic":"orderbook.50.BTCUSDT","type":"delta","ts":1729581236053,"data":{"s":"BTCUSDT","b":[["67461.70","0.002"],["67461.60","0"]],"a":[],"u":10184974,"seq":9374372783},"cts":1729581236034}'
2024-10-22 09:13:56,826 - DEBUG - ++Rcv raw: b'\x81~\x00\xbe{"topic":"orderbook.50.BTCUSDT","type":"delta","ts":1729581236333,"data":{"s":"BTCUSDT","b":[],"a":[["67561.10","0.001"],["68124.60","0"]],"u":10184975,"seq":9374372784},"cts":1729581236326}'
2024-10-22 09:13:56,827 - DEBUG - ++Rcv decoded: fin=1 opcode=1 data=b'{"topic":"orderbook.50.BTCUSDT","type":"delta","ts":1729581236333,"data":{"s":"BTCUSDT","b":[],"a":[["67561.10","0.001"],["68124.60","0"]],"u":10184975,"seq":9374372784},"cts":1729581236326}'
2024-10-22 09:13:58,003 - DEBUG - ++Rcv raw: b'\x81~\x00\xbe{"topic":"orderbook.50.BTCUSDT","type":"delta","ts":1729581237512,"data":{"s":"BTCUSDT","b":[["67461.80","0.002"],["67461.70","0"]],"a":[],"u":10184976,"seq":9374372785},"cts":1729581237498}'
2024-10-22 09:13:58,003 - DEBUG - ++Rcv decoded: fin=1 opcode=1 data=b'{"topic":"orderbook.50.BTCUSDT","type":"delta","ts":1729581237512,"data":{"s":"BTCUSDT","b":[["67461.80","0.002"],["67461.70","0"]],"a":[],"u":10184976,"seq":9374372785},"cts":1729581237498}'
2024-10-22 09:13:58,217 - DEBUG - ++Rcv raw: b'\x81~\x00\xbe{"topic":"orderbook.50.BTCUSDT","type":"delta","ts":1729581237732,"data":{"s":"BTCUSDT","b":[["67461.90","0.002"],["67461.80","0"]],"a":[],"u":10184977,"seq":9374372786},"cts":1729581237715}'
2024-10-22 09:13:58,219 - DEBUG - ++Rcv decoded: fin=1 opcode=1 data=b'{"topic":"orderbook.50.BTCUSDT","type":"delta","ts":1729581237732,"data":{"s":"BTCUSDT","b":[["67461.90","0.002"],["67461.80","0"]],"a":[],"u":10184977,"seq":9374372786},"cts":1729581237715}'
2024-10-22 09:13:59,053 - DEBUG - ++Rcv raw: b'\x81~\x00\xbe{"topic":"orderbook.50.BTCUSDT","type":"delta","ts":1729581238553,"data":{"s":"BTCUSDT","b":[["67462.00","0.002"],["67461.90","0"]],"a":[],"u":10184978,"seq":9374372787},"cts":1729581238532}'
2024-10-22 09:13:59,053 - DEBUG - ++Rcv decoded: fin=1 opcode=1 data=b'{"topic":"orderbook.50.BTCUSDT","type":"delta","ts":1729581238553,"data":{"s":"BTCUSDT","b":[["67462.00","0.002"],["67461.90","0"]],"a":[],"u":10184978,"seq":9374372787},"cts":1729581238532}'
2024-10-22 09:13:59,258 - DEBUG - ++Rcv raw: b'\x81~\x00\xbe{"topic":"orderbook.50.BTCUSDT","type":"delta","ts":1729581238772,"data":{"s":"BTCUSDT","b":[["67462.10","0.002"],["67462.00","0"]],"a":[],"u":10184979,"seq":9374372788},"cts":1729581238755}'
2024-10-22 09:13:59,259 - DEBUG - ++Rcv decoded: fin=1 opcode=1 data=b'{"topic":"orderbook.50.BTCUSDT","type":"delta","ts":1729581238772,"data":{"s":"BTCUSDT","b":[["67462.10","0.002"],["67462.00","0"]],"a":[],"u":10184979,"seq":9374372788},"cts":1729581238755}'
2024-10-22 09:13:59,482 - DEBUG - ++Rcv raw: b'\x81~\x00\xbe{"topic":"orderbook.50.BTCUSDT","type":"delta","ts":1729581238992,"data":{"s":"BTCUSDT","b":[["67462.20","0.002"],["67462.10","0"]],"a":[],"u":10184980,"seq":9374372791},"cts":1729581238974}'
2024-10-22 09:13:59,483 - DEBUG - ++Rcv decoded: fin=1 opcode=1 data=b'{"topic":"orderbook.50.BTCUSDT","type":"delta","ts":1729581238992,"data":{"s":"BTCUSDT","b":[["67462.20","0.002"],["67462.10","0"]],"a":[],"u":10184980,"seq":9374372791},"cts":1729581238974}'
2024-10-22 09:13:59,698 - DEBUG - ++Rcv raw: b'\x81~\x00\xbe{"topic":"orderbook.50.BTCUSDT","type":"delta","ts":1729581239213,"data":{"s":"BTCUSDT","b":[["67462.30","0.002"],["67462.20","0"]],"a":[],"u":10184981,"seq":9374372792},"cts":1729581239194}'
2024-10-22 09:13:59,699 - DEBUG - ++Rcv decoded: fin=1 opcode=1 data=b'{"topic":"orderbook.50.BTCUSDT","type":"delta","ts":1729581239213,"data":{"s":"BTCUSDT","b":[["67462.30","0.002"],["67462.20","0"]],"a":[],"u":10184981,"seq":9374372792},"cts":1729581239194}'
2024-10-22 09:14:00,997 - DEBUG - ++Rcv raw: b'\x81~\x00\xbe{"topic":"orderbook.50.BTCUSDT","type":"delta","ts":1729581240512,"data":{"s":"BTCUSDT","b":[["67462.40","0.002"],["67462.30","0"]],"a":[],"u":10184982,"seq":9374372793},"cts":1729581240494}'
2024-10-22 09:14:00,998 - DEBUG - ++Rcv decoded: fin=1 opcode=1 data=b'{"topic":"orderbook.50.BTCUSDT","type":"delta","ts":1729581240512,"data":{"s":"BTCUSDT","b":[["67462.40","0.002"],["67462.30","0"]],"a":[],"u":10184982,"seq":9374372793},"cts":1729581240494}'
2024-10-22 09:14:01,098 - DEBUG - ++Rcv raw: b'\x81~\x00\xbe{"topic":"orderbook.50.BTCUSDT","type":"delta","ts":1729581240612,"data":{"s":"BTCUSDT","b":[],"a":[["67648.80","0.001"],["68117.50","0"]],"u":10184983,"seq":9374372796},"cts":1729581240607}'
2024-10-22 09:14:01,098 - DEBUG - ++Rcv decoded: fin=1 opcode=1 data=b'{"topic":"orderbook.50.BTCUSDT","type":"delta","ts":1729581240612,"data":{"s":"BTCUSDT","b":[],"a":[["67648.80","0.001"],["68117.50","0"]],"u":10184983,"seq":9374372796},"cts":1729581240607}'
2024-10-22 09:14:01,220 - DEBUG - ++Rcv raw: b'\x81~\x00\xbe{"topic":"orderbook.50.BTCUSDT","type":"delta","ts":1729581240732,"data":{"s":"BTCUSDT","b":[["67462.50","0.002"],["67462.40","0"]],"a":[],"u":10184984,"seq":9374372797},"cts":1729581240714}'
2024-10-22 09:14:01,221 - DEBUG - ++Rcv decoded: fin=1 opcode=1 data=b'{"topic":"orderbook.50.BTCUSDT","type":"delta","ts":1729581240732,"data":{"s":"BTCUSDT","b":[["67462.50","0.002"],["67462.40","0"]],"a":[],"u":10184984,"seq":9374372797},"cts":1729581240714}'
2024-10-22 09:14:01,337 - DEBUG - ++Rcv raw: b'\x81~\x00\xbe{"topic":"orderbook.50.BTCUSDT","type":"delta","ts":1729581240853,"data":{"s":"BTCUSDT","b":[["67471.30","0.001"],["66957.70","0"]],"a":[],"u":10184985,"seq":9374372798},"cts":1729581240843}'
2024-10-22 09:14:01,337 - DEBUG - ++Rcv decoded: fin=1 opcode=1 data=b'{"topic":"orderbook.50.BTCUSDT","type":"delta","ts":1729581240853,"data":{"s":"BTCUSDT","b":[["67471.30","0.001"],["66957.70","0"]],"a":[],"u":10184985,"seq":9374372798},"cts":1729581240843}'
2024-10-22 09:14:01,443 - DEBUG - ++Rcv raw: b'\x81~\x00\xbe{"topic":"orderbook.50.BTCUSDT","type":"delta","ts":1729581240953,"data":{"s":"BTCUSDT","b":[["67462.60","0.002"],["67462.50","0"]],"a":[],"u":10184986,"seq":9374372799},"cts":1729581240934}'
2024-10-22 09:14:01,443 - DEBUG - ++Rcv decoded: fin=1 opcode=1 data=b'{"topic":"orderbook.50.BTCUSDT","type":"delta","ts":1729581240953,"data":{"s":"BTCUSDT","b":[["67462.60","0.002"],["67462.50","0"]],"a":[],"u":10184986,"seq":9374372799},"cts":1729581240934}'
2024-10-22 09:14:02,037 - DEBUG - ++Rcv raw: b'\x81~\x00\xbe{"topic":"orderbook.50.BTCUSDT","type":"delta","ts":1729581241552,"data":{"s":"BTCUSDT","b":[["67471.40","0.002"],["67462.60","0"]],"a":[],"u":10184987,"seq":9374372800},"cts":1729581241535}'
2024-10-22 09:14:02,037 - DEBUG - ++Rcv decoded: fin=1 opcode=1 data=b'{"topic":"orderbook.50.BTCUSDT","type":"delta","ts":1729581241552,"data":{"s":"BTCUSDT","b":[["67471.40","0.002"],["67462.60","0"]],"a":[],"u":10184987,"seq":9374372800},"cts":1729581241535}'
2024-10-22 09:14:02,256 - DEBUG - ++Rcv raw: b'\x81~\x01\x90{"topic":"orderbook.50.BTCUSDT","type":"delta","ts":1729581241773,"data":{"s":"BTCUSDT","b":[["67471.50","0.002"],["67471.40","0"]],"a":[["67561.10","0"],["67566.40","0"],["67574.70","0"],["67648.80","0"],["67656.90","0"],["67658.80","0.671"],["68117.50","0.024"],["68124.60","0.129"],["68131.30","0.296"],["68140.80","0.443"],["68142.80","0.020"]],"u":10184988,"seq":9374372802},"cts":1729581241767}'
2024-10-22 09:14:02,257 - DEBUG - ++Rcv decoded: fin=1 opcode=1 data=b'{"topic":"orderbook.50.BTCUSDT","type":"delta","ts":1729581241773,"data":{"s":"BTCUSDT","b":[["67471.50","0.002"],["67471.40","0"]],"a":[["67561.10","0"],["67566.40","0"],["67574.70","0"],["67648.80","0"],["67656.90","0"],["67658.80","0.671"],["68117.50","0.024"],["68124.60","0.129"],["68131.30","0.296"],["68140.80","0.443"],["68142.80","0.020"]],"u":10184988,"seq":9374372802},"cts":1729581241767}'
2024-10-22 09:14:02,276 - DEBUG - ++Rcv raw: b'\x81~\x00\xbe{"topic":"orderbook.50.BTCUSDT","type":"delta","ts":1729581241792,"data":{"s":"BTCUSDT","b":[["67494.30","0.004"],["66960.00","0"]],"a":[],"u":10184989,"seq":9374372804},"cts":1729581241780}'
2024-10-22 09:14:02,276 - DEBUG - ++Rcv decoded: fin=1 opcode=1 data=b'{"topic":"orderbook.50.BTCUSDT","type":"delta","ts":1729581241792,"data":{"s":"BTCUSDT","b":[["67494.30","0.004"],["66960.00","0"]],"a":[],"u":10184989,"seq":9374372804},"cts":1729581241780}'
2024-10-22 09:14:02,481 - DEBUG - ++Rcv raw: b'\x81~\x00\xbe{"topic":"orderbook.50.BTCUSDT","type":"delta","ts":1729581241992,"data":{"s":"BTCUSDT","b":[["67471.60","0.002"],["67471.50","0"]],"a":[],"u":10184990,"seq":9374372806},"cts":1729581241975}'
2024-10-22 09:14:02,482 - DEBUG - ++Rcv decoded: fin=1 opcode=1 data=b'{"topic":"orderbook.50.BTCUSDT","type":"delta","ts":1729581241992,"data":{"s":"BTCUSDT","b":[["67471.60","0.002"],["67471.50","0"]],"a":[],"u":10184990,"seq":9374372806},"cts":1729581241975}'
2024-10-22 09:14:03,818 - DEBUG - ++Rcv raw: b'\x81~\x00\xe4{"topic":"orderbook.50.BTCUSDT","type":"delta","ts":1729581243332,"data":{"s":"BTCUSDT","b":[],"a":[["67549.30","0.001"],["67562.90","0.001"],["68140.80","0"],["68142.80","0"]],"u":10184991,"seq":9374372810},"cts":1729581243329}'
2024-10-22 09:14:03,819 - DEBUG - ++Rcv decoded: fin=1 opcode=1 data=b'{"topic":"orderbook.50.BTCUSDT","type":"delta","ts":1729581243332,"data":{"s":"BTCUSDT","b":[],"a":[["67549.30","0.001"],["67562.90","0.001"],["68140.80","0"],["68142.80","0"]],"u":10184991,"seq":9374372810},"cts":1729581243329}'
2024-10-22 09:14:03,843 - DEBUG - ++Rcv raw: b'\x81~\x00\xbe{"topic":"orderbook.50.BTCUSDT","type":"delta","ts":1729581243352,"data":{"s":"BTCUSDT","b":[],"a":[["67576.50","0.001"],["68131.30","0"]],"u":10184992,"seq":9374372811},"cts":1729581243329}'
2024-10-22 09:14:03,844 - DEBUG - ++Rcv decoded: fin=1 opcode=1 data=b'{"topic":"orderbook.50.BTCUSDT","type":"delta","ts":1729581243352,"data":{"s":"BTCUSDT","b":[],"a":[["67576.50","0.001"],["68131.30","0"]],"u":10184992,"seq":9374372811},"cts":1729581243329}'
2024-10-22 09:14:03,879 - DEBUG - ++Rcv raw: b'\x81~\x00\xbe{"topic":"orderbook.50.BTCUSDT","type":"delta","ts":1729581243393,"data":{"s":"BTCUSDT","b":[["67494.40","0.002"],["67471.60","0"]],"a":[],"u":10184993,"seq":9374372812},"cts":1729581243386}'
2024-10-22 09:14:03,879 - DEBUG - ++Rcv decoded: fin=1 opcode=1 data=b'{"topic":"orderbook.50.BTCUSDT","type":"delta","ts":1729581243393,"data":{"s":"BTCUSDT","b":[["67494.40","0.002"],["67471.60","0"]],"a":[],"u":10184993,"seq":9374372812},"cts":1729581243386}'
2024-10-22 09:14:04,099 - DEBUG - ++Rcv raw: b'\x81~\x00\xbe{"topic":"orderbook.50.BTCUSDT","type":"delta","ts":1729581243612,"data":{"s":"BTCUSDT","b":[["67494.50","0.002"],["67494.40","0"]],"a":[],"u":10184994,"seq":9374372815},"cts":1729581243604}'
2024-10-22 09:14:04,100 - DEBUG - ++Rcv decoded: fin=1 opcode=1 data=b'{"topic":"orderbook.50.BTCUSDT","type":"delta","ts":1729581243612,"data":{"s":"BTCUSDT","b":[["67494.50","0.002"],["67494.40","0"]],"a":[],"u":10184994,"seq":9374372815},"cts":1729581243604}'
2024-10-22 09:14:04,320 - DEBUG - ++Rcv raw: b'\x81~\x00\xbe{"topic":"orderbook.50.BTCUSDT","type":"delta","ts":1729581243832,"data":{"s":"BTCUSDT","b":[["67494.60","0.002"],["67494.50","0"]],"a":[],"u":10184995,"seq":9374372816},"cts":1729581243824}'
2024-10-22 09:14:04,323 - DEBUG - ++Rcv decoded: fin=1 opcode=1 data=b'{"topic":"orderbook.50.BTCUSDT","type":"delta","ts":1729581243832,"data":{"s":"BTCUSDT","b":[["67494.60","0.002"],["67494.50","0"]],"a":[],"u":10184995,"seq":9374372816},"cts":1729581243824}'
2024-10-22 09:14:04,549 - DEBUG - ++Rcv raw: b'\x81~\x00\xbe{"topic":"orderbook.50.BTCUSDT","type":"delta","ts":1729581244053,"data":{"s":"BTCUSDT","b":[["67494.70","0.002"],["67494.60","0"]],"a":[],"u":10184996,"seq":9374372819},"cts":1729581244043}'
2024-10-22 09:14:04,549 - DEBUG - ++Rcv decoded: fin=1 opcode=1 data=b'{"topic":"orderbook.50.BTCUSDT","type":"delta","ts":1729581244053,"data":{"s":"BTCUSDT","b":[["67494.70","0.002"],["67494.60","0"]],"a":[],"u":10184996,"seq":9374372819},"cts":1729581244043}'
2024-10-22 09:14:04,761 - DEBUG - ++Rcv raw: b'\x81~\x00\xbe{"topic":"orderbook.50.BTCUSDT","type":"delta","ts":1729581244272,"data":{"s":"BTCUSDT","b":[["67494.80","0.002"],["67494.70","0"]],"a":[],"u":10184997,"seq":9374372820},"cts":1729581244264}'
2024-10-22 09:14:04,762 - DEBUG - ++Rcv decoded: fin=1 opcode=1 data=b'{"topic":"orderbook.50.BTCUSDT","type":"delta","ts":1729581244272,"data":{"s":"BTCUSDT","b":[["67494.80","0.002"],["67494.70","0"]],"a":[],"u":10184997,"seq":9374372820},"cts":1729581244264}'
2024-10-22 09:14:04,822 - DEBUG - ++Rcv raw: b'\x81~\x00\xbe{"topic":"orderbook.50.BTCUSDT","type":"delta","ts":1729581244332,"data":{"s":"BTCUSDT","b":[],"a":[["67566.40","0.592"],["68124.60","0"]],"u":10184998,"seq":9374372821},"cts":1729581244326}'
2024-10-22 09:14:04,823 - DEBUG - ++Rcv decoded: fin=1 opcode=1 data=b'{"topic":"orderbook.50.BTCUSDT","type":"delta","ts":1729581244332,"data":{"s":"BTCUSDT","b":[],"a":[["67566.40","0.592"],["68124.60","0"]],"u":10184998,"seq":9374372821},"cts":1729581244326}'
2024-10-22 09:14:04,843 - DEBUG - ++Rcv raw: b'\x81~\x00\xbe{"topic":"orderbook.50.BTCUSDT","type":"delta","ts":1729581244353,"data":{"s":"BTCUSDT","b":[],"a":[["67549.30","0"],["68124.60","0.129"]],"u":10184999,"seq":9374372823},"cts":1729581244331}'
2024-10-22 09:14:04,843 - DEBUG - ++Rcv decoded: fin=1 opcode=1 data=b'{"topic":"orderbook.50.BTCUSDT","type":"delta","ts":1729581244353,"data":{"s":"BTCUSDT","b":[],"a":[["67549.30","0"],["68124.60","0.129"]],"u":10184999,"seq":9374372823},"cts":1729581244331}'
2024-10-22 09:14:04,979 - DEBUG - ++Rcv raw: b'\x81~\x00\xbe{"topic":"orderbook.50.BTCUSDT","type":"delta","ts":1729581244492,"data":{"s":"BTCUSDT","b":[["67494.90","0.002"],["67494.80","0"]],"a":[],"u":10185000,"seq":9374372826},"cts":1729581244483}'
2024-10-22 09:14:04,979 - DEBUG - ++Rcv decoded: fin=1 opcode=1 data=b'{"topic":"orderbook.50.BTCUSDT","type":"delta","ts":1729581244492,"data":{"s":"BTCUSDT","b":[["67494.90","0.002"],["67494.80","0"]],"a":[],"u":10185000,"seq":9374372826},"cts":1729581244483}'
2024-10-22 09:14:05,843 - DEBUG - ++Rcv raw: b'\x81~\x00\xd3{"topic":"orderbook.50.BTCUSDT","type":"delta","ts":1729581245353,"data":{"s":"BTCUSDT","b":[],"a":[["67562.90","0"],["67566.40","0.147"],["68131.30","0.296"]],"u":10185001,"seq":9374372850},"cts":1729581245340}'
2024-10-22 09:14:05,844 - DEBUG - ++Rcv decoded: fin=1 opcode=1 data=b'{"topic":"orderbook.50.BTCUSDT","type":"delta","ts":1729581245353,"data":{"s":"BTCUSDT","b":[],"a":[["67562.90","0"],["67566.40","0.147"],["68131.30","0.296"]],"u":10185001,"seq":9374372850},"cts":1729581245340}'
2024-10-22 09:14:06,062 - DEBUG - ++Rcv raw: b'\x81~\x00\xbe{"topic":"orderbook.50.BTCUSDT","type":"delta","ts":1729581245572,"data":{"s":"BTCUSDT","b":[["67495.00","0.002"],["67494.90","0"]],"a":[],"u":10185002,"seq":9374372853},"cts":1729581245555}'
2024-10-22 09:14:06,063 - DEBUG - ++Rcv decoded: fin=1 opcode=1 data=b'{"topic":"orderbook.50.BTCUSDT","type":"delta","ts":1729581245572,"data":{"s":"BTCUSDT","b":[["67495.00","0.002"],["67494.90","0"]],"a":[],"u":10185002,"seq":9374372853},"cts":1729581245555}'
2024-10-22 09:14:06,279 - DEBUG - ++Rcv raw: b'\x81~\x00\xbe{"topic":"orderbook.50.BTCUSDT","type":"delta","ts":1729581245792,"data":{"s":"BTCUSDT","b":[["67495.10","0.002"],["67495.00","0"]],"a":[],"u":10185003,"seq":9374372854},"cts":1729581245773}'
2024-10-22 09:14:06,279 - DEBUG - ++Rcv decoded: fin=1 opcode=1 data=b'{"topic":"orderbook.50.BTCUSDT","type":"delta","ts":1729581245792,"data":{"s":"BTCUSDT","b":[["67495.10","0.002"],["67495.00","0"]],"a":[],"u":10185003,"seq":9374372854},"cts":1729581245773}'
2024-10-22 09:14:06,503 - DEBUG - ++Rcv raw: b'\x81~\x00\xbe{"topic":"orderbook.50.BTCUSDT","type":"delta","ts":1729581246013,"data":{"s":"BTCUSDT","b":[["67495.20","0.002"],["67495.10","0"]],"a":[],"u":10185004,"seq":9374372857},"cts":1729581246003}'
2024-10-22 09:14:06,504 - DEBUG - ++Rcv decoded: fin=1 opcode=1 data=b'{"topic":"orderbook.50.BTCUSDT","type":"delta","ts":1729581246013,"data":{"s":"BTCUSDT","b":[["67495.20","0.002"],["67495.10","0"]],"a":[],"u":10185004,"seq":9374372857},"cts":1729581246003}'
2024-10-22 09:14:06,785 - DEBUG - ++Rcv raw: b'\x81~\x00\xbe{"topic":"orderbook.50.BTCUSDT","type":"delta","ts":1729581246293,"data":{"s":"BTCUSDT","b":[["67471.30","0"],["66960.00","0.013"]],"a":[],"u":10185005,"seq":9374372858},"cts":1729581246274}'
2024-10-22 09:14:06,786 - DEBUG - ++Rcv decoded: fin=1 opcode=1 data=b'{"topic":"orderbook.50.BTCUSDT","type":"delta","ts":1729581246293,"data":{"s":"BTCUSDT","b":[["67471.30","0"],["66960.00","0.013"]],"a":[],"u":10185005,"seq":9374372858},"cts":1729581246274}'
2024-10-22 09:14:07,321 - DEBUG - ++Rcv raw: b'\x81~\x00\xbe{"topic":"orderbook.50.BTCUSDT","type":"delta","ts":1729581246832,"data":{"s":"BTCUSDT","b":[["67505.20","0.001"],["66960.00","0"]],"a":[],"u":10185006,"seq":9374372859},"cts":1729581246826}'
2024-10-22 09:14:07,321 - DEBUG - ++Rcv decoded: fin=1 opcode=1 data=b'{"topic":"orderbook.50.BTCUSDT","type":"delta","ts":1729581246832,"data":{"s":"BTCUSDT","b":[["67505.20","0.001"],["66960.00","0"]],"a":[],"u":10185006,"seq":9374372859},"cts":1729581246826}'
2024-10-22 09:14:08,840 - DEBUG - ++Rcv raw: b'\x81~\x00\xbe{"topic":"orderbook.50.BTCUSDT","type":"delta","ts":1729581248353,"data":{"s":"BTCUSDT","b":[],"a":[["67562.90","0.001"],["68131.30","0"]],"u":10185007,"seq":9374372861},"cts":1729581248333}'
2024-10-22 09:14:08,840 - DEBUG - ++Rcv decoded: fin=1 opcode=1 data=b'{"topic":"orderbook.50.BTCUSDT","type":"delta","ts":1729581248353,"data":{"s":"BTCUSDT","b":[],"a":[["67562.90","0.001"],["68131.30","0"]],"u":10185007,"seq":9374372861},"cts":1729581248333}'
2024-10-22 09:14:09,840 - DEBUG - ++Rcv raw: b'\x81~\x00\xbe{"topic":"orderbook.50.BTCUSDT","type":"delta","ts":1729581249352,"data":{"s":"BTCUSDT","b":[],"a":[["67590.10","0.001"],["68124.60","0"]],"u":10185008,"seq":9374372864},"cts":1729581249334}'
2024-10-22 09:14:09,840 - DEBUG - ++Rcv decoded: fin=1 opcode=1 data=b'{"topic":"orderbook.50.BTCUSDT","type":"delta","ts":1729581249352,"data":{"s":"BTCUSDT","b":[],"a":[["67590.10","0.001"],["68124.60","0"]],"u":10185008,"seq":9374372864},"cts":1729581249334}'
2024-10-22 09:14:10,562 - DEBUG - ++Rcv raw: b'\x81~\x00\xbe{"topic":"orderbook.50.BTCUSDT","type":"delta","ts":1729581250073,"data":{"s":"BTCUSDT","b":[["67505.30","0.002"],["67495.20","0"]],"a":[],"u":10185009,"seq":9374372867},"cts":1729581250051}'
2024-10-22 09:14:10,562 - DEBUG - ++Rcv decoded: fin=1 opcode=1 data=b'{"topic":"orderbook.50.BTCUSDT","type":"delta","ts":1729581250073,"data":{"s":"BTCUSDT","b":[["67505.30","0.002"],["67495.20","0"]],"a":[],"u":10185009,"seq":9374372867},"cts":1729581250051}'
2024-10-22 09:14:10,776 - DEBUG - ++Rcv raw: b'\x81~\x00\xbe{"topic":"orderbook.50.BTCUSDT","type":"delta","ts":1729581250293,"data":{"s":"BTCUSDT","b":[["67505.40","0.002"],["67505.30","0"]],"a":[],"u":10185010,"seq":9374372870},"cts":1729581250274}'
2024-10-22 09:14:10,777 - DEBUG - ++Rcv decoded: fin=1 opcode=1 data=b'{"topic":"orderbook.50.BTCUSDT","type":"delta","ts":1729581250293,"data":{"s":"BTCUSDT","b":[["67505.40","0.002"],["67505.30","0"]],"a":[],"u":10185010,"seq":9374372870},"cts":1729581250274}'
2024-10-22 09:14:10,838 - DEBUG - ++Rcv raw: b'\x81~\x00\xbe{"topic":"orderbook.50.BTCUSDT","type":"delta","ts":1729581250352,"data":{"s":"BTCUSDT","b":[],"a":[["67562.90","0"],["68124.60","0.129"]],"u":10185011,"seq":9374372871},"cts":1729581250334}'
2024-10-22 09:14:10,840 - DEBUG - ++Rcv decoded: fin=1 opcode=1 data=b'{"topic":"orderbook.50.BTCUSDT","type":"delta","ts":1729581250352,"data":{"s":"BTCUSDT","b":[],"a":[["67562.90","0"],["68124.60","0.129"]],"u":10185011,"seq":9374372871},"cts":1729581250334}'
2024-10-22 09:14:10,998 - DEBUG - ++Rcv raw: b'\x81~\x00\xbe{"topic":"orderbook.50.BTCUSDT","type":"delta","ts":1729581250513,"data":{"s":"BTCUSDT","b":[["67505.50","0.002"],["67505.40","0"]],"a":[],"u":10185012,"seq":9374372872},"cts":1729581250493}'
2024-10-22 09:14:10,999 - DEBUG - ++Rcv decoded: fin=1 opcode=1 data=b'{"topic":"orderbook.50.BTCUSDT","type":"delta","ts":1729581250513,"data":{"s":"BTCUSDT","b":[["67505.50","0.002"],["67505.40","0"]],"a":[],"u":10185012,"seq":9374372872},"cts":1729581250493}'
2024-10-22 09:14:11,216 - DEBUG - ++Rcv raw: b'\x81~\x00\xbe{"topic":"orderbook.50.BTCUSDT","type":"delta","ts":1729581250732,"data":{"s":"BTCUSDT","b":[["67505.60","0.002"],["67505.50","0"]],"a":[],"u":10185013,"seq":9374372873},"cts":1729581250714}'
2024-10-22 09:14:11,216 - DEBUG - ++Rcv decoded: fin=1 opcode=1 data=b'{"topic":"orderbook.50.BTCUSDT","type":"delta","ts":1729581250732,"data":{"s":"BTCUSDT","b":[["67505.60","0.002"],["67505.50","0"]],"a":[],"u":10185013,"seq":9374372873},"cts":1729581250714}'
2024-10-22 09:14:11,442 - DEBUG - ++Rcv raw: b'\x81~\x00\xbe{"topic":"orderbook.50.BTCUSDT","type":"delta","ts":1729581250952,"data":{"s":"BTCUSDT","b":[["67505.70","0.002"],["67505.60","0"]],"a":[],"u":10185014,"seq":9374372874},"cts":1729581250933}'
2024-10-22 09:14:11,443 - DEBUG - ++Rcv decoded: fin=1 opcode=1 data=b'{"topic":"orderbook.50.BTCUSDT","type":"delta","ts":1729581250952,"data":{"s":"BTCUSDT","b":[["67505.70","0.002"],["67505.60","0"]],"a":[],"u":10185014,"seq":9374372874},"cts":1729581250933}'
2024-10-22 09:14:11,661 - DEBUG - ++Rcv raw: b'\x81~\x00\xbe{"topic":"orderbook.50.BTCUSDT","type":"delta","ts":1729581251172,"data":{"s":"BTCUSDT","b":[["67505.80","0.002"],["67505.70","0"]],"a":[],"u":10185015,"seq":9374372877},"cts":1729581251154}'
2024-10-22 09:14:11,661 - DEBUG - ++Rcv decoded: fin=1 opcode=1 data=b'{"topic":"orderbook.50.BTCUSDT","type":"delta","ts":1729581251172,"data":{"s":"BTCUSDT","b":[["67505.80","0.002"],["67505.70","0"]],"a":[],"u":10185015,"seq":9374372877},"cts":1729581251154}'
2024-10-22 09:14:11,876 - DEBUG - ++Rcv raw: b'\x81~\x00\xbe{"topic":"orderbook.50.BTCUSDT","type":"delta","ts":1729581251392,"data":{"s":"BTCUSDT","b":[["67505.90","0.002"],["67505.80","0"]],"a":[],"u":10185016,"seq":9374372880},"cts":1729581251374}'
2024-10-22 09:14:11,876 - DEBUG - ++Rcv decoded: fin=1 opcode=1 data=b'{"topic":"orderbook.50.BTCUSDT","type":"delta","ts":1729581251392,"data":{"s":"BTCUSDT","b":[["67505.90","0.002"],["67505.80","0"]],"a":[],"u":10185016,"seq":9374372880},"cts":1729581251374}'
2024-10-22 09:14:12,101 - DEBUG - ++Rcv raw: b'\x81~\x00\xbe{"topic":"orderbook.50.BTCUSDT","type":"delta","ts":1729581251612,"data":{"s":"BTCUSDT","b":[["67506.00","0.002"],["67505.90","0"]],"a":[],"u":10185017,"seq":9374372881},"cts":1729581251595}'
2024-10-22 09:14:12,102 - DEBUG - ++Rcv decoded: fin=1 opcode=1 data=b'{"topic":"orderbook.50.BTCUSDT","type":"delta","ts":1729581251612,"data":{"s":"BTCUSDT","b":[["67506.00","0.002"],["67505.90","0"]],"a":[],"u":10185017,"seq":9374372881},"cts":1729581251595}'
2024-10-22 09:14:12,200 - DEBUG - ++Rcv raw: b'\x81~\x00\xbe{"topic":"orderbook.50.BTCUSDT","type":"delta","ts":1729581251712,"data":{"s":"BTCUSDT","b":[],"a":[["67833.40","0"],["68131.30","0.296"]],"u":10185018,"seq":9374372882},"cts":1729581251696}'
2024-10-22 09:14:12,200 - DEBUG - ++Rcv decoded: fin=1 opcode=1 data=b'{"topic":"orderbook.50.BTCUSDT","type":"delta","ts":1729581251712,"data":{"s":"BTCUSDT","b":[],"a":[["67833.40","0"],["68131.30","0.296"]],"u":10185018,"seq":9374372882},"cts":1729581251696}'
2024-10-22 09:14:12,322 - DEBUG - ++Rcv raw: b'\x81~\x00\xbe{"topic":"orderbook.50.BTCUSDT","type":"delta","ts":1729581251832,"data":{"s":"BTCUSDT","b":[["67506.10","0.002"],["67506.00","0"]],"a":[],"u":10185019,"seq":9374372883},"cts":1729581251813}'
2024-10-22 09:14:12,323 - DEBUG - ++Rcv decoded: fin=1 opcode=1 data=b'{"topic":"orderbook.50.BTCUSDT","type":"delta","ts":1729581251832,"data":{"s":"BTCUSDT","b":[["67506.10","0.002"],["67506.00","0"]],"a":[],"u":10185019,"seq":9374372883},"cts":1729581251813}'
2024-10-22 09:14:12,416 - DEBUG - ++Rcv raw: b'\x81~\x00\xbe{"topic":"orderbook.50.BTCUSDT","type":"delta","ts":1729581251933,"data":{"s":"BTCUSDT","b":[],"a":[["67840.20","0.001"],["68131.30","0"]],"u":10185020,"seq":9374372884},"cts":1729581251917}'
2024-10-22 09:14:12,416 - DEBUG - ++Rcv decoded: fin=1 opcode=1 data=b'{"topic":"orderbook.50.BTCUSDT","type":"delta","ts":1729581251933,"data":{"s":"BTCUSDT","b":[],"a":[["67840.20","0.001"],["68131.30","0"]],"u":10185020,"seq":9374372884},"cts":1729581251917}'
2024-10-22 09:14:12,538 - DEBUG - ++Rcv raw: b'\x81~\x00\xbe{"topic":"orderbook.50.BTCUSDT","type":"delta","ts":1729581252052,"data":{"s":"BTCUSDT","b":[["67506.20","0.002"],["67506.10","0"]],"a":[],"u":10185021,"seq":9374372885},"cts":1729581252034}'
2024-10-22 09:14:12,539 - DEBUG - ++Rcv decoded: fin=1 opcode=1 data=b'{"topic":"orderbook.50.BTCUSDT","type":"delta","ts":1729581252052,"data":{"s":"BTCUSDT","b":[["67506.20","0.002"],["67506.10","0"]],"a":[],"u":10185021,"seq":9374372885},"cts":1729581252034}'
2024-10-22 09:14:12,658 - DEBUG - ++Rcv raw: b'\x81~\x00\xbe{"topic":"orderbook.50.BTCUSDT","type":"delta","ts":1729581252172,"data":{"s":"BTCUSDT","b":[["67505.20","0"],["66960.00","0.013"]],"a":[],"u":10185022,"seq":9374372886},"cts":1729581252163}'
2024-10-22 09:14:12,658 - DEBUG - ++Rcv decoded: fin=1 opcode=1 data=b'{"topic":"orderbook.50.BTCUSDT","type":"delta","ts":1729581252172,"data":{"s":"BTCUSDT","b":[["67505.20","0"],["66960.00","0.013"]],"a":[],"u":10185022,"seq":9374372886},"cts":1729581252163}'
2024-10-22 09:14:12,763 - DEBUG - ++Rcv raw: b'\x81~\x00\xbe{"topic":"orderbook.50.BTCUSDT","type":"delta","ts":1729581252272,"data":{"s":"BTCUSDT","b":[["67506.30","0.002"],["67506.20","0"]],"a":[],"u":10185023,"seq":9374372887},"cts":1729581252254}'
2024-10-22 09:14:12,763 - DEBUG - ++Rcv decoded: fin=1 opcode=1 data=b'{"topic":"orderbook.50.BTCUSDT","type":"delta","ts":1729581252272,"data":{"s":"BTCUSDT","b":[["67506.30","0.002"],["67506.20","0"]],"a":[],"u":10185023,"seq":9374372887},"cts":1729581252254}'
2024-10-22 09:14:12,980 - DEBUG - ++Rcv raw: b'\x81~\x00\xbe{"topic":"orderbook.50.BTCUSDT","type":"delta","ts":1729581252492,"data":{"s":"BTCUSDT","b":[["67506.40","0.002"],["67506.30","0"]],"a":[],"u":10185024,"seq":9374372889},"cts":1729581252473}'
2024-10-22 09:14:12,981 - DEBUG - ++Rcv decoded: fin=1 opcode=1 data=b'{"topic":"orderbook.50.BTCUSDT","type":"delta","ts":1729581252492,"data":{"s":"BTCUSDT","b":[["67506.40","0.002"],["67506.30","0"]],"a":[],"u":10185024,"seq":9374372889},"cts":1729581252473}'
2024-10-22 09:14:13,204 - DEBUG - ++Rcv raw: b'\x81~\x00\xbe{"topic":"orderbook.50.BTCUSDT","type":"delta","ts":1729581252713,"data":{"s":"BTCUSDT","b":[["67516.40","0.001"],["66960.00","0"]],"a":[],"u":10185025,"seq":9374372890},"cts":1729581252702}'
2024-10-22 09:14:13,205 - DEBUG - ++Rcv decoded: fin=1 opcode=1 data=b'{"topic":"orderbook.50.BTCUSDT","type":"delta","ts":1729581252713,"data":{"s":"BTCUSDT","b":[["67516.40","0.001"],["66960.00","0"]],"a":[],"u":10185025,"seq":9374372890},"cts":1729581252702}'
2024-10-22 09:14:13,642 - DEBUG - ++Sent raw: b'\x81\x8e\x93H\xe4j\xe8j\x8b\x1a\xb1r\xc4H\xe3!\x8a\r\xb15'
2024-10-22 09:14:13,642 - DEBUG - ++Sent decoded: fin=1 opcode=1 data=b'{"op": "ping"}'
2024-10-22 09:14:14,022 - DEBUG - ++Rcv raw: b'\x81~\x00\xad{"topic":"orderbook.50.BTCUSDT","type":"delta","ts":1729581253532,"data":{"s":"BTCUSDT","b":[],"a":[["67566.40","0.044"]],"u":10185026,"seq":9374372894},"cts":1729581253520}'
2024-10-22 09:14:14,023 - DEBUG - ++Rcv decoded: fin=1 opcode=1 data=b'{"topic":"orderbook.50.BTCUSDT","type":"delta","ts":1729581253532,"data":{"s":"BTCUSDT","b":[],"a":[["67566.40","0.044"]],"u":10185026,"seq":9374372894},"cts":1729581253520}'
2024-10-22 09:14:14,054 - DEBUG - ++Rcv raw: b'\x81j{"success":true,"ret_msg":"pong","conn_id":"16b2ad43-542f-480c-8860-a44e4f544e1c","req_id":"","op":"ping"}'
2024-10-22 09:14:14,055 - DEBUG - ++Rcv decoded: fin=1 opcode=1 data=b'{"success":true,"ret_msg":"pong","conn_id":"16b2ad43-542f-480c-8860-a44e4f544e1c","req_id":"","op":"ping"}'
2024-10-22 09:14:14,379 - DEBUG - ++Rcv raw: b'\x81~\x01\x1f{"topic":"orderbook.50.BTCUSDT","type":"delta","ts":1729581253892,"data":{"s":"BTCUSDT","b":[],"a":[["67566.40","0"],["67576.50","0"],["67590.10","0"],["67658.80","0.223"],["68131.30","0.296"],["68140.80","0.443"],["68142.80","0.020"]],"u":10185027,"seq":9374372918},"cts":1729581253887}'
2024-10-22 09:14:14,379 - DEBUG - ++Rcv decoded: fin=1 opcode=1 data=b'{"topic":"orderbook.50.BTCUSDT","type":"delta","ts":1729581253892,"data":{"s":"BTCUSDT","b":[],"a":[["67566.40","0"],["67576.50","0"],["67590.10","0"],["67658.80","0.223"],["68131.30","0.296"],["68140.80","0.443"],["68142.80","0.020"]],"u":10185027,"seq":9374372918},"cts":1729581253887}'
2024-10-22 09:14:14,400 - DEBUG - ++Rcv raw: b'\x81~\x00\xbe{"topic":"orderbook.50.BTCUSDT","type":"delta","ts":1729581253913,"data":{"s":"BTCUSDT","b":[["67489.80","0.459"],["66965.70","0"]],"a":[],"u":10185028,"seq":9374372921},"cts":1729581253904}'
2024-10-22 09:14:14,400 - DEBUG - ++Rcv decoded: fin=1 opcode=1 data=b'{"topic":"orderbook.50.BTCUSDT","type":"delta","ts":1729581253913,"data":{"s":"BTCUSDT","b":[["67489.80","0.459"],["66965.70","0"]],"a":[],"u":10185028,"seq":9374372921},"cts":1729581253904}'
2024-10-22 09:14:14,850 - DEBUG - ++Rcv raw: b'\x81~\x00\xbe{"topic":"orderbook.50.BTCUSDT","type":"delta","ts":1729581254353,"data":{"s":"BTCUSDT","b":[],"a":[["67603.70","0.001"],["68142.80","0"]],"u":10185029,"seq":9374372923},"cts":1729581254336}'
2024-10-22 09:14:14,850 - DEBUG - ++Rcv decoded: fin=1 opcode=1 data=b'{"topic":"orderbook.50.BTCUSDT","type":"delta","ts":1729581254353,"data":{"s":"BTCUSDT","b":[],"a":[["67603.70","0.001"],["68142.80","0"]],"u":10185029,"seq":9374372923},"cts":1729581254336}'
2024-10-22 09:14:15,576 - DEBUG - ++Sent raw: b'\x81\x8e\xdf\r\xea\x7f\xa4/\x85\x0f\xfd7\xca]\xafd\x84\x18\xfdp'
2024-10-22 09:14:15,576 - DEBUG - ++Sent decoded: fin=1 opcode=1 data=b'{"op": "ping"}'
2024-10-22 09:14:15,746 - DEBUG - ++Sent raw: b'\x88\x82\x97@7\x7f\x94\xa8'
2024-10-22 09:14:15,746 - DEBUG - ++Sent decoded: fin=1 opcode=8 data=b'\x03\xe8'
2024-10-22 09:14:15,987 - DEBUG - ++Rcv raw: b'\x81M{"op":"pong","args":["1729581255503"],"conn_id":"crjtta1qo29j6gv0ald0-3okp4"}'
2024-10-22 09:14:15,987 - DEBUG - ++Rcv decoded: fin=1 opcode=1 data=b'{"op":"pong","args":["1729581255503"],"conn_id":"crjtta1qo29j6gv0ald0-3okp4"}'
2024-10-22 09:14:30,461 - INFO - WebSocket Unified V5 (Auth) attempting connection...
2024-10-22 09:14:31,373 - DEBUG - --- request header ---
2024-10-22 09:14:31,404 - DEBUG - GET /v5/public/linear HTTP/1.1
Upgrade: websocket
Host: stream-testnet.bybit.com
Origin: https://stream-testnet.bybit.com
Sec-WebSocket-Key: yDMe/Y9FHkVUfH47X7KD/Q==
Sec-WebSocket-Version: 13
Connection: Upgrade


2024-10-22 09:14:31,481 - DEBUG - -----------------------
2024-10-22 09:14:31,512 - DEBUG - --- response header ---
2024-10-22 09:14:32,356 - DEBUG - HTTP/1.1 101 Switching Protocols
2024-10-22 09:14:32,385 - DEBUG - Connection: upgrade
2024-10-22 09:14:32,539 - DEBUG - Date: Tue, 22 Oct 2024 07:14:31 GMT
2024-10-22 09:14:32,601 - DEBUG - Upgrade: websocket
2024-10-22 09:14:32,632 - DEBUG - Sec-WebSocket-Accept: 2jEU9RDJzaB+BAYI2awZHyxhxhQ=
2024-10-22 09:14:32,661 - DEBUG - X-Cache: Miss from cloudfront
2024-10-22 09:14:32,738 - DEBUG - Via: 1.1 7662c8abc46b26b811683f946db8d376.cloudfront.net (CloudFront)
2024-10-22 09:14:32,769 - DEBUG - X-Amz-Cf-Pop: VIE50-P3
2024-10-22 09:14:32,800 - DEBUG - X-Amz-Cf-Id: znrNLcR5dLYyTrUviZrpS6HvBS-W6VgHvMJXKDSRZaNBrSG3s44Ntw==
2024-10-22 09:14:32,830 - DEBUG - -----------------------
2024-10-22 09:14:32,846 - INFO - WebSocket Unified V5 (Auth) connected
2024-10-22 09:14:32,846 - INFO - Websocket connected
2024-10-22 09:14:32,848 - INFO - WebSocket Unified V5 (Auth) attempting connection...
2024-10-22 09:14:33,539 - DEBUG - --- request header ---
2024-10-22 09:14:33,555 - DEBUG - GET /v5/private HTTP/1.1
Upgrade: websocket
Host: stream-testnet.bybit.com
Origin: https://stream-testnet.bybit.com
Sec-WebSocket-Key: qol3f+GZ11IEwoii7Zoeog==
Sec-WebSocket-Version: 13
Connection: Upgrade


2024-10-22 09:14:33,585 - DEBUG - -----------------------
2024-10-22 09:14:33,615 - DEBUG - --- response header ---
2024-10-22 09:14:34,417 - DEBUG - HTTP/1.1 101 Switching Protocols
2024-10-22 09:14:34,463 - DEBUG - Connection: upgrade
2024-10-22 09:14:34,525 - DEBUG - Date: Tue, 22 Oct 2024 07:14:33 GMT
2024-10-22 09:14:34,540 - DEBUG - Server: fasthttp
2024-10-22 09:14:34,556 - DEBUG - Upgrade: websocket
2024-10-22 09:14:34,570 - DEBUG - Sec-Websocket-Accept: ILpfsfVKH0xDKXsL1Guo732wZoQ=
2024-10-22 09:14:34,586 - DEBUG - X-Cache: Miss from cloudfront
2024-10-22 09:14:34,632 - DEBUG - Via: 1.1 75368b7bf20cbbab33ae6a3ed6416920.cloudfront.net (CloudFront)
2024-10-22 09:14:34,647 - DEBUG - X-Amz-Cf-Pop: VIE50-P3
2024-10-22 09:14:34,739 - DEBUG - X-Amz-Cf-Id: TLWblJ335Ub1I1oHGqetNAMmrhevUTJcB5N1ftZ0i1usW_IGzffRCg==
2024-10-22 09:14:34,770 - DEBUG - -----------------------
2024-10-22 09:14:34,786 - INFO - WebSocket Unified V5 (Auth) connected
2024-10-22 09:14:34,786 - INFO - Websocket connected
2024-10-22 09:14:34,787 - DEBUG - ++Sent raw: b'\x81\xfe\x00\x81\xc2\xb7"\xaf\xb9\x95M\xdf\xe0\x8d\x02\x8d\xa3\xc2V\xc7\xe0\x9b\x02\x8d\xa3\xc5E\xdc\xe0\x8d\x02\xf4\xe0\xd0g\xd7\xb1\xc5O\xed\xa4\xd2e\x97\xaf\xffW\xcd\xf2\x84q\x8d\xee\x97\x13\x98\xf0\x8e\x17\x97\xf3\x85\x15\x9a\xf5\x8f\x15\x83\xe2\x95\x1b\xce\xf6\xd3\x16\x96\xf7\x8e\x16\x98\xa7\xd1F\x9a\xf3\x84F\xcb\xf5\xd1\x10\x9d\xf6\x8eF\x9f\xfb\x85F\xce\xf5\x86D\x9f\xa0\x85@\xc9\xf2\xd4\x13\x9d\xfb\xd2\x15\xc9\xf6\xd5D\x9a\xf3\x84\x11\xca\xf4\x87\x1b\x9b\xfb\xd1@\x9b\xa0\x84\x00\xf2\xbf'
2024-10-22 09:14:34,789 - DEBUG - ++Sent decoded: fin=1 opcode=1 data=b'{"op": "auth", "args": ["gExsrmBfeG8mHub03S", 1729581275787, "9a4d495947efd513dd7f2249d092da71f0b2bf0c129e7f4bf5133e60949fb4b3"]}'
2024-10-22 09:14:34,792 - DEBUG - ++Sent raw: b'\x81\xe7-\xe2\xdeeV\xc0\xb1\x15\x0f\xd8\xfeG^\x97\xbc\x16N\x90\xb7\x07H\xc0\xf2E\x0f\x90\xbb\x14r\x8b\xbaG\x17\xc2\xfcR\x15\xd5\xed]H\xdb\xbaHO\xd4\xe7U\x00\xd6\xecPH\xcf\xe6P\x1b\xd2\xf3S\x1a\x84\xbb\x00\x1a\xd2\xb8Q\x1b\xd4\xeeG\x01\xc2\xfc\x04_\x85\xadG\x17\xc2\x85GB\x90\xba\x00_\x80\xb1\nF\xcc\xebU\x03\xa0\x8a&x\xb1\x9a1\x0f\xbf\xa3'
2024-10-22 09:14:34,793 - DEBUG - ++Sent decoded: fin=1 opcode=1 data=b'{"op": "subscribe", "req_id": "78738e9d-b690-425e-8560-67fee70f4660", "args": ["orderbook.50.BTCUSDT"]}'
2024-10-22 09:14:35,186 - DEBUG - ++Rcv raw: b'\x81P{"success":true,"ret_msg":"","op":"auth","conn_id":"crjtta1qo29j6gv0ald0-3okqv"}'
2024-10-22 09:14:35,187 - DEBUG - ++Rcv decoded: fin=1 opcode=1 data=b'{"success":true,"ret_msg":"","op":"auth","conn_id":"crjtta1qo29j6gv0ald0-3okqv"}'
2024-10-22 09:14:35,187 - DEBUG - ++Rcv raw: b'\x81~\x08\xce{"topic":"orderbook.50.BTCUSDT","type":"snapshot","ts":1729581271874,"data":{"s":"BTCUSDT","b":[["67601.10","0.547"],["67560.80","0.001"],["67550.80","0.457"],["67550.00","0.003"],["67516.90","0.002"],["67494.30","0.004"],["67489.80","0.918"],["67461.30","0.230"],["67456.90","0.002"],["67452.60","0.426"],["67450.20","0.247"],["67432.20","0.547"],["67376.10","0.027"],["67375.00","0.003"],["67331.70","0.004"],["67322.10","0.001"],["67320.90","0.835"],["67300.00","0.057"],["67293.30","0.017"],["67292.80","0.002"],["67291.50","0.044"],["67290.00","0.057"],["67287.60","0.264"],["67286.80","0.670"],["67283.50","0.001"],["67282.90","0.426"],["67277.30","0.089"],["67263.30","0.547"],["67249.40","0.129"],["67233.30","0.001"],["67225.20","0.020"],["67223.60","0.002"],["67214.10","0.005"],["67201.90","0.153"],["67200.00","0.003"],["67169.10","0.004"],["67151.90","0.918"],["67129.00","0.002"],["67123.40","0.625"],["67122.90","0.001"],["67121.60","0.120"],["67113.20","0.424"],["67094.40","0.545"],["67035.70","0.001"],["67033.30","0.057"],["67028.10","0.459"],["67025.00","0.003"],["67010.00","0.089"],["67006.50","0.004"],["67006.10","0.001"]],"a":[["67777.00","0.293"],["67779.30","0.001"],["67786.40","0.002"],["67792.00","0.426"],["67800.00","0.013"],["67801.10","0.443"],["67802.90","0.551"],["67811.90","0.089"],["67827.80","0.878"],["67832.90","0.129"],["67833.30","0.057"],["67840.20","0.001"],["67893.00","0.001"],["67900.00","0.003"],["67901.50","0.459"],["67928.30","0.001"],["67939.00","0.547"],["67951.70","0.002"],["67961.70","0.131"],["67970.90","0.443"],["67984.00","0.074"],["67985.20","0.001"],["67986.60","0.017"],["67996.70","0.487"],["68000.00","0.050"],["68001.00","0.010"],["68008.80","0.005"],["68011.20","0.018"],["68027.10","0.001"],["68030.00","0.553"],["68039.80","0.593"],["68056.90","0.264"],["68068.10","0.001"],["68069.00","0.001"],["68075.00","0.003"],["68077.50","0.026"],["68079.10","0.089"],["68100.00","0.070"],["68107.90","0.547"],["68108.00","0.001"],["68115.60","0.005"],["68117.50","0.024"],["68124.60","0.129"],["68131.30","0.296"],["68140.80","0.443"],["68142.80","0.020"],["68165.70","0.918"],["68166.90","0.035"],["68181.90","0.020"],["68188.40","0.001"]],"u":10185077,"seq":9374373045},"cts":1729581271007}'
2024-10-22 09:14:35,189 - DEBUG - ++Rcv decoded: fin=1 opcode=1 data=b'{"topic":"orderbook.50.BTCUSDT","type":"snapshot","ts":1729581271874,"data":{"s":"BTCUSDT","b":[["67601.10","0.547"],["67560.80","0.001"],["67550.80","0.457"],["67550.00","0.003"],["67516.90","0.002"],["67494.30","0.004"],["67489.80","0.918"],["67461.30","0.230"],["67456.90","0.002"],["67452.60","0.426"],["67450.20","0.247"],["67432.20","0.547"],["67376.10","0.027"],["67375.00","0.003"],["67331.70","0.004"],["67322.10","0.001"],["67320.90","0.835"],["67300.00","0.057"],["67293.30","0.017"],["67292.80","0.002"],["67291.50","0.044"],["67290.00","0.057"],["67287.60","0.264"],["67286.80","0.670"],["67283.50","0.001"],["67282.90","0.426"],["67277.30","0.089"],["67263.30","0.547"],["67249.40","0.129"],["67233.30","0.001"],["67225.20","0.020"],["67223.60","0.002"],["67214.10","0.005"],["67201.90","0.153"],["67200.00","0.003"],["67169.10","0.004"],["67151.90","0.918"],["67129.00","0.002"],["67123.40","0.625"],["67122.90","0.001"],["67121.60","0.120"],["67113.20","0.424"],["67094.40","0.545"],["67035.70","0.001"],["67033.30","0.057"],["67028.10","0.459"],["67025.00","0.003"],["67010.00","0.089"],["67006.50","0.004"],["67006.10","0.001"]],"a":[["67777.00","0.293"],["67779.30","0.001"],["67786.40","0.002"],["67792.00","0.426"],["67800.00","0.013"],["67801.10","0.443"],["67802.90","0.551"],["67811.90","0.089"],["67827.80","0.878"],["67832.90","0.129"],["67833.30","0.057"],["67840.20","0.001"],["67893.00","0.001"],["67900.00","0.003"],["67901.50","0.459"],["67928.30","0.001"],["67939.00","0.547"],["67951.70","0.002"],["67961.70","0.131"],["67970.90","0.443"],["67984.00","0.074"],["67985.20","0.001"],["67986.60","0.017"],["67996.70","0.487"],["68000.00","0.050"],["68001.00","0.010"],["68008.80","0.005"],["68011.20","0.018"],["68027.10","0.001"],["68030.00","0.553"],["68039.80","0.593"],["68056.90","0.264"],["68068.10","0.001"],["68069.00","0.001"],["68075.00","0.003"],["68077.50","0.026"],["68079.10","0.089"],["68100.00","0.070"],["68107.90","0.547"],["68108.00","0.001"],["68115.60","0.005"],["68117.50","0.024"],["68124.60","0.129"],["68131.30","0.296"],["68140.80","0.443"],["68142.80","0.020"],["68165.70","0.918"],["68166.90","0.035"],["68181.90","0.020"],["68188.40","0.001"]],"u":10185077,"seq":9374373045},"cts":1729581271007}'
2024-10-22 09:14:52,858 - DEBUG - ++Sent raw: b'\x81\x8e\xe4E\xe5\xc8\x9fg\x8a\xb8\xc6\x7f\xc5\xea\x94,\x8b\xaf\xc68'
2024-10-22 09:14:52,858 - DEBUG - ++Sent decoded: fin=1 opcode=1 data=b'{"op": "ping"}'
2024-10-22 09:14:54,796 - DEBUG - ++Sent raw: b'\x81\x8e\x80\x81\xd6\x01\xfb\xa3\xb9q\xa2\xbb\xf6#\xf0\xe8\xb8f\xa2\xfc'
2024-10-22 09:14:54,797 - DEBUG - ++Sent decoded: fin=1 opcode=1 data=b'{"op": "ping"}'
2024-10-22 09:14:55,203 - DEBUG - ++Rcv raw: b'\x81M{"op":"pong","args":["1729581294710"],"conn_id":"crjtta1qo29j6gv0ald0-3okqv"}'
2024-10-22 09:14:55,203 - DEBUG - ++Rcv decoded: fin=1 opcode=1 data=b'{"op":"pong","args":["1729581294710"],"conn_id":"crjtta1qo29j6gv0ald0-3okqv"}'
2024-10-22 09:15:08,946 - DEBUG - ++Sent raw: b'\x88\x82\t\x91I\x9b\ny'
2024-10-22 09:15:08,947 - DEBUG - ++Sent decoded: fin=1 opcode=8 data=b'\x03\xe8'
2024-10-22 09:15:14,812 - DEBUG - Sending ping
2024-10-22 09:15:14,813 - DEBUG - ++Sent raw: b'\x89\x80a\x14W\xf1'
2024-10-22 09:15:14,813 - DEBUG - ++Sent decoded: fin=1 opcode=9 data=b''
2024-10-22 09:15:15,205 - DEBUG - ++Rcv raw: b'\x8a\x00'
2024-10-22 09:15:15,205 - DEBUG - ++Rcv decoded: fin=1 opcode=10 data=b''
2024-10-22 09:15:15,206 - DEBUG - ++Sent raw: b'\x81\x8e}B1[\x06`^+_x\x11y\r+_<_?'
2024-10-22 09:15:15,206 - DEBUG - ++Sent decoded: fin=1 opcode=1 data=b'{"op": "ping"}'
2024-10-22 09:15:15,598 - DEBUG - ++Rcv raw: b'\x81M{"op":"pong","args":["1729581315117"],"conn_id":"crjtta1qo29j6gv0ald0-3okqv"}'
2024-10-22 09:15:15,599 - DEBUG - ++Rcv decoded: fin=1 opcode=1 data=b'{"op":"pong","args":["1729581315117"],"conn_id":"crjtta1qo29j6gv0ald0-3okqv"}'
2024-10-22 09:15:34,823 - DEBUG - Sending ping
2024-10-22 09:15:34,823 - DEBUG - ++Sent raw: b'\x89\x80k\x92\x1bR'
2024-10-22 09:15:34,824 - DEBUG - ++Sent decoded: fin=1 opcode=9 data=b''
2024-10-22 09:15:35,226 - DEBUG - ++Rcv raw: b'\x8a\x00'
2024-10-22 09:15:35,226 - DEBUG - ++Rcv decoded: fin=1 opcode=10 data=b''
2024-10-22 09:15:35,227 - DEBUG - ++Sent raw: b'\x81\x8ef\x13\xb9\xeb\x1d1\xd6\x9bD)\x99\xc9\x16z\xd7\x8cDn'
2024-10-22 09:15:35,227 - DEBUG - ++Sent decoded: fin=1 opcode=1 data=b'{"op": "ping"}'
2024-10-22 09:15:35,622 - DEBUG - ++Rcv raw: b'\x81M{"op":"pong","args":["1729581335137"],"conn_id":"crjtta1qo29j6gv0ald0-3okqv"}'
2024-10-22 09:15:35,622 - DEBUG - ++Rcv decoded: fin=1 opcode=1 data=b'{"op":"pong","args":["1729581335137"],"conn_id":"crjtta1qo29j6gv0ald0-3okqv"}'
2024-10-22 09:15:54,833 - DEBUG - Sending ping
2024-10-22 09:15:54,834 - DEBUG - ++Sent raw: b'\x89\x80STa#'
2024-10-22 09:15:54,834 - DEBUG - ++Sent decoded: fin=1 opcode=9 data=b''
2024-10-22 09:15:55,220 - DEBUG - ++Rcv raw: b'\x8a\x00'
2024-10-22 09:15:55,220 - DEBUG - ++Rcv decoded: fin=1 opcode=10 data=b''
2024-10-22 09:15:55,222 - DEBUG - ++Sent raw: b'\x81\x8e\xc7(\xb2\xae\xbc\n\xdd\xde\xe5\x12\x92\x8c\xb7A\xdc\xc9\xe5U'
2024-10-22 09:15:55,222 - DEBUG - ++Sent decoded: fin=1 opcode=1 data=b'{"op": "ping"}'
2024-10-22 09:15:55,628 - DEBUG - ++Rcv raw: b'\x81M{"op":"pong","args":["1729581355143"],"conn_id":"crjtta1qo29j6gv0ald0-3okqv"}'
2024-10-22 09:15:55,628 - DEBUG - ++Rcv decoded: fin=1 opcode=1 data=b'{"op":"pong","args":["1729581355143"],"conn_id":"crjtta1qo29j6gv0ald0-3okqv"}'
2024-10-22 09:16:09,166 - INFO - WebSocket Unified V5 (Auth) attempting connection...
2024-10-22 09:16:10,321 - DEBUG - --- request header ---
2024-10-22 09:16:10,336 - DEBUG - GET /v5/public/linear HTTP/1.1
Upgrade: websocket
Host: stream-testnet.bybit.com
Origin: https://stream-testnet.bybit.com
Sec-WebSocket-Key: C/CvSruEP34WIUDyo0Z/nw==
Sec-WebSocket-Version: 13
Connection: Upgrade


2024-10-22 09:16:10,366 - DEBUG - -----------------------
2024-10-22 09:16:10,397 - DEBUG - --- response header ---
2024-10-22 09:16:11,195 - DEBUG - HTTP/1.1 101 Switching Protocols
2024-10-22 09:16:11,241 - DEBUG - Connection: upgrade
2024-10-22 09:16:11,256 - DEBUG - Date: Tue, 22 Oct 2024 07:16:10 GMT
2024-10-22 09:16:11,318 - DEBUG - Upgrade: websocket
2024-10-22 09:16:11,349 - DEBUG - Sec-WebSocket-Accept: hVcoKAVgc+r6d762tWQlY8Mzpxo=
2024-10-22 09:16:11,380 - DEBUG - X-Cache: Miss from cloudfront
2024-10-22 09:16:11,442 - DEBUG - Via: 1.1 516cc0bb4a2e63bc7203b884b9f5c486.cloudfront.net (CloudFront)
2024-10-22 09:16:11,503 - DEBUG - X-Amz-Cf-Pop: VIE50-P3
2024-10-22 09:16:11,533 - DEBUG - X-Amz-Cf-Id: ju47vNSA7GtFFv_7_YAS8F_JtbAID6mYbb-Kx6CyXNOoGNuRXX9ZNQ==
2024-10-22 09:16:11,564 - DEBUG - -----------------------
2024-10-22 09:16:11,579 - INFO - WebSocket Unified V5 (Auth) connected
2024-10-22 09:16:11,579 - INFO - Websocket connected
2024-10-22 09:16:11,582 - INFO - WebSocket Unified V5 (Auth) attempting connection...
2024-10-22 09:16:12,226 - DEBUG - --- request header ---
2024-10-22 09:16:12,257 - DEBUG - GET /v5/private HTTP/1.1
Upgrade: websocket
Host: stream-testnet.bybit.com
Origin: https://stream-testnet.bybit.com
Sec-WebSocket-Key: VLAI0sLWi0T8dNVBWyKZSA==
Sec-WebSocket-Version: 13
Connection: Upgrade


2024-10-22 09:16:12,304 - DEBUG - -----------------------
2024-10-22 09:16:12,320 - DEBUG - --- response header ---
2024-10-22 09:16:13,151 - DEBUG - HTTP/1.1 101 Switching Protocols
2024-10-22 09:16:13,198 - DEBUG - Connection: upgrade
2024-10-22 09:16:13,213 - DEBUG - Date: Tue, 22 Oct 2024 07:16:12 GMT
2024-10-22 09:16:13,260 - DEBUG - Server: fasthttp
2024-10-22 09:16:13,306 - DEBUG - Upgrade: websocket
2024-10-22 09:16:13,322 - DEBUG - Sec-Websocket-Accept: VtDmMxUp1f9+XE9TIJat1ECU2F0=
2024-10-22 09:16:13,337 - DEBUG - X-Cache: Miss from cloudfront
2024-10-22 09:16:13,506 - DEBUG - Via: 1.1 293d4918243e6d2ccc6737621ee569c6.cloudfront.net (CloudFront)
2024-10-22 09:16:13,537 - DEBUG - X-Amz-Cf-Pop: VIE50-P3
2024-10-22 09:16:13,568 - DEBUG - X-Amz-Cf-Id: z5BZTtmnTsCQHKZTQLNNpKhX3EHDWjMhF7wVna5vAMTbW0c1iFO_Ww==
2024-10-22 09:16:13,599 - DEBUG - -----------------------
2024-10-22 09:16:13,615 - INFO - WebSocket Unified V5 (Auth) connected
2024-10-22 09:16:13,615 - INFO - Websocket connected
2024-10-22 09:16:13,616 - DEBUG - ++Sent raw: b'\x81\xfe\x00\x81\xf5c\xfe\xb6\x8eA\x91\xc6\xd7Y\xde\x94\x94\x16\x8a\xde\xd7O\xde\x94\x94\x11\x99\xc5\xd7Y\xde\xed\xd7\x04\xbb\xce\x86\x11\x93\xf4\x93\x06\xb9\x8e\x98+\x8b\xd4\xc5P\xad\x94\xd9C\xcf\x81\xc7Z\xcb\x8e\xc4P\xc9\x82\xc3R\xcb\x9a\xd5A\x9d\xd3\xc3Z\xcf\x82\xc5T\xc6\x86\x90[\xc9\x8f\xc1\x01\x98\xd5\x91\x01\xc8\xd4\x97T\x9f\x8e\x91S\xcc\xd5\xc2Z\xcc\x8f\xcdZ\xca\xd7\x93T\x9d\x82\xc4Q\xca\xd4\xcdZ\xce\x83\x91R\xc9\x80\xc3\x07\x9c\x86\xc2U\xc9\x81\xc6S\xdc\xeb\x88'
2024-10-22 09:16:13,617 - DEBUG - ++Sent decoded: fin=1 opcode=1 data=b'{"op": "auth", "args": ["gExsrmBfeG8mHub03S", 1729581374615, "ce69140780e8794bfcdb6bb7a8d02c7929894af7c4124b8905d1766db0767730"]}'
2024-10-22 09:16:13,619 - DEBUG - ++Sent raw: b'\x81\xe7`\x0f\xd5\x1a\x1b-\xbajB5\xf58\x13z\xb7i\x03}\xbcx\x05-\xf9:B}\xb0k?f\xb18Z/\xf7.\x03l\xb4#\x05j\xe27\x01n\xe5.M;\xb7.R"\xb4|Y;\xf8(\x01?\xb6.S<\xe0~X7\xb38L/\xf7{\x12h\xa68Z/\x8e8\x0f}\xb1\x7f\x12m\xbau\x0b!\xe0*NM\x81Y5\\\x91NBR\xa8'
2024-10-22 09:16:13,620 - DEBUG - ++Sent decoded: fin=1 opcode=1 data=b'{"op": "subscribe", "req_id": "4cca9ee7-aa04-4b42-af94-2a0c4335d88f", "args": ["orderbook.50.BTCUSDT"]}'
2024-10-22 09:16:14,012 - DEBUG - ++Rcv raw: b'\x81~\x08\xce{"topic":"orderbook.50.BTCUSDT","type":"snapshot","ts":1729581371874,"data":{"s":"BTCUSDT","b":[["67490.00","0.002"],["67489.80","0.465"],["67461.30","0.230"],["67456.90","0.002"],["67452.60","0.426"],["67450.20","0.247"],["67432.20","0.547"],["67376.10","0.027"],["67375.00","0.003"],["67331.70","0.004"],["67322.10","0.001"],["67320.90","0.835"],["67300.00","0.057"],["67293.30","0.017"],["67292.80","0.002"],["67291.50","0.044"],["67290.00","0.057"],["67287.60","0.264"],["67286.80","0.670"],["67286.70","0.020"],["67283.50","0.001"],["67282.90","0.426"],["67277.30","0.089"],["67263.30","0.547"],["67249.40","0.129"],["67233.30","0.001"],["67223.60","0.002"],["67214.10","0.005"],["67201.90","0.153"],["67200.00","0.003"],["67169.10","0.004"],["67151.90","0.918"],["67129.00","0.002"],["67123.40","0.625"],["67122.90","0.001"],["67121.60","0.120"],["67113.20","0.424"],["67094.40","0.545"],["67035.70","0.001"],["67033.30","0.057"],["67028.10","0.459"],["67025.00","0.003"],["67010.00","0.089"],["67006.50","0.004"],["67006.10","0.001"],["67000.00","0.074"],["66992.80","0.281"],["66982.90","0.918"],["66965.70","0.002"],["66960.00","0.013"]],"a":[["67600.00","0.001"],["67613.60","0.001"],["67627.20","0.001"],["67656.90","0.004"],["67725.00","0.003"],["67725.90","0.459"],["67770.10","0.082"],["67777.00","0.686"],["67779.30","0.001"],["67786.40","0.001"],["67792.00","0.244"],["67800.00","0.013"],["67801.10","0.443"],["67802.90","0.551"],["67811.90","0.089"],["67827.80","0.878"],["67832.90","0.129"],["67833.30","0.057"],["67840.20","0.001"],["67893.00","0.001"],["67900.00","0.003"],["67901.50","0.459"],["67928.30","0.001"],["67939.00","0.547"],["67951.70","0.002"],["67961.70","0.131"],["67970.90","0.443"],["67984.00","0.074"],["67985.20","0.001"],["67986.60","0.017"],["67996.70","0.487"],["68000.00","0.050"],["68001.00","0.010"],["68008.80","0.005"],["68011.20","0.018"],["68027.10","0.001"],["68030.00","0.553"],["68039.80","0.593"],["68056.90","0.264"],["68068.10","0.001"],["68069.00","0.001"],["68075.00","0.003"],["68077.50","0.026"],["68079.10","0.089"],["68100.00","0.070"],["68107.90","0.547"],["68108.00","0.001"],["68115.60","0.005"],["68117.50","0.024"],["68124.60","0.129"]],"u":10185324,"seq":9374373641},"cts":1729581371794}'
2024-10-22 09:16:14,013 - DEBUG - ++Rcv raw: b'\x81P{"success":true,"ret_msg":"","op":"auth","conn_id":"crjtta1qo29j6gv0ald0-3okvn"}'
2024-10-22 09:16:14,014 - DEBUG - ++Rcv decoded: fin=1 opcode=1 data=b'{"topic":"orderbook.50.BTCUSDT","type":"snapshot","ts":1729581371874,"data":{"s":"BTCUSDT","b":[["67490.00","0.002"],["67489.80","0.465"],["67461.30","0.230"],["67456.90","0.002"],["67452.60","0.426"],["67450.20","0.247"],["67432.20","0.547"],["67376.10","0.027"],["67375.00","0.003"],["67331.70","0.004"],["67322.10","0.001"],["67320.90","0.835"],["67300.00","0.057"],["67293.30","0.017"],["67292.80","0.002"],["67291.50","0.044"],["67290.00","0.057"],["67287.60","0.264"],["67286.80","0.670"],["67286.70","0.020"],["67283.50","0.001"],["67282.90","0.426"],["67277.30","0.089"],["67263.30","0.547"],["67249.40","0.129"],["67233.30","0.001"],["67223.60","0.002"],["67214.10","0.005"],["67201.90","0.153"],["67200.00","0.003"],["67169.10","0.004"],["67151.90","0.918"],["67129.00","0.002"],["67123.40","0.625"],["67122.90","0.001"],["67121.60","0.120"],["67113.20","0.424"],["67094.40","0.545"],["67035.70","0.001"],["67033.30","0.057"],["67028.10","0.459"],["67025.00","0.003"],["67010.00","0.089"],["67006.50","0.004"],["67006.10","0.001"],["67000.00","0.074"],["66992.80","0.281"],["66982.90","0.918"],["66965.70","0.002"],["66960.00","0.013"]],"a":[["67600.00","0.001"],["67613.60","0.001"],["67627.20","0.001"],["67656.90","0.004"],["67725.00","0.003"],["67725.90","0.459"],["67770.10","0.082"],["67777.00","0.686"],["67779.30","0.001"],["67786.40","0.001"],["67792.00","0.244"],["67800.00","0.013"],["67801.10","0.443"],["67802.90","0.551"],["67811.90","0.089"],["67827.80","0.878"],["67832.90","0.129"],["67833.30","0.057"],["67840.20","0.001"],["67893.00","0.001"],["67900.00","0.003"],["67901.50","0.459"],["67928.30","0.001"],["67939.00","0.547"],["67951.70","0.002"],["67961.70","0.131"],["67970.90","0.443"],["67984.00","0.074"],["67985.20","0.001"],["67986.60","0.017"],["67996.70","0.487"],["68000.00","0.050"],["68001.00","0.010"],["68008.80","0.005"],["68011.20","0.018"],["68027.10","0.001"],["68030.00","0.553"],["68039.80","0.593"],["68056.90","0.264"],["68068.10","0.001"],["68069.00","0.001"],["68075.00","0.003"],["68077.50","0.026"],["68079.10","0.089"],["68100.00","0.070"],["68107.90","0.547"],["68108.00","0.001"],["68115.60","0.005"],["68117.50","0.024"],["68124.60","0.129"]],"u":10185324,"seq":9374373641},"cts":1729581371794}'
2024-10-22 09:16:14,014 - DEBUG - ++Rcv decoded: fin=1 opcode=1 data=b'{"success":true,"ret_msg":"","op":"auth","conn_id":"crjtta1qo29j6gv0ald0-3okvn"}'
2024-10-22 09:16:31,595 - DEBUG - ++Sent raw: b'\x81\x8e\xc6IS\x12\xbdk<b\xe4ss0\xb6 =u\xe44'
2024-10-22 09:16:31,595 - DEBUG - ++Sent decoded: fin=1 opcode=1 data=b'{"op": "ping"}'
2024-10-22 09:16:33,623 - DEBUG - ++Sent raw: b'\x81\x8e\xf3\xe7\xff6\x88\xc5\x90F\xd1\xdd\xdf\x14\x83\x8e\x91Q\xd1\x9a'
2024-10-22 09:16:33,624 - DEBUG - ++Sent decoded: fin=1 opcode=1 data=b'{"op": "ping"}'
2024-10-22 09:16:34,035 - DEBUG - ++Rcv raw: b'\x81M{"op":"pong","args":["1729581393542"],"conn_id":"crjtta1qo29j6gv0ald0-3okvn"}'
2024-10-22 09:16:34,036 - DEBUG - ++Rcv decoded: fin=1 opcode=1 data=b'{"op":"pong","args":["1729581393542"],"conn_id":"crjtta1qo29j6gv0ald0-3okvn"}'
2024-10-22 09:16:40,976 - DEBUG - ++Sent raw: b'\x88\x82\x92~\xcb\xe1\x91\x96'
2024-10-22 09:16:40,977 - DEBUG - ++Sent decoded: fin=1 opcode=8 data=b'\x03\xe8'
2024-10-22 09:17:17,350 - INFO - WebSocket Unified V5 (Auth) attempting connection...
2024-10-22 09:17:18,188 - DEBUG - --- request header ---
2024-10-22 09:17:18,219 - DEBUG - GET /v5/public/linear HTTP/1.1
Upgrade: websocket
Host: stream-testnet.bybit.com
Origin: https://stream-testnet.bybit.com
Sec-WebSocket-Key: k7WRXjpxIsNBQmf1biCm9w==
Sec-WebSocket-Version: 13
Connection: Upgrade


2024-10-22 09:17:18,250 - DEBUG - -----------------------
2024-10-22 09:17:18,281 - DEBUG - --- response header ---
2024-10-22 09:17:19,082 - DEBUG - HTTP/1.1 101 Switching Protocols
2024-10-22 09:17:19,098 - DEBUG - Connection: upgrade
2024-10-22 09:17:19,129 - DEBUG - Date: Tue, 22 Oct 2024 07:17:18 GMT
2024-10-22 09:17:19,191 - DEBUG - Upgrade: websocket
2024-10-22 09:17:19,267 - DEBUG - Sec-WebSocket-Accept: UYcVmLI3aoZqq6+tkfZam/ghEw8=
2024-10-22 09:17:19,298 - DEBUG - X-Cache: Miss from cloudfront
2024-10-22 09:17:19,314 - DEBUG - Via: 1.1 59934e2100e012bf757855f3cda08cbc.cloudfront.net (CloudFront)
2024-10-22 09:17:19,314 - DEBUG - X-Amz-Cf-Pop: VIE50-P3
2024-10-22 09:17:19,344 - DEBUG - X-Amz-Cf-Id: kU1Qc2xksv0-tWMLL65MmhDfEdoKWSr63IhKjk_kZyA0wjCwpeHu1g==
2024-10-22 09:17:19,391 - DEBUG - -----------------------
2024-10-22 09:17:19,422 - INFO - WebSocket Unified V5 (Auth) connected
2024-10-22 09:17:19,422 - INFO - Websocket connected
2024-10-22 09:17:19,423 - INFO - WebSocket Unified V5 (Auth) attempting connection...
2024-10-22 09:17:20,024 - DEBUG - --- request header ---
2024-10-22 09:17:20,040 - DEBUG - GET /v5/private HTTP/1.1
Upgrade: websocket
Host: stream-testnet.bybit.com
Origin: https://stream-testnet.bybit.com
Sec-WebSocket-Key: iVMwxXiaD1mh2ZYcb2U9Gg==
Sec-WebSocket-Version: 13
Connection: Upgrade


2024-10-22 09:17:20,056 - DEBUG - -----------------------
2024-10-22 09:17:20,071 - DEBUG - --- response header ---
2024-10-22 09:17:20,900 - DEBUG - HTTP/1.1 101 Switching Protocols
2024-10-22 09:17:20,931 - DEBUG - Connection: upgrade
2024-10-22 09:17:20,946 - DEBUG - Date: Tue, 22 Oct 2024 07:17:20 GMT
2024-10-22 09:17:20,961 - DEBUG - Server: fasthttp
2024-10-22 09:17:20,992 - DEBUG - Upgrade: websocket
2024-10-22 09:17:21,039 - DEBUG - Sec-Websocket-Accept: Ctvzbg/fMajtil0j42Un27EEOe0=
2024-10-22 09:17:21,054 - DEBUG - X-Cache: Miss from cloudfront
2024-10-22 09:17:21,085 - DEBUG - Via: 1.1 099789dcc2dc61f3a3221c8edb33ae6a.cloudfront.net (CloudFront)
2024-10-22 09:17:21,115 - DEBUG - X-Amz-Cf-Pop: VIE50-P3
2024-10-22 09:17:21,131 - DEBUG - X-Amz-Cf-Id: F-bziAxh1sQzI4f4Srm9d4eRfFw5N4RsaD5wFOGPtFAo_hzpNsQeTQ==
2024-10-22 09:17:21,177 - DEBUG - -----------------------
2024-10-22 09:17:21,208 - INFO - WebSocket Unified V5 (Auth) connected
2024-10-22 09:17:21,208 - INFO - Websocket connected
2024-10-22 09:17:21,208 - DEBUG - ++Sent raw: b'\x81\xfe\x00\x81m-D\x03\x16\x0f+sO\x17d!\x0cX0kO\x01d!\x0c_#pO\x17dXOJ\x01{\x1e_)A\x0bH\x03;\x00e1a]\x1e\x17!A\ru4_\x14q;\\\x19p1_\x1d|/M\x0fpaTK\'bZ\x1a!g[Ov1\x0e\x15qb\x0e\x1cu:\x0c\x18|6X\x1d|5U\x15"`X\x18q4]Hq:\x0f\x18q1_\x1a|fT\x1cw7UL&`[\x1e\'b\x0f\x1ef^\x10'
2024-10-22 09:17:21,208 - DEBUG - ++Sent decoded: fin=1 opcode=1 data=b'{"op": "auth", "args": ["gExsrmBfeG8mHub03S", 1729581442208, "4b9fca77ed6b22c85ac119a585508688fc55570e59b552278e91348abc63cab3"]}'
2024-10-22 09:17:21,209 - DEBUG - ++Sent raw: b'\x81\xe7\xfa\xfc\xad\x95\x81\xde\xc2\xe5\xd8\xc6\x8d\xb7\x89\x89\xcf\xe6\x99\x8e\xc4\xf7\x9f\xde\x81\xb5\xd8\x8e\xc8\xe4\xa5\x95\xc9\xb7\xc0\xdc\x8f\xa3\x9c\xc9\x98\xf0\xcb\x9a\x9a\xb8\xce\x99\xcb\xf6\xd7\xc8\xcb\xad\xc9\xd1\x95\xf1\x9b\xc5\x80\xad\x99\xcb\x9e\xac\x9c\xce\x99\xa6\x9c\x9f\x95\xb7\xd6\xdc\x8f\xf4\x88\x9b\xde\xb7\xc0\xdc\xf6\xb7\x95\x8e\xc9\xf0\x88\x9e\xc2\xfa\x91\xd2\x98\xa5\xd4\xbe\xf9\xd6\xaf\xaf\xe9\xc1\xd8\xa1\xd0'
2024-10-22 09:17:21,210 - DEBUG - ++Sent decoded: fin=1 opcode=1 data=b'{"op": "subscribe", "req_id": "6f55e1f7-4efc-4f83-8da9-8c739f243fc8", "args": ["orderbook.50.BTCUSDT"]}'
2024-10-22 09:17:21,610 - DEBUG - ++Rcv raw: b'\x81P{"success":true,"ret_msg":"","op":"auth","conn_id":"crjtta1qo29j6gv0ald0-3okwf"}'
2024-10-22 09:17:21,610 - DEBUG - ++Rcv decoded: fin=1 opcode=1 data=b'{"success":true,"ret_msg":"","op":"auth","conn_id":"crjtta1qo29j6gv0ald0-3okwf"}'
2024-10-22 09:17:21,616 - DEBUG - ++Rcv raw: b'\x81~\x08\xce{"topic":"orderbook.50.BTCUSDT","type":"snapshot","ts":1729581439873,"data":{"s":"BTCUSDT","b":[["67622.30","0.427"],["67621.50","0.002"],["67613.60","0.686"],["67601.10","0.547"],["67550.80","0.065"],["67550.00","0.001"],["67531.40","0.001"],["67500.00","0.013"],["67494.30","0.004"],["67489.80","0.465"],["67461.30","0.230"],["67456.90","0.002"],["67452.60","0.426"],["67450.20","0.247"],["67432.20","0.547"],["67376.10","0.027"],["67375.00","0.003"],["67331.70","0.004"],["67322.10","0.001"],["67320.90","0.835"],["67300.00","0.057"],["67293.30","0.017"],["67292.80","0.002"],["67291.50","0.044"],["67290.00","0.057"],["67287.60","0.264"],["67286.80","0.670"],["67286.70","0.020"],["67283.50","0.001"],["67282.90","0.426"],["67277.30","0.089"],["67263.30","0.547"],["67249.40","0.129"],["67233.30","0.001"],["67223.60","0.002"],["67214.10","0.005"],["67201.90","0.153"],["67200.00","0.003"],["67169.10","0.004"],["67151.90","0.918"],["67129.00","0.002"],["67123.40","0.625"],["67122.90","0.001"],["67121.60","0.120"],["67113.20","0.424"],["67094.40","0.545"],["67035.70","0.001"],["67033.30","0.057"],["67028.10","0.459"],["67025.00","0.003"]],"a":[["67622.40","0.001"],["67636.10","0.001"],["67649.60","0.001"],["67801.10","0.423"],["67802.90","0.551"],["67811.90","0.089"],["67827.80","0.878"],["67832.90","0.129"],["67833.30","0.057"],["67840.20","0.001"],["67893.00","0.001"],["67900.00","0.003"],["67901.50","0.459"],["67928.30","0.001"],["67939.00","0.547"],["67951.70","0.002"],["67961.70","0.131"],["67970.90","0.443"],["67984.00","0.074"],["67985.20","0.001"],["67986.60","0.017"],["67996.70","0.487"],["68000.00","0.050"],["68001.00","0.010"],["68008.80","0.005"],["68011.20","0.018"],["68027.10","0.001"],["68030.00","0.553"],["68039.80","0.593"],["68056.90","0.264"],["68068.10","0.001"],["68069.00","0.001"],["68075.00","0.003"],["68077.50","0.026"],["68079.10","0.089"],["68100.00","0.070"],["68107.90","0.547"],["68108.00","0.001"],["68115.60","0.005"],["68117.50","0.024"],["68124.60","0.129"],["68131.30","0.296"],["68140.80","0.443"],["68142.80","0.020"],["68165.70","0.918"],["68166.90","0.035"],["68181.90","0.020"],["68188.40","0.001"],["68192.10","0.012"],["68211.60","0.002"]],"u":10185461,"seq":9374374038},"cts":1729581430423}'
2024-10-22 09:17:21,618 - DEBUG - ++Rcv decoded: fin=1 opcode=1 data=b'{"topic":"orderbook.50.BTCUSDT","type":"snapshot","ts":1729581439873,"data":{"s":"BTCUSDT","b":[["67622.30","0.427"],["67621.50","0.002"],["67613.60","0.686"],["67601.10","0.547"],["67550.80","0.065"],["67550.00","0.001"],["67531.40","0.001"],["67500.00","0.013"],["67494.30","0.004"],["67489.80","0.465"],["67461.30","0.230"],["67456.90","0.002"],["67452.60","0.426"],["67450.20","0.247"],["67432.20","0.547"],["67376.10","0.027"],["67375.00","0.003"],["67331.70","0.004"],["67322.10","0.001"],["67320.90","0.835"],["67300.00","0.057"],["67293.30","0.017"],["67292.80","0.002"],["67291.50","0.044"],["67290.00","0.057"],["67287.60","0.264"],["67286.80","0.670"],["67286.70","0.020"],["67283.50","0.001"],["67282.90","0.426"],["67277.30","0.089"],["67263.30","0.547"],["67249.40","0.129"],["67233.30","0.001"],["67223.60","0.002"],["67214.10","0.005"],["67201.90","0.153"],["67200.00","0.003"],["67169.10","0.004"],["67151.90","0.918"],["67129.00","0.002"],["67123.40","0.625"],["67122.90","0.001"],["67121.60","0.120"],["67113.20","0.424"],["67094.40","0.545"],["67035.70","0.001"],["67033.30","0.057"],["67028.10","0.459"],["67025.00","0.003"]],"a":[["67622.40","0.001"],["67636.10","0.001"],["67649.60","0.001"],["67801.10","0.423"],["67802.90","0.551"],["67811.90","0.089"],["67827.80","0.878"],["67832.90","0.129"],["67833.30","0.057"],["67840.20","0.001"],["67893.00","0.001"],["67900.00","0.003"],["67901.50","0.459"],["67928.30","0.001"],["67939.00","0.547"],["67951.70","0.002"],["67961.70","0.131"],["67970.90","0.443"],["67984.00","0.074"],["67985.20","0.001"],["67986.60","0.017"],["67996.70","0.487"],["68000.00","0.050"],["68001.00","0.010"],["68008.80","0.005"],["68011.20","0.018"],["68027.10","0.001"],["68030.00","0.553"],["68039.80","0.593"],["68056.90","0.264"],["68068.10","0.001"],["68069.00","0.001"],["68075.00","0.003"],["68077.50","0.026"],["68079.10","0.089"],["68100.00","0.070"],["68107.90","0.547"],["68108.00","0.001"],["68115.60","0.005"],["68117.50","0.024"],["68124.60","0.129"],["68131.30","0.296"],["68140.80","0.443"],["68142.80","0.020"],["68165.70","0.918"],["68166.90","0.035"],["68181.90","0.020"],["68188.40","0.001"],["68192.10","0.012"],["68211.60","0.002"]],"u":10185461,"seq":9374374038},"cts":1729581430423}'
2024-10-22 09:17:21,624 - DEBUG - ++Rcv raw: b'\x81~\x00\x8f{"success":true,"ret_msg":"","conn_id":"3da2f476-6bd7-45c1-8508-2fd8a11a4628","req_id":"6f55e1f7-4efc-4f83-8da9-8c739f243fc8","op":"subscribe"}'
2024-10-22 09:17:21,624 - DEBUG - ++Rcv decoded: fin=1 opcode=1 data=b'{"success":true,"ret_msg":"","conn_id":"3da2f476-6bd7-45c1-8508-2fd8a11a4628","req_id":"6f55e1f7-4efc-4f83-8da9-8c739f243fc8","op":"subscribe"}'
2024-10-22 09:17:21,654 - DEBUG - ++Rcv raw: b'\x81~\x01\x1f{"topic":"orderbook.50.BTCUSDT","type":"delta","ts":1729581441173,"data":{"s":"BTCUSDT","b":[],"a":[["67622.40","0"],["67636.10","0"],["67649.60","0"],["67801.10","0.041"],["68216.50","0.281"],["68229.90","0.001"],["68250.00","0.003"]],"u":10185462,"seq":9374374062},"cts":1729581441155}'
2024-10-22 09:17:21,654 - DEBUG - ++Rcv decoded: fin=1 opcode=1 data=b'{"topic":"orderbook.50.BTCUSDT","type":"delta","ts":1729581441173,"data":{"s":"BTCUSDT","b":[],"a":[["67622.40","0"],["67636.10","0"],["67649.60","0"],["67801.10","0.041"],["68216.50","0.281"],["68229.90","0.001"],["68250.00","0.003"]],"u":10185462,"seq":9374374062},"cts":1729581441155}'
2024-10-22 09:17:21,680 - DEBUG - ++Rcv raw: b'\x81~\x00\xf8{"topic":"orderbook.50.BTCUSDT","type":"delta","ts":1729581441192,"data":{"s":"BTCUSDT","b":[["67631.20","0.443"],["67025.00","0"]],"a":[["67801.10","0"],["67802.90","0.530"],["68254.00","0.459"]],"u":10185463,"seq":9374374067},"cts":1729581441186}'
2024-10-22 09:17:21,681 - DEBUG - ++Rcv decoded: fin=1 opcode=1 data=b'{"topic":"orderbook.50.BTCUSDT","type":"delta","ts":1729581441192,"data":{"s":"BTCUSDT","b":[["67631.20","0.443"],["67025.00","0"]],"a":[["67801.10","0"],["67802.90","0.530"],["68254.00","0.459"]],"u":10185463,"seq":9374374067},"cts":1729581441186}'
2024-10-22 09:17:21,917 - DEBUG - ++Rcv raw: b'\x81~\x01\n{"topic":"orderbook.50.BTCUSDT","type":"delta","ts":1729581441432,"data":{"s":"BTCUSDT","b":[],"a":[["67631.30","0.001"],["67644.90","0.001"],["67658.50","0.001"],["68229.90","0"],["68250.00","0"],["68254.00","0"]],"u":10185464,"seq":9374374070},"cts":1729581441429}'
2024-10-22 09:17:21,917 - DEBUG - ++Rcv decoded: fin=1 opcode=1 data=b'{"topic":"orderbook.50.BTCUSDT","type":"delta","ts":1729581441432,"data":{"s":"BTCUSDT","b":[],"a":[["67631.30","0.001"],["67644.90","0.001"],["67658.50","0.001"],["68229.90","0"],["68250.00","0"],["68254.00","0"]],"u":10185464,"seq":9374374070},"cts":1729581441429}'
2024-10-22 09:17:24,020 - DEBUG - ++Rcv raw: b'\x81~\x01\x1f{"topic":"orderbook.50.BTCUSDT","type":"delta","ts":1729581443532,"data":{"s":"BTCUSDT","b":[],"a":[["67631.30","0"],["67644.90","0"],["67658.50","0"],["67802.90","0.422"],["68229.90","0.001"],["68250.00","0.003"],["68254.00","0.459"]],"u":10185465,"seq":9374374071},"cts":1729581443522}'
2024-10-22 09:17:24,020 - DEBUG - ++Rcv decoded: fin=1 opcode=1 data=b'{"topic":"orderbook.50.BTCUSDT","type":"delta","ts":1729581443532,"data":{"s":"BTCUSDT","b":[],"a":[["67631.30","0"],["67644.90","0"],["67658.50","0"],["67802.90","0.422"],["68229.90","0.001"],["68250.00","0.003"],["68254.00","0.459"]],"u":10185465,"seq":9374374071},"cts":1729581443522}'
2024-10-22 09:17:24,822 - DEBUG - ++Rcv raw: b'\x81~\x00\xbe{"topic":"orderbook.50.BTCUSDT","type":"delta","ts":1729581444332,"data":{"s":"BTCUSDT","b":[["67641.20","0.001"],["67028.10","0"]],"a":[],"u":10185466,"seq":9374374072},"cts":1729581444319}'
2024-10-22 09:17:24,823 - DEBUG - ++Rcv decoded: fin=1 opcode=1 data=b'{"topic":"orderbook.50.BTCUSDT","type":"delta","ts":1729581444332,"data":{"s":"BTCUSDT","b":[["67641.20","0.001"],["67028.10","0"]],"a":[],"u":10185466,"seq":9374374072},"cts":1729581444319}'
2024-10-22 09:17:24,950 - DEBUG - ++Rcv raw: b'\x81~\x00\xe4{"topic":"orderbook.50.BTCUSDT","type":"delta","ts":1729581444452,"data":{"s":"BTCUSDT","b":[],"a":[["67644.90","0.001"],["67658.50","0.001"],["68250.00","0"],["68254.00","0"]],"u":10185467,"seq":9374374075},"cts":1729581444431}'
2024-10-22 09:17:24,950 - DEBUG - ++Rcv decoded: fin=1 opcode=1 data=b'{"topic":"orderbook.50.BTCUSDT","type":"delta","ts":1729581444452,"data":{"s":"BTCUSDT","b":[],"a":[["67644.90","0.001"],["67658.50","0.001"],["68250.00","0"],["68254.00","0"]],"u":10185467,"seq":9374374075},"cts":1729581444431}'
2024-10-22 09:17:25,933 - DEBUG - ++Rcv raw: b'\x81~\x00\xbe{"topic":"orderbook.50.BTCUSDT","type":"delta","ts":1729581445452,"data":{"s":"BTCUSDT","b":[],"a":[["67672.10","0.001"],["68229.90","0"]],"u":10185468,"seq":9374374076},"cts":1729581445431}'
2024-10-22 09:17:25,934 - DEBUG - ++Rcv decoded: fin=1 opcode=1 data=b'{"topic":"orderbook.50.BTCUSDT","type":"delta","ts":1729581445452,"data":{"s":"BTCUSDT","b":[],"a":[["67672.10","0.001"],["68229.90","0"]],"u":10185468,"seq":9374374076},"cts":1729581445431}'
2024-10-22 09:17:30,016 - DEBUG - ++Rcv raw: b'\x81~\x00\xbe{"topic":"orderbook.50.BTCUSDT","type":"delta","ts":1729581449532,"data":{"s":"BTCUSDT","b":[["67641.20","0"],["67028.10","0.459"]],"a":[],"u":10185469,"seq":9374374079},"cts":1729581449518}'
2024-10-22 09:17:30,017 - DEBUG - ++Rcv decoded: fin=1 opcode=1 data=b'{"topic":"orderbook.50.BTCUSDT","type":"delta","ts":1729581449532,"data":{"s":"BTCUSDT","b":[["67641.20","0"],["67028.10","0.459"]],"a":[],"u":10185469,"seq":9374374079},"cts":1729581449518}'
2024-10-22 09:17:30,696 - DEBUG - ++Rcv raw: b'\x81~\x00\xbe{"topic":"orderbook.50.BTCUSDT","type":"delta","ts":1729581450212,"data":{"s":"BTCUSDT","b":[["67641.20","0.001"],["67028.10","0"]],"a":[],"u":10185470,"seq":9374374080},"cts":1729581450195}'
2024-10-22 09:17:30,696 - DEBUG - ++Rcv decoded: fin=1 opcode=1 data=b'{"topic":"orderbook.50.BTCUSDT","type":"delta","ts":1729581450212,"data":{"s":"BTCUSDT","b":[["67641.20","0.001"],["67028.10","0"]],"a":[],"u":10185470,"seq":9374374080},"cts":1729581450195}'
2024-10-22 09:17:32,144 - DEBUG - ++Rcv raw: b'\x81~\x00\xd3{"topic":"orderbook.50.BTCUSDT","type":"delta","ts":1729581451652,"data":{"s":"BTCUSDT","b":[["67641.20","0"],["67631.20","0.012"],["67028.10","0.459"]],"a":[],"u":10185471,"seq":9374374107},"cts":1729581451640}'
2024-10-22 09:17:32,145 - DEBUG - ++Rcv decoded: fin=1 opcode=1 data=b'{"topic":"orderbook.50.BTCUSDT","type":"delta","ts":1729581451652,"data":{"s":"BTCUSDT","b":[["67641.20","0"],["67631.20","0.012"],["67028.10","0.459"]],"a":[],"u":10185471,"seq":9374374107},"cts":1729581451640}'
2024-10-22 09:17:32,360 - DEBUG - ++Rcv raw: b'\x81~\x00\xd3{"topic":"orderbook.50.BTCUSDT","type":"delta","ts":1729581451873,"data":{"s":"BTCUSDT","b":[["67631.30","0.002"],["67622.30","0.423"],["67028.10","0"]],"a":[],"u":10185472,"seq":9374374109},"cts":1729581451854}'
2024-10-22 09:17:32,361 - DEBUG - ++Rcv decoded: fin=1 opcode=1 data=b'{"topic":"orderbook.50.BTCUSDT","type":"delta","ts":1729581451873,"data":{"s":"BTCUSDT","b":[["67631.30","0.002"],["67622.30","0.423"],["67028.10","0"]],"a":[],"u":10185472,"seq":9374374109},"cts":1729581451854}'
2024-10-22 09:17:32,576 - DEBUG - ++Rcv raw: b'\x81~\x00\xbe{"topic":"orderbook.50.BTCUSDT","type":"delta","ts":1729581452092,"data":{"s":"BTCUSDT","b":[["67631.40","0.004"],["67631.30","0"]],"a":[],"u":10185473,"seq":9374374111},"cts":1729581452076}'
2024-10-22 09:17:32,577 - DEBUG - ++Rcv decoded: fin=1 opcode=1 data=b'{"topic":"orderbook.50.BTCUSDT","type":"delta","ts":1729581452092,"data":{"s":"BTCUSDT","b":[["67631.40","0.004"],["67631.30","0"]],"a":[],"u":10185473,"seq":9374374111},"cts":1729581452076}'
2024-10-22 09:17:32,803 - DEBUG - ++Rcv raw: b'\x81~\x00\xbe{"topic":"orderbook.50.BTCUSDT","type":"delta","ts":1729581452312,"data":{"s":"BTCUSDT","b":[["67631.50","0.002"],["67631.40","0"]],"a":[],"u":10185474,"seq":9374374113},"cts":1729581452296}'
2024-10-22 09:17:32,805 - DEBUG - ++Rcv decoded: fin=1 opcode=1 data=b'{"topic":"orderbook.50.BTCUSDT","type":"delta","ts":1729581452312,"data":{"s":"BTCUSDT","b":[["67631.50","0.002"],["67631.40","0"]],"a":[],"u":10185474,"seq":9374374113},"cts":1729581452296}'
2024-10-22 09:17:33,015 - DEBUG - ++Rcv raw: b'\x81~\x00\xbe{"topic":"orderbook.50.BTCUSDT","type":"delta","ts":1729581452532,"data":{"s":"BTCUSDT","b":[["67631.60","0.002"],["67631.50","0"]],"a":[],"u":10185475,"seq":9374374118},"cts":1729581452513}'
2024-10-22 09:17:33,015 - DEBUG - ++Rcv decoded: fin=1 opcode=1 data=b'{"topic":"orderbook.50.BTCUSDT","type":"delta","ts":1729581452532,"data":{"s":"BTCUSDT","b":[["67631.60","0.002"],["67631.50","0"]],"a":[],"u":10185475,"seq":9374374118},"cts":1729581452513}'
2024-10-22 09:17:33,237 - DEBUG - ++Rcv raw: b'\x81~\x00\xbe{"topic":"orderbook.50.BTCUSDT","type":"delta","ts":1729581452752,"data":{"s":"BTCUSDT","b":[["67631.70","0.004"],["67631.60","0"]],"a":[],"u":10185476,"seq":9374374120},"cts":1729581452734}'
2024-10-22 09:17:33,238 - DEBUG - ++Rcv decoded: fin=1 opcode=1 data=b'{"topic":"orderbook.50.BTCUSDT","type":"delta","ts":1729581452752,"data":{"s":"BTCUSDT","b":[["67631.70","0.004"],["67631.60","0"]],"a":[],"u":10185476,"seq":9374374120},"cts":1729581452734}'
2024-10-22 09:17:35,038 - DEBUG - ++Rcv raw: b'\x81~\x00\xbe{"topic":"orderbook.50.BTCUSDT","type":"delta","ts":1729581454553,"data":{"s":"BTCUSDT","b":[["67631.80","0.002"],["67631.70","0"]],"a":[],"u":10185477,"seq":9374374123},"cts":1729581454542}'
2024-10-22 09:17:35,038 - DEBUG - ++Rcv decoded: fin=1 opcode=1 data=b'{"topic":"orderbook.50.BTCUSDT","type":"delta","ts":1729581454553,"data":{"s":"BTCUSDT","b":[["67631.80","0.002"],["67631.70","0"]],"a":[],"u":10185477,"seq":9374374123},"cts":1729581454542}'
2024-10-22 09:17:39,429 - DEBUG - ++Sent raw: b'\x81\x8e\xef\x8diy\x94\xaf\x06\t\xcd\xb7I[\x9f\xe4\x07\x1e\xcd\xf0'
2024-10-22 09:17:39,429 - DEBUG - ++Sent decoded: fin=1 opcode=1 data=b'{"op": "ping"}'
2024-10-22 09:17:39,654 - DEBUG - ++Rcv raw: b'\x81~\x00\xbe{"topic":"orderbook.50.BTCUSDT","type":"delta","ts":1729581459173,"data":{"s":"BTCUSDT","b":[],"a":[["67792.90","0.001"],["68216.50","0"]],"u":10185478,"seq":9374374124},"cts":1729581459155}'
2024-10-22 09:17:39,655 - DEBUG - ++Rcv decoded: fin=1 opcode=1 data=b'{"topic":"orderbook.50.BTCUSDT","type":"delta","ts":1729581459173,"data":{"s":"BTCUSDT","b":[],"a":[["67792.90","0.001"],["68216.50","0"]],"u":10185478,"seq":9374374124},"cts":1729581459155}'
2024-10-22 09:17:39,736 - DEBUG - ++Rcv raw: b'\x81~\x00\xbe{"topic":"orderbook.50.BTCUSDT","type":"delta","ts":1729581459252,"data":{"s":"BTCUSDT","b":[["67632.30","0.001"],["67033.30","0"]],"a":[],"u":10185479,"seq":9374374125},"cts":1729581459248}'
2024-10-22 09:17:39,736 - DEBUG - ++Rcv decoded: fin=1 opcode=1 data=b'{"topic":"orderbook.50.BTCUSDT","type":"delta","ts":1729581459252,"data":{"s":"BTCUSDT","b":[["67632.30","0.001"],["67033.30","0"]],"a":[],"u":10185479,"seq":9374374125},"cts":1729581459248}'
2024-10-22 09:17:39,825 - DEBUG - ++Rcv raw: b'\x81j{"success":true,"ret_msg":"pong","conn_id":"3da2f476-6bd7-45c1-8508-2fd8a11a4628","req_id":"","op":"ping"}'
2024-10-22 09:17:39,826 - DEBUG - ++Rcv decoded: fin=1 opcode=1 data=b'{"success":true,"ret_msg":"pong","conn_id":"3da2f476-6bd7-45c1-8508-2fd8a11a4628","req_id":"","op":"ping"}'
2024-10-22 09:17:41,217 - DEBUG - ++Sent raw: b'\x81\x8e{js\xca\x00H\x1c\xbaYPS\xe8\x0b\x03\x1d\xadY\x17'
2024-10-22 09:17:41,217 - DEBUG - ++Sent decoded: fin=1 opcode=1 data=b'{"op": "ping"}'
2024-10-22 09:17:41,386 - DEBUG - ++Sent raw: b'\x88\x82Z\xa2:\xa0YJ'
2024-10-22 09:17:41,387 - DEBUG - ++Sent decoded: fin=1 opcode=8 data=b'\x03\xe8'
2024-10-22 09:17:41,603 - DEBUG - ++Rcv raw: b'\x81M{"op":"pong","args":["1729581461121"],"conn_id":"crjtta1qo29j6gv0ald0-3okwf"}'
2024-10-22 09:17:41,604 - DEBUG - ++Rcv decoded: fin=1 opcode=1 data=b'{"op":"pong","args":["1729581461121"],"conn_id":"crjtta1qo29j6gv0ald0-3okwf"}'
2024-10-22 09:18:07,226 - INFO - WebSocket Unified V5 (Auth) attempting connection...
2024-10-22 09:18:07,936 - DEBUG - --- request header ---
2024-10-22 09:18:07,952 - DEBUG - GET /v5/public/linear HTTP/1.1
Upgrade: websocket
Host: stream-testnet.bybit.com
Origin: https://stream-testnet.bybit.com
Sec-WebSocket-Key: XRWFcgH1D5rx1qMWDerC9g==
Sec-WebSocket-Version: 13
Connection: Upgrade


2024-10-22 09:18:07,983 - DEBUG - -----------------------
2024-10-22 09:18:08,013 - DEBUG - --- response header ---
2024-10-22 09:18:08,691 - DEBUG - HTTP/1.1 101 Switching Protocols
2024-10-22 09:18:08,737 - DEBUG - Connection: upgrade
2024-10-22 09:18:08,753 - DEBUG - Date: Tue, 22 Oct 2024 07:18:08 GMT
2024-10-22 09:18:08,815 - DEBUG - Upgrade: websocket
2024-10-22 09:18:08,875 - DEBUG - Sec-WebSocket-Accept: OnN1aQkzYyypLulmXwf1BG06tEc=
2024-10-22 09:18:08,919 - DEBUG - X-Cache: Miss from cloudfront
2024-10-22 09:18:08,966 - DEBUG - Via: 1.1 fb5c24475d6ce2683fe1262475a1c24c.cloudfront.net (CloudFront)
2024-10-22 09:18:09,012 - DEBUG - X-Amz-Cf-Pop: VIE50-P3
2024-10-22 09:18:09,027 - DEBUG - X-Amz-Cf-Id: JSrAxjoXQck8LCkSEhPgtU-k9yx3oIfHMF9kBlnS9b9NlQIBna1JdA==
2024-10-22 09:18:09,089 - DEBUG - -----------------------
2024-10-22 09:18:09,120 - INFO - WebSocket Unified V5 (Auth) connected
2024-10-22 09:18:09,120 - INFO - Websocket connected
2024-10-22 09:18:09,121 - INFO - WebSocket Unified V5 (Auth) attempting connection...
2024-10-22 09:18:09,752 - DEBUG - --- request header ---
2024-10-22 09:18:09,783 - DEBUG - GET /v5/private HTTP/1.1
Upgrade: websocket
Host: stream-testnet.bybit.com
Origin: https://stream-testnet.bybit.com
Sec-WebSocket-Key: dOfJP23XBOoKzc8BJ8lj6g==
Sec-WebSocket-Version: 13
Connection: Upgrade


2024-10-22 09:18:09,798 - DEBUG - -----------------------
2024-10-22 09:18:09,830 - DEBUG - --- response header ---
2024-10-22 09:18:10,631 - DEBUG - HTTP/1.1 101 Switching Protocols
2024-10-22 09:18:10,646 - DEBUG - Connection: upgrade
2024-10-22 09:18:10,661 - DEBUG - Date: Tue, 22 Oct 2024 07:18:10 GMT
2024-10-22 09:18:10,692 - DEBUG - Server: fasthttp
2024-10-22 09:18:10,738 - DEBUG - Upgrade: websocket
2024-10-22 09:18:10,754 - DEBUG - Sec-Websocket-Accept: JzpMMau017xR/TWARbvtAuqSKYI=
2024-10-22 09:18:10,769 - DEBUG - X-Cache: Miss from cloudfront
2024-10-22 09:18:10,785 - DEBUG - Via: 1.1 d619c47997370e0eec10214d0a828f18.cloudfront.net (CloudFront)
2024-10-22 09:18:10,815 - DEBUG - X-Amz-Cf-Pop: VIE50-P3
2024-10-22 09:18:10,878 - DEBUG - X-Amz-Cf-Id: PN1R1VAKGiTBiPgeokqsdTVemPftluwhddXxRO82YHXA2j3gtmEARA==
2024-10-22 09:18:10,908 - DEBUG - -----------------------
2024-10-22 09:18:10,923 - INFO - WebSocket Unified V5 (Auth) connected
2024-10-22 09:18:10,923 - INFO - Websocket connected
2024-10-22 09:18:10,924 - DEBUG - ++Sent raw: b'\x81\xfe\x00\x81\x87\xb1\x0e\x88\xfc\x93a\xf8\xa5\x8b.\xaa\xe6\xc4z\xe0\xa5\x9d.\xaa\xe6\xc3i\xfb\xa5\x8b.\xd3\xa5\xd6K\xf0\xf4\xc3c\xca\xe1\xd4I\xb0\xea\xf9{\xea\xb7\x82]\xaa\xab\x91?\xbf\xb5\x88;\xb0\xb6\x857\xb9\xbe\x83:\xa4\xa7\x93m\xbb\xb2\xd4l\xee\xb5\xd2?\xbf\xb7\x84j\xed\xbe\x877\xbc\xe4\x838\xeb\xb3\x897\xe9\xe3\x83h\xec\xb7\x82l\xe9\xe6\x80?\xb9\xe3\x808\xb1\xbe\x879\xb8\xbf\x82>\xb9\xb4\xd7;\xbe\xb3\x846\xb1\xb4\xd2>\xb0\xb6\x81,\xd5\xfa'
2024-10-22 09:18:10,924 - DEBUG - ++Sent decoded: fin=1 opcode=1 data=b'{"op": "auth", "args": ["gExsrmBfeG8mHub03S", 1729581491924, "c35ebf2c1705de9694c26c489ad2fd03baa111d169967083013f5645893c0810"]}'
2024-10-22 09:18:10,926 - DEBUG - ++Sent raw: b'\x81\xe7\xa2\xa1\xc2\x83\xd9\x83\xad\xf3\x80\x9b\xe2\xa1\xd1\xd4\xa0\xf0\xc1\xd3\xab\xe1\xc7\x83\xee\xa3\x80\xd3\xa7\xf2\xfd\xc8\xa6\xa1\x98\x81\xe0\xb3\xc4\x96\xfb\xb1\x92\xc5\xa1\xae\xc1\x91\xa0\xb1\x8f\x95\xfa\xe6\x90\x8c\xa0\xba\x93\x97\xef\xe5\xc4\x95\xf2\xbb\x93\xc3\xfb\xb7\x96\xc7\xa1\xa1\x8e\x81\xe0\xe2\xd0\xc6\xb1\xa1\x98\x81\x99\xa1\xcd\xd3\xa6\xe6\xd0\xc3\xad\xec\xc9\x8f\xf7\xb3\x8c\xe3\x96\xc0\xf7\xf2\x86\xd7\x80\xfc\xbf'
2024-10-22 09:18:10,927 - DEBUG - ++Sent decoded: fin=1 opcode=1 data=b'{"op": "subscribe", "req_id": "0f7920dc-c0b2-48e2-b916-ff4081b944fc", "args": ["orderbook.50.BTCUSDT"]}'
2024-10-22 09:18:11,333 - DEBUG - ++Rcv raw: b'\x81P{"success":true,"ret_msg":"","op":"auth","conn_id":"crjtta1qo29j6gv0ald0-3okym"}'
2024-10-22 09:18:11,333 - DEBUG - ++Rcv raw: b'\x81~\x08\xce{"topic":"orderbook.50.BTCUSDT","type":"snapshot","ts":1729581487873,"data":{"s":"BTCUSDT","b":[["67658.80","0.459"],["67631.80","0.002"],["67631.20","0.012"],["67622.30","0.423"],["67621.50","0.002"],["67613.60","0.686"],["67601.10","0.547"],["67550.80","0.065"],["67550.00","0.001"],["67544.60","0.089"],["67531.40","0.001"],["67500.00","0.013"],["67494.30","0.004"],["67489.80","0.465"],["67461.30","0.230"],["67456.90","0.002"],["67452.60","0.426"],["67450.20","0.247"],["67432.20","0.547"],["67376.10","0.027"],["67375.00","0.003"],["67331.70","0.004"],["67322.10","0.001"],["67320.90","0.835"],["67300.00","0.057"],["67293.30","0.017"],["67292.80","0.002"],["67291.50","0.044"],["67290.00","0.057"],["67287.60","0.264"],["67286.80","0.670"],["67286.70","0.020"],["67283.50","0.001"],["67282.90","0.426"],["67277.30","0.089"],["67263.30","0.547"],["67249.40","0.129"],["67233.30","0.001"],["67223.60","0.002"],["67214.10","0.005"],["67201.90","0.153"],["67200.00","0.003"],["67169.10","0.004"],["67151.90","0.918"],["67129.00","0.002"],["67123.40","0.625"],["67122.90","0.001"],["67121.60","0.120"],["67113.20","0.424"],["67094.40","0.545"]],"a":[["67658.90","0.001"],["67672.60","0.001"],["67686.10","0.001"],["67802.90","0.591"],["67827.80","0.431"],["67832.90","0.129"],["67833.30","0.057"],["67840.20","0.001"],["67893.00","0.001"],["67900.00","0.003"],["67901.50","0.459"],["67928.30","0.001"],["67939.00","0.547"],["67951.70","0.002"],["67961.70","0.131"],["67970.90","0.443"],["67984.00","0.074"],["67985.20","0.001"],["67986.60","0.017"],["67996.70","0.487"],["68000.00","0.050"],["68001.00","0.010"],["68008.80","0.005"],["68011.20","0.018"],["68027.10","0.001"],["68030.00","0.553"],["68039.80","0.593"],["68056.90","0.264"],["68068.10","0.001"],["68069.00","0.001"],["68075.00","0.003"],["68077.50","0.026"],["68079.10","0.089"],["68100.00","0.070"],["68107.90","0.547"],["68108.00","0.001"],["68115.60","0.005"],["68117.50","0.024"],["68124.60","0.129"],["68131.30","0.296"],["68140.80","0.443"],["68142.80","0.020"],["68165.70","0.918"],["68166.90","0.035"],["68188.40","0.001"],["68192.10","0.012"],["68211.60","0.002"],["68216.50","0.281"],["68229.90","0.001"],["68250.00","0.003"]],"u":10185492,"seq":9374374235},"cts":1729581487451}'
2024-10-22 09:18:11,333 - DEBUG - ++Rcv decoded: fin=1 opcode=1 data=b'{"success":true,"ret_msg":"","op":"auth","conn_id":"crjtta1qo29j6gv0ald0-3okym"}'
